<?xml version="1.0" encoding="UTF-8"?>
<mujoco model="walker_astron_v1">
  <compiler angle="radian" meshdir="/home/soom/work/GMR/xgmr_tienkung/assets/walker_c1/meshes" boundmass="0.0001"/>
  <option integrator="implicitfast" cone="elliptic" impratio="100" timestep="0.001" iterations="100" solver="CG" gravity="0 0 -9.81">
    <flag contact="enable" energy="enable" />
  </option>
  <statistic meansize="0.140456" extent="1.93199" center="-0.0165219 -8.18765e-05 -0.0755538"/>
  <default>
    <joint damping="1.0" frictionloss="0.2" armature="0.01"/>
  </default>
  <asset>
    <mesh name="base_link" file="base_link.STL"/>
    <mesh name="L_hip_pitch_link" file="L_hip_pitch_link.STL"/>
    <mesh name="L_hip_roll_link" file="L_hip_roll_link.STL"/>
    <mesh name="L_hip_yaw_link" file="L_hip_yaw_link.STL"/>
    <mesh name="L_knee_pitch_link" file="L_knee_pitch_link.STL"/>
    <mesh name="L_ankle_pitch_link" file="L_ankle_pitch_link.STL"/>
    <mesh name="L_ankle_roll_link" file="L_ankle_roll_link.STL"/>
    <mesh name="R_hip_pitch_link" file="R_hip_pitch_link.STL"/>
    <mesh name="R_hip_roll_link" file="R_hip_roll_link.STL"/>
    <mesh name="R_hip_yaw_link" file="R_hip_yaw_link.STL"/>
    <mesh name="R_knee_pitch_link" file="R_knee_pitch_link.STL"/>
    <mesh name="R_ankle_pitch_link" file="R_ankle_pitch_link.STL"/>
    <mesh name="R_ankle_roll_link" file="R_ankle_roll_link.STL"/>
    <mesh name="waist_yaw_link" file="waist_yaw_link.STL"/>
    <mesh name="waist_pitch_link" file="waist_pitch_link.STL"/>
    <mesh name="waist_roll_link" file="waist_roll_link.STL"/>
    <mesh name="L_shoulder_pitch_link" file="L_shoulder_pitch_link.STL"/>
    <mesh name="L_shoulder_roll_link" file="L_shoulder_roll_link.STL"/>
    <mesh name="L_shoulder_yaw_link" file="L_shoulder_yaw_link.STL"/>
    <mesh name="L_elbow_pitch_link" file="L_elbow_pitch_link.STL"/>
    <mesh name="L_elbow_yaw_link" file="L_elbow_yaw_link.STL"/>
    <mesh name="L_wrist_pitch_link" file="L_wrist_pitch_link.STL"/>
    <mesh name="L_wrist_roll_link" file="L_wrist_roll_link.STL"/>
    <mesh name="R_shoulder_pitch_link" file="R_shoulder_pitch_link.STL"/>
    <mesh name="R_shoulder_roll_link" file="R_shoulder_roll_link.STL"/>
    <mesh name="R_shoulder_yaw_link" file="R_shoulder_yaw_link.STL"/>
    <mesh name="R_elbow_pitch_link" file="R_elbow_pitch_link.STL"/>
    <mesh name="R_elbow_yaw_link" file="R_elbow_yaw_link.STL"/>
    <mesh name="R_wrist_pitch_link" file="R_wrist_pitch_link.STL"/>
    <mesh name="R_wrist_roll_link" file="R_wrist_roll_link.STL"/>
    <mesh name="head_yaw_link" file="head_yaw_link.STL"/>
    <mesh name="head_pitch_link" file="head_pitch_link.STL"/>

    <mesh name="L_hand_base_link" file="hand3_v1_new/L_hand_base_link.STL"/>
    <mesh name="L_palm_link" file="hand3_v1_new/L_palm_link.STL"/>
    <mesh name="L_thumb_cmp_link" file="hand3_v1_new/L_thumb_cmp_link.STL"/>
    <mesh name="L_thumb_mpp_link" file="hand3_v1_new/L_thumb_mpp_link.STL"/>
    <mesh name="L_thumb_ip_link" file="hand3_v1_new/L_thumb_ip_link.STL"/>
    <mesh name="L_index_mpp_link" file="hand3_v1_new/L_index_mpp_link.STL"/>
    <mesh name="L_index_ip_link" file="hand3_v1_new/L_index_ip_link.STL"/>
    <mesh name="L_middle_mpp_link" file="hand3_v1_new/L_middle_mpp_link.STL"/>
    <mesh name="L_middle_ip_link" file="hand3_v1_new/L_middle_ip_link.STL"/>
    <mesh name="L_ring_mpp_link" file="hand3_v1_new/L_ring_mpp_link.STL"/>
    <mesh name="L_ring_ip_link" file="hand3_v1_new/L_ring_ip_link.STL"/>
    <mesh name="L_little_mpp_link" file="hand3_v1_new/L_little_mpp_link.STL"/>
    <mesh name="L_little_ip_link" file="hand3_v1_new/L_little_ip_link.STL"/>
    <mesh name="R_hand_base_link" file="hand3_v1_new/R_hand_base_link.STL"/>
    <mesh name="R_palm_link" file="hand3_v1_new/R_palm_link.STL"/>
    <mesh name="R_thumb_cmp_link" file="hand3_v1_new/R_thumb_cmp_link.STL"/>
    <mesh name="R_thumb_mpp_link" file="hand3_v1_new/R_thumb_mpp_link.STL"/>
    <mesh name="R_thumb_ip_link" file="hand3_v1_new/R_thumb_ip_link.STL"/>
    <mesh name="R_index_mpp_link" file="hand3_v1_new/R_index_mpp_link.STL"/>
    <mesh name="R_index_ip_link" file="hand3_v1_new/R_index_ip_link.STL"/>
    <mesh name="R_middle_mpp_link" file="hand3_v1_new/R_middle_mpp_link.STL"/>
    <mesh name="R_middle_ip_link" file="hand3_v1_new/R_middle_ip_link.STL"/>
    <mesh name="R_ring_mpp_link" file="hand3_v1_new/R_ring_mpp_link.STL"/>
    <mesh name="R_ring_ip_link" file="hand3_v1_new/R_ring_ip_link.STL"/>
    <mesh name="R_little_mpp_link" file="hand3_v1_new/R_little_mpp_link.STL"/>
    <mesh name="R_little_ip_link" file="hand3_v1_new/R_little_ip_link.STL"/>
    <texture type="skybox" builtin="flat" rgb1="0 0 0" rgb2="0 0 0" width="512" height="3072"/>
    <texture type="2d" name="groundplane" builtin="checker" mark="edge" rgb1="0.2 0.3 0.4" rgb2="0.1 0.2 0.3" markrgb="0.8 0.8 0.8" width="300" height="300"/>
    <material name="groundplane" texture="groundplane" texuniform="true" texrepeat="5 5" reflectance="0.2"/>
  </asset>
  <worldbody>
    <light pos="1 0 3.5" dir="0 0 -1" directional="true"/>
    <geom name="floor" size="0 0 0.05" type="plane" material="groundplane"/>
    <body name="base_link" pos="0 0 0.91">
      <inertial pos="-0.00060742 0 -0.00390464" quat="1 0 0 0" mass="5.32923152" diaginertia="0.02561815 0.01751097 0.02397466"/>
      <joint name="floating_base" type="free"/>
      <geom type="mesh" contype="0" conaffinity="0" group="1" density="0" rgba="0.22 0.40 0.65 1" mesh="base_link"/>
      <geom name="base_link_collision" type="sphere" size="0.06" pos="0 0 -0.004" rgba="0.22 0.40 0.65 0.3"/>
      <body name="body_imu_link" quat="0.707107 0 0 -0.707107">
        <inertial pos="0 0 0" mass="0.0001" diaginertia="1e-09 1e-09 1e-09"/>
        <geom size="0.005 0.005 0.005" type="box" contype="0" conaffinity="0" group="1" density="0" rgba="0 0 1 1"/>
        <site name="imu" size="0.01" pos="0 0 0"/>
      </body>
      <body name="L_hip_pitch_link" pos="0 0.073499 -0.019694" quat="0.991445 -0.130526 0 0">
        <inertial pos="0.0048541 0.0500696 -0.0150271" quat="0.245039 0.652073 0.417654 0.583372" mass="1.65569" diaginertia="0.00293392 0.00256263 0.00240876"/>
        <joint name="L_hip_pitch_joint" pos="0 0 0" axis="0 1 0" limited="true" range="-2.98 2.53"/>
        <geom type="mesh" contype="0" conaffinity="0" group="1" density="0" rgba="0.85 0.45 0.10 1" mesh="L_hip_pitch_link"/>
        <geom name="L_hip_pitch_collision" type="sphere" size="0.045" rgba="0.85 0.45 0.10 0.3"/>
        <body name="L_hip_roll_link" pos="0 0.0535795 -0.02" quat="0.991445 0.130526 0 0">
          <inertial pos="0.00120874 0.00203626 -0.0330367" quat="0.513666 0.487315 0.496385 0.502267" mass="0.514808" diaginertia="0.00158831 0.0015264 0.000682669"/>
          <joint name="L_hip_roll_joint" pos="0 0 0" axis="1 0 0" limited="true" range="-0.314 2.059"/>
          <geom type="mesh" contype="0" conaffinity="0" group="1" density="0" rgba="0.90 0.62 0.15 1" mesh="L_hip_roll_link"/>
          <geom name="L_hip_roll_collision" type="sphere" size="0.065" pos="0 0 -0.033" rgba="0.90 0.62 0.15 0.3"/>
          <body name="L_hip_yaw_link" pos="0 0 -0.0621" quat="1 0 0 0">
            <inertial pos="-0.00120768 -0.00740878 -0.123895" quat="0.723017 0.011601 0.0200665 0.690441" mass="5.13193" diaginertia="0.0446202 0.0424782 0.0109089"/>
            <joint name="L_hip_yaw_joint" pos="0 0 0" axis="0 0 1" limited="true" range="-2.146 3.246"/>
            <geom type="mesh" contype="0" conaffinity="0" group="1" density="0" rgba="0.85 0.75 0.10 1" mesh="L_hip_yaw_link"/>
            <geom name="L_hip_yaw_collision" type="capsule" size="0.07 0.18" pos="0 0 -0.13" rgba="0.85 0.75 0.10 0.3"/>
            <body name="L_knee_pitch_link" pos="-0.035 0 -0.3179" quat="1 0 0 0">
              <inertial pos="0.00270804 3.653e-05 -0.160407" quat="0.705286 0.0123666 0.015597 0.708643" mass="3.32222" diaginertia="0.0369622 0.0367307 0.00346204"/>
              <joint name="L_knee_pitch_joint" pos="0 0 0" axis="0 1 0" limited="true" range="0.08 2.478"/>
              <geom type="mesh" contype="0" conaffinity="0" group="1" density="0" rgba="0.92 0.88 0.12 1" mesh="L_knee_pitch_link"/>
              <geom name="L_knee_pitch_collision" type="cylinder" size="0.05 0.16" pos="0 0 -0.2" rgba="0.92 0.88 0.12 0.3"/>
              <body name="L_ankle_pitch_link" pos="0 0 -0.41" quat="1 0 0 0">
                <inertial pos="-0.00012374 -0.00221434 -0.0057231" quat="0.0409104 0.70465 0.0378602 0.707362" mass="0.110584" diaginertia="4.6937e-05 3.42735e-05 2.57096e-05"/>
                <joint name="L_ankle_pitch_joint" pos="0 0 0" axis="0 1 0" limited="true" range="-1.012 0.488"/>
                <geom type="mesh" contype="0" conaffinity="0" group="1" density="0" rgba="0.15 0.65 0.60 1" mesh="L_ankle_pitch_link"/>
                <geom name="L_ankle_pitch_collision" type="sphere" size="0.035" rgba="0.15 0.65 0.60 0.3"/>
                <body name="L_ankle_roll_link" pos="0 0 -0.012" quat="1 0 0 0">
                  <inertial pos="0.0340612 2.01988e-06 -0.0209947" quat="-4.35034e-05 0.733434 -6.9335e-06 0.679761" mass="0.826921" diaginertia="0.00492003 0.00442443 0.00096887"/>
                  <joint name="L_ankle_roll_joint" pos="0 0 0" axis="1 0 0" limited="true" range="-0.401 0.401"/>
                  <geom type="mesh" contype="0" conaffinity="0" group="1" density="0" rgba="0.10 0.50 0.50 1" mesh="L_ankle_roll_link"/>
                  <geom name="L_ankle_roll_collision" type="box" size="0.095 0.05 0.015" pos="0.05 0 -0.045" rgba="1 1 1 0.3"/>
                  <geom name="L_foot_end_outer"      pos="-0.049  0.0  -0.045" size="0.005 0.005" type="cylinder" rgba="0.10 0.50 0.50 1" contype="0" conaffinity="0"/>
                  <geom name="L_foot_front_outer"    size="0.01 0.001" pos="0.155 -0.03 -0.045" type="cylinder" rgba="0.10 0.50 0.50 1" contype="0" conaffinity="0"/>
                  <geom name="L_foot_front_inner"    size="0.01 0.001" pos="0.145  0.03 -0.045" type="cylinder" rgba="0.10 0.50 0.50 1" contype="0" conaffinity="0"/>
                  <geom name="L_foot_mid_outer"      size="0.01 0.001" pos="0.045 -0.02 -0.045" type="cylinder" rgba="0.10 0.50 0.50 1" contype="0" conaffinity="0"/>
                  <geom name="L_foot_mid_inner"      size="0.01 0.001" pos="0.045  0.02 -0.045" type="cylinder" rgba="0.10 0.50 0.50 1" contype="0" conaffinity="0"/>
                  <geom name="L_foot_strip_outer"    size="0.01 0.001" pos="0.095 -0.01 -0.045" type="cylinder" rgba="0.10 0.50 0.50 1" contype="0" conaffinity="0"/>
                  <geom name="toe1_left_collision"   size="0.01 0.015" pos="0.155  0.03 -0.045" type="cylinder" rgba="0.10 0.50 0.50 1"/>
                  <geom name="toe2_left_collision"   size="0.01 0.015" pos="0.155 -0.03 -0.045" type="cylinder" rgba="0.10 0.50 0.50 1"/>
                  <geom name="foot_left_sole" type="sphere" size="0.005" pos="0 0 -0.05" rgba="0 0 0 0"/>
                  <site name="left_foot_end" pos="0.15 0 -0.03" size="0.008" rgba="0 1 0 1"/>
                  <site name="left_foot_force" pos="0 0 -0.05"/>
                  <site name="left_foot_torque" pos="0 0 -0.05"/>
                </body>
              </body>
            </body>
          </body>
        </body>
      </body>
      <body name="R_hip_pitch_link" pos="0 -0.0734226 -0.0196735" quat="0.991445 0.130526 0 0">
        <inertial pos="0.0062436 -0.0504262 -0.014716" quat="0.519984 0.459924 0.700462 0.165648" mass="1.65592" diaginertia="0.00288142 0.00250814 0.00239465"/>
        <joint name="R_hip_pitch_joint" pos="0 0 0" axis="0 1 0" limited="true" range="-2.98 2.53"/>
        <geom type="mesh" contype="0" conaffinity="0" group="1" density="0" rgba="0.85 0.45 0.10 1" mesh="R_hip_pitch_link"/>
        <geom name="R_hip_pitch_collision" type="sphere" size="0.045" rgba="0.85 0.45 0.10 0.3"/>
        <body name="R_hip_roll_link" pos="0 -0.053579 -0.02" quat="0.991445 -0.130526 0 0">
          <inertial pos="0.00120761 -0.00204745 -0.033039" quat="0.502185 0.496301 0.487383 0.513764" mass="0.514808" diaginertia="0.00158819 0.00152639 0.000682655"/>
          <joint name="R_hip_roll_joint" pos="0 0 0" axis="1 0 0" limited="true" range="-2.059 0.314"/>
          <geom type="mesh" contype="0" conaffinity="0" group="1" density="0" rgba="0.90 0.62 0.15 1" mesh="R_hip_roll_link"/>
          <geom name="R_hip_roll_collision" type="sphere" size="0.065" pos="0 0 -0.033" rgba="0.90 0.62 0.15 0.3"/>
          <body name="R_hip_yaw_link" pos="0 0 -0.0621" quat="1 0 0 0">
            <inertial pos="-0.00120109 0.00740989 -0.123888" quat="0.688781 0.0189619 0.0104703 0.724645" mass="5.13155" diaginertia="0.0446208 0.04247 0.0109153"/>
            <joint name="R_hip_yaw_joint" pos="0 0 0" axis="0 0 1" limited="true" range="-3.246 2.146"/>
            <geom type="mesh" contype="0" conaffinity="0" group="1" density="0" rgba="0.85 0.75 0.10 1" mesh="R_hip_yaw_link"/>
            <geom name="R_hip_yaw_collision" type="capsule" size="0.07 0.18" pos="0 0 -0.13" rgba="0.85 0.75 0.10 0.3"/>
            <body name="R_knee_pitch_link" pos="-0.035 0 -0.3179" quat="1 0 0 0">
              <inertial pos="0.00271353 -0.00017413 -0.160478" quat="0.734924 0.0149851 0.0127119 0.677864" mass="3.32312" diaginertia="0.0369759 0.0367282 0.00345006"/>
              <joint name="R_knee_pitch_joint" pos="0 0 0" axis="0 1 0" limited="true" range="0.08 2.478"/>
              <geom type="mesh" contype="0" conaffinity="0" group="1" density="0" rgba="0.92 0.88 0.12 1" mesh="R_knee_pitch_link"/>
              <geom name="R_knee_pitch_collision" type="cylinder" size="0.05 0.16" pos="0 0 -0.2" rgba="0.92 0.88 0.12 0.3"/>
              <body name="R_ankle_pitch_link" pos="0 0 -0.41" quat="1 0 0 0">
                <inertial pos="0.00012374 0.00221434 -0.0057231" quat="-0.0378602 0.707362 -0.0409104 0.70465" mass="0.110584" diaginertia="4.6937e-05 3.42735e-05 2.57096e-05"/>
                <joint name="R_ankle_pitch_joint" pos="0 0 0" axis="0 1 0" limited="true" range="-1.012 0.488"/>
                <geom type="mesh" contype="0" conaffinity="0" group="1" density="0" rgba="0.15 0.65 0.60 1" mesh="R_ankle_pitch_link"/>
                <geom name="R_ankle_pitch_collision" type="sphere" size="0.035" rgba="0.15 0.65 0.60 0.3"/>
                <body name="R_ankle_roll_link" pos="0 0 -0.012" quat="1 0 0 0">
                  <inertial pos="0.0340612 2.01988e-06 -0.0209947" quat="-4.35034e-05 0.733434 -6.9335e-06 0.679761" mass="0.826921" diaginertia="0.00492003 0.00442443 0.00096887"/>
                  <joint name="R_ankle_roll_joint" pos="0 0 0" axis="1 0 0" limited="true" range="-0.401 0.401"/>
                  <geom type="mesh" contype="0" conaffinity="0" group="1" density="0" rgba="0.10 0.50 0.50 1" mesh="R_ankle_roll_link"/>
                  <geom name="R_ankle_roll_collision" type="box" size="0.095 0.05 0.015" pos="0.05 0 -0.045" rgba="1 1 1 0.3"/>
                  <geom name="R_foot_end_outer"      pos="-0.049  0.0  -0.045" size="0.005 0.005" type="cylinder" rgba="0.10 0.50 0.50 1" contype="0" conaffinity="0"/>
                  <geom name="R_foot_front_outer"    size="0.01 0.001" pos="0.155 -0.03 -0.045" type="cylinder" rgba="0.10 0.50 0.50 1" contype="0" conaffinity="0"/>
                  <geom name="R_foot_front_inner"    size="0.01 0.001" pos="0.145  0.03 -0.045" type="cylinder" rgba="0.10 0.50 0.50 1" contype="0" conaffinity="0"/>
                  <geom name="R_foot_mid_outer"      size="0.01 0.001" pos="0.045 -0.02 -0.045" type="cylinder" rgba="0.10 0.50 0.50 1" contype="0" conaffinity="0"/>
                  <geom name="R_foot_mid_inner"      size="0.01 0.001" pos="0.045  0.02 -0.045" type="cylinder" rgba="0.10 0.50 0.50 1" contype="0" conaffinity="0"/>
                  <geom name="R_foot_strip_outer"    size="0.01 0.001" pos="0.095 -0.01 -0.045" type="cylinder" rgba="0.10 0.50 0.50 1" contype="0" conaffinity="0"/>
                  <geom name="toe1_right_collision"  size="0.01 0.015" pos="0.155  0.03 -0.045" type="cylinder" rgba="0.10 0.50 0.50 1"/>
                  <geom name="toe2_right_collision"  size="0.01 0.015" pos="0.155 -0.03 -0.045" type="cylinder" rgba="0.10 0.50 0.50 1"/>
                  <geom name="foot_right_sole" type="sphere" size="0.005" pos="0 0 -0.05" rgba="0 0 0 0"/>
                  <site name="right_foot_end" pos="0.15 0 -0.03" size="0.008" rgba="1 0 0 1"/>
                  <site name="right_foot_force" pos="0 0 -0.05"/>
                  <site name="right_foot_torque" pos="0 0 -0.05"/>
                </body>
              </body>
            </body>
          </body>
        </body>
      </body>
      <body name="waist_yaw_link" pos="0 0 0.0766406" quat="1 0 0 0">
        <inertial pos="0.00270178 -0.00088235 0.0369526" quat="0.400373 0.42401 -0.529445 0.616121" mass="2.0613" diaginertia="0.0057903 0.00442111 0.00398297"/>
        <joint name="waist_yaw_joint" pos="0 0 0" axis="0 0 1" limited="true" range="-2.792 2.792"/>
        <geom type="mesh" contype="0" conaffinity="0" group="1" density="0" rgba="0.10 0.20 0.55 1" mesh="waist_yaw_link"/>
        <geom name="waist_yaw_collision" type="sphere" size="0.09" pos="0 0.007 -0.049" rgba="0.10 0.20 0.55 0.3"/>
        <body name="waist_pitch_link" pos="0.04 0 0.1155" quat="1 0 0 0">
          <inertial pos="-0.00141152 -0.00378014 -1.015e-05" quat="0.489842 0.49442 -0.504432 0.51103" mass="1.56616" diaginertia="0.00200827 0.00193456 0.0014908"/>
          <joint name="waist_pitch_joint" pos="0 0 0" axis="0 1 0" limited="true" range="-0.017 1.221"/>
          <geom type="mesh" contype="0" conaffinity="0" group="1" density="0" rgba="0.20 0.38 0.72 1" mesh="waist_pitch_link"/>
          <geom name="waist_pitch_collision" type="sphere" size="0.055" pos="0.002 0 -0.001" rgba="0.20 0.38 0.72 0.3"/>
          <body name="waist_roll_link" pos="-0.0515 0 0" quat="1 0 0 0">
            <inertial pos="-0.00232419 0.000109073 0.150683" quat="0.997895 0.00083228 0.0647555 -0.00354434" mass="13.3404" diaginertia="0.14941 0.126998 0.0780225"/>
            <joint name="waist_roll_joint" pos="0 0 0" axis="1 0 0" limited="true" range="-0.75 0.75"/>
            <geom type="mesh" contype="0" conaffinity="0" group="1" density="0" rgba="0.15 0.28 0.62 1" mesh="waist_roll_link"/>
            <geom name="waist_roll_collision" type="capsule" size="0.12 0.05" pos="0 0 0.1" rgba="0.15 0.28 0.62 0.3"/>
            <body name="L_shoulder_pitch_link" pos="0.0115 0.114262 0.247779" quat="0.996195 0.0871557 0 0">
              <inertial pos="0.00379496 0.0469029 -4.625e-05" quat="0.530969 0.396641 -0.559055 0.498202" mass="0.798422" diaginertia="0.000564005 0.000537541 0.000482404"/>
              <joint name="L_shoulder_pitch_joint" pos="0 0 0" axis="0 1 0" limited="true" range="-3.089 2.565"/>
              <geom type="mesh" contype="0" conaffinity="0" group="1" density="0" rgba="0.15 0.70 0.32 1" mesh="L_shoulder_pitch_link"/>
              <geom name="L_shoulder_pitch_collision" type="sphere" size="0.04" rgba="0.15 0.70 0.32 0.3"/>
              <body name="L_shoulder_roll_link" pos="0 0.0499 0" quat="1 0 0 0">
                <inertial pos="0.00388223 0.00090177 -0.0814423" quat="0.872628 0.0372716 0.135609 0.467698" mass="0.954452" diaginertia="0.00175475 0.00170192 0.000762658"/>
                <joint name="L_shoulder_roll_joint" pos="0 0 0" axis="1 0 0" limited="true" range="-0.139 1.884"/>
                <geom type="mesh" contype="0" conaffinity="0" group="1" density="0" rgba="0.20 0.72 0.35 1" mesh="L_shoulder_roll_link"/>
                <geom name="L_shoulder_roll_collision" type="capsule" size="0.028 0.055" pos="0 0 -0.063" quat="1 0 0 0" rgba="0.20 0.72 0.35 0.3"/>
                <body name="L_shoulder_yaw_link" pos="0 0 -0.12675" quat="1 0 0 0">
                  <inertial pos="-0.00111624 -0.00509191 -0.0777859" quat="0.726587 -0.0403648 0.0185064 0.685638" mass="0.951576" diaginertia="0.0013695 0.00135249 0.000633425"/>
                  <joint name="L_shoulder_yaw_joint" pos="0 0 0" axis="0 0 1" limited="true" range="-2.844 2.844"/>
                  <geom type="mesh" contype="0" conaffinity="0" group="1" density="0" rgba="0.25 0.75 0.38 1" mesh="L_shoulder_yaw_link"/>
                  <geom name="L_shoulder_yaw_collision" type="cylinder" size="0.035 0.05" pos="0 0 -0.08" rgba="0.25 0.75 0.38 0.3"/>
                  <body name="L_elbow_pitch_link" pos="0 0 -0.09325" quat="1 0 0 0">
                    <inertial pos="-0.00109585 -0.00301164 -0.0816298" quat="0.965846 0.115424 -0.0658207 0.222454" mass="0.910303" diaginertia="0.00151258 0.00147365 0.000681226"/>
                    <joint name="L_elbow_pitch_joint" pos="0 0 0" axis="0 1 0" limited="true" range="-2.2689 0.104"/>
                    <geom type="mesh" contype="0" conaffinity="0" group="1" density="0" rgba="0.75 0.20 0.10 1" mesh="L_elbow_pitch_link"/>
                    <geom name="L_elbow_pitch_collision" type="sphere" size="0.04" pos="-0.002 0 -0.08" rgba="0.75 0.20 0.10 0.3"/>
                    <body name="L_elbow_yaw_link" pos="0 0 -0.12425" quat="1 0 0 0">
                      <inertial pos="0.00041996 0.00835103 -0.0205441" quat="0.658348 0.351515 -0.319902 0.583676" mass="0.0923308" diaginertia="8.7254e-05 8.15789e-05 5.94071e-05"/>
                      <joint name="L_elbow_yaw_joint" pos="0 0 0" axis="0 0 1" limited="true" range="-2.844 2.844"/>
                      <geom type="mesh" contype="0" conaffinity="0" group="1" density="0" rgba="0.78 0.25 0.15 1" mesh="L_elbow_yaw_link"/>
                      <geom name="L_elbow_yaw_collision" type="sphere" size="0.03" pos="0.001 -0.002 -0.026" rgba="0.78 0.25 0.15 0.3"/>
                      <body name="L_wrist_pitch_link" pos="0 0 -0.05575" quat="1 0 0 0">
                        <inertial pos="0.00244378 0.00252389 -0.0194028" quat="0.55381 -0.111462 0.0117937 0.825064" mass="0.498236" diaginertia="0.00033589 0.000333064 0.000165096"/>
                        <joint name="L_wrist_pitch_joint" pos="0 0 0" axis="0 1 0" limited="true" range="-0.68 0.68"/>
                        <geom type="mesh" contype="0" conaffinity="0" group="1" density="0" rgba="0.55 0.15 0.75 1" mesh="L_wrist_pitch_link"/>
                        <geom name="L_wrist_pitch_collision" type="sphere" size="0.03" rgba="0.55 0.15 0.75 0.3"/>
                        <body name="L_wrist_roll_link" pos="0 0 -0.0399515" quat="1 0 0 0">
                          <inertial pos="0.0085537 -1.437e-05 -0.021913" quat="0.586057 0.395648 0.395648 0.586057" mass="0.0476664" diaginertia="4.753e-05 4.13777e-05 1.91423e-05"/>
                          <joint name="L_wrist_roll_joint" pos="0 0 0" axis="1 0 0" limited="true" range="-1.57 1.57"/>
                          <geom type="mesh" contype="0" conaffinity="0" group="1" density="0" rgba="0.65 0.28 0.82 1" mesh="L_wrist_roll_link"/>
                          <geom name="L_wrist_roll_collision" type="sphere" size="0.02" pos="0.02 0 -0.01" rgba="0.65 0.28 0.82 0.3"/>
                          <geom name="hand_l_base_collision" type="capsule" size="0.025 0.025" pos="-0.004 -0.002 -0.084" rgba="0.65 0.28 0.82 0.5"/>
                          <geom name="hand_l_palm_collision" type="box" size="0.035 0.015 0.04" pos="0 -0.005 -0.21" rgba="0.65 0.28 0.82 0.5"/>

                          <!-- Left hand from S2 -->
                          <geom pos="-0.0044948 -0.0019462 -0.084379" quat="0.999994 -0.00244449 0.00257359 6.29115e-06" type="mesh" contype="0" conaffinity="0" group="1" density="0" rgba="0.65 0.28 0.82 1" mesh="L_hand_base_link"/>
                          <geom pos="9.82685e-05 -0.00183303 -0.0699028" quat="-0.00258616 -0.00388747 0.999988 -0.00163816" type="mesh" contype="0" conaffinity="0" group="1" density="0" rgba="0.65 0.28 0.82 1" mesh="L_hand_base_link"/>
                          <geom pos="-0.000669534 -0.0153602 -0.169634" quat="0.501464 0.49594 0.50241 -0.500162" type="mesh" contype="0" conaffinity="0" group="1" density="0" rgba="0.65 0.28 0.82 1" mesh="L_palm_link"/>
                          <geom pos="0.0284784 -0.00761078 -0.121231" quat="0.931513 -0.00247393 0.00180091 -0.363696" type="mesh" contype="0" conaffinity="0" group="1" density="0" rgba="0.65 0.28 0.82 1" mesh="L_thumb_cmp_link"/>
                          <geom pos="0.0365366 -0.0165513 -0.131288" quat="0.621471 -0.693899 0.271482 -0.242024" type="mesh" contype="0" conaffinity="0" group="1" density="0" rgba="0.65 0.28 0.82 1" mesh="L_thumb_mpp_link"/>
                          <geom pos="0.0916958 -0.0673692 -0.131393" quat="0.621471 -0.693899 0.271482 -0.242024" type="mesh" contype="0" conaffinity="0" group="1" density="0" rgba="0.65 0.28 0.82 1" mesh="L_thumb_ip_link"/>
                          <geom pos="0.0297915 -0.00356363 -0.211648" quat="0.0673628 0.709576 -0.0628232 -0.698582" type="mesh" contype="0" conaffinity="0" group="1" density="0" rgba="0.65 0.28 0.82 1" mesh="L_index_mpp_link"/>
                          <geom pos="0.0304151 -0.0106746 -0.249786" quat="0.0622932 0.710013 -0.0576739 -0.699053" type="mesh" contype="0" conaffinity="0" group="1" density="0" rgba="0.65 0.28 0.82 1" mesh="L_index_ip_link"/>
                          <geom pos="0.00937837 -0.00372277 -0.211747" quat="0.0680224 0.702523 -0.0622217 -0.705665" type="mesh" contype="0" conaffinity="0" group="1" density="0" rgba="0.65 0.28 0.82 1" mesh="L_middle_mpp_link"/>
                          <geom pos="0.00923598 -0.0108397 -0.249889" quat="0.0637639 0.702885 -0.0579823 -0.706063" type="mesh" contype="0" conaffinity="0" group="1" density="0" rgba="0.65 0.28 0.82 1" mesh="L_middle_ip_link"/>
                          <geom pos="-0.0110327 -0.00388055 -0.211436" quat="0.0686751 0.695399 -0.061614 -0.712677" type="mesh" contype="0" conaffinity="0" group="1" density="0" rgba="0.65 0.28 0.82 1" mesh="L_ring_mpp_link"/>
                          <geom pos="-0.011941 -0.0110034 -0.249566" quat="0.0635032 0.695827 -0.0565677 -0.713156" type="mesh" contype="0" conaffinity="0" group="1" density="0" rgba="0.65 0.28 0.82 1" mesh="L_ring_ip_link"/>
                          <geom pos="-0.0314336 -0.00403693 -0.210717" quat="0.069321 0.688204 -0.0610001 -0.719617" type="mesh" contype="0" conaffinity="0" group="1" density="0" rgba="0.65 0.28 0.82 1" mesh="L_little_mpp_link"/>
                          <geom pos="-0.0331074 -0.0111657 -0.248819" quat="0.0640988 0.688629 -0.056006 -0.720101" type="mesh" contype="0" conaffinity="0" group="1" density="0" rgba="0.65 0.28 0.82 1" mesh="L_little_ip_link"/>
                        </body>
                      </body>
                    </body>
                  </body>
                </body>
              </body>
            </body>
            <body name="R_shoulder_pitch_link" pos="0.0115 -0.11481 0.247779" quat="0.996195 -0.0871557 0 0">
              <inertial pos="0.00384148 -0.046973 7.92e-06" quat="0.443496 0.539557 -0.491243 0.520451" mass="0.79994" diaginertia="0.000563949 0.000536866 0.000485635"/>
              <joint name="R_shoulder_pitch_joint" pos="0 0 0" axis="0 1 0" limited="true" range="-3.089 2.565"/>
              <geom type="mesh" contype="0" conaffinity="0" group="1" density="0" rgba="0.15 0.70 0.32 1" mesh="R_shoulder_pitch_link"/>
              <geom name="R_shoulder_pitch_collision" type="sphere" size="0.04" rgba="0.15 0.70 0.32 0.3"/>
              <body name="R_shoulder_roll_link" pos="0 -0.0499 0" quat="1 0 0 0">
                <inertial pos="0.00374986 -0.00090026 -0.0814559" quat="0.475045 0.134535 0.0380022 0.868786" mass="0.954183" diaginertia="0.00175385 0.00170009 0.000764477"/>
                <joint name="R_shoulder_roll_joint" pos="0 0 0" axis="1 0 0" limited="true" range="-1.884 0.139"/>
                <geom type="mesh" contype="0" conaffinity="0" group="1" density="0" rgba="0.20 0.72 0.35 1" mesh="R_shoulder_roll_link"/>
                <geom name="R_shoulder_roll_collision" type="capsule" size="0.028 0.055" pos="0 0 -0.063" quat="1 0 0 0" rgba="0.20 0.72 0.35 0.3"/>
                <body name="R_shoulder_yaw_link" pos="0 0 -0.12675" quat="1 0 0 0">
                  <inertial pos="-0.00111484 -0.00508263 -0.0776773" quat="0.726766 -0.0401509 0.0186017 0.685458" mass="0.952713" diaginertia="0.00137689 0.00135996 0.000633578"/>
                  <joint name="R_shoulder_yaw_joint" pos="0 0 0" axis="0 0 1" limited="true" range="-2.844 2.844"/>
                  <geom type="mesh" contype="0" conaffinity="0" group="1" density="0" rgba="0.25 0.75 0.38 1" mesh="R_shoulder_yaw_link"/>
                  <geom name="R_shoulder_yaw_collision" type="cylinder" size="0.035 0.05" pos="0 0 -0.08" rgba="0.25 0.75 0.38 0.3"/>
                  <body name="R_elbow_pitch_link" pos="0 0 -0.09325" quat="1 0 0 0">
                    <inertial pos="-0.00109585 -0.00301164 -0.0816298" quat="0.965858 0.115427 -0.0658144 0.222405" mass="0.910303" diaginertia="0.00151259 0.00147365 0.000681226"/>
                    <joint name="R_elbow_pitch_joint" pos="0 0 0" axis="0 1 0" limited="true" range="-2.2689 0.104"/>
                    <geom type="mesh" contype="0" conaffinity="0" group="1" density="0" rgba="0.75 0.20 0.10 1" mesh="R_elbow_pitch_link"/>
                    <geom name="R_elbow_pitch_collision" type="sphere" size="0.04" pos="-0.002 0 -0.08" rgba="0.75 0.20 0.10 0.3"/>
                    <body name="R_elbow_yaw_link" pos="0 0 -0.12425" quat="1 0 0 0">
                      <inertial pos="0.00042308 0.00819376 -0.0202823" quat="0.654539 0.356415 -0.325593 0.581839" mass="0.0916493" diaginertia="8.62948e-05 8.04003e-05 5.91449e-05"/>
                      <joint name="R_elbow_yaw_joint" pos="0 0 0" axis="0 0 1" limited="true" range="-2.844 2.844"/>
                      <geom type="mesh" contype="0" conaffinity="0" group="1" density="0" rgba="0.78 0.25 0.15 1" mesh="R_elbow_yaw_link"/>
                      <geom name="R_elbow_yaw_collision" type="sphere" size="0.03" pos="-0.001 0.002 -0.026" rgba="0.78 0.25 0.15 0.3"/>
                      <body name="R_wrist_pitch_link" pos="0 0 -0.05575" quat="1 0 0 0">
                        <inertial pos="0.00244378 0.00252389 -0.0194028" quat="0.55381 -0.111462 0.0117937 0.825064" mass="0.498236" diaginertia="0.00033589 0.000333064 0.000165096"/>
                        <joint name="R_wrist_pitch_joint" pos="0 0 0" axis="0 1 0" limited="true" range="-0.68 0.68"/>
                        <geom type="mesh" contype="0" conaffinity="0" group="1" density="0" rgba="0.55 0.15 0.75 1" mesh="R_wrist_pitch_link"/>
                        <geom name="R_wrist_pitch_collision" type="sphere" size="0.03" rgba="0.55 0.15 0.75 0.3"/>
                        <body name="R_wrist_roll_link" pos="0 0 -0.0399515" quat="1 0 0 0">
                          <inertial pos="0.0085537 -1.437e-05 -0.021913" quat="0.586057 0.395648 0.395648 0.586057" mass="0.0476664" diaginertia="4.753e-05 4.13777e-05 1.91423e-05"/>
                          <joint name="R_wrist_roll_joint" pos="0 0 0" axis="1 0 0" limited="true" range="-1.57 1.57"/>
                          <geom type="mesh" contype="0" conaffinity="0" group="1" density="0" rgba="0.65 0.28 0.82 1" mesh="R_wrist_roll_link"/>
                          <geom name="R_wrist_roll_collision" type="sphere" size="0.02" pos="0.02 0 0.01" rgba="0.65 0.28 0.82 0.3"/>
                          <geom name="hand_r_base_collision" type="capsule" size="0.025 0.025" pos="0.002 -0.002 -0.082" rgba="0.65 0.28 0.82 0.5"/>
                          <geom name="hand_r_palm_collision" type="box" size="0.035 0.015 0.04" pos="0 0.005 -0.21" rgba="0.65 0.28 0.82 0.5"/>

                          <!-- Right hand from S2 -->
                          <geom pos="0.0022054 -0.0019134 -0.081806" quat="0.999997 -0.00243675 0 0" type="mesh" contype="0" conaffinity="0" group="1" density="0" rgba="0.65 0.28 0.82 1" mesh="R_hand_base_link"/>
                          <geom pos="6.97036e-05 -0.00280912 -0.0674472" quat="0.00079634 0.999998 1.38929e-06 -0.00174477" type="mesh" contype="0" conaffinity="0" group="1" density="0" rgba="0.65 0.28 0.82 1" mesh="R_hand_base_link"/>
                          <geom pos="7.84698e-05 0.0102279 -0.167247" quat="-0.498728 0.499524 -0.501271 -0.500474" type="mesh" contype="0" conaffinity="0" group="1" density="0" rgba="0.65 0.28 0.82 1" mesh="R_palm_link"/>
                          <geom pos="0.029204 0.00294042 -0.118758" quat="-0.930095 9.80899e-05 -0.00191599 -0.367313" type="mesh" contype="0" conaffinity="0" group="1" density="0" rgba="0.65 0.28 0.82 1" mesh="R_thumb_cmp_link"/>
                          <geom pos="0.0372094 0.0118945 -0.128846" quat="-0.691144 0.622417 0.244408 -0.274193" type="mesh" contype="0" conaffinity="0" group="1" density="0" rgba="0.65 0.28 0.82 1" mesh="R_thumb_mpp_link"/>
                          <geom pos="0.0919719 0.0631391 -0.129107" quat="-0.689475 0.623882 0.240644 -0.278363" type="mesh" contype="0" conaffinity="0" group="1" density="0" rgba="0.65 0.28 0.82 1" mesh="R_thumb_ip_link"/>
                          <geom pos="0.0307022 -0.00153475 -0.209153" quat="-0.71007 -0.062872 -0.698397 -0.0639405" type="mesh" contype="0" conaffinity="0" group="1" density="0" rgba="0.65 0.28 0.82 1" mesh="R_index_mpp_link"/>
                          <geom pos="0.0313349 0.00539585 -0.247324" quat="-0.710515 -0.0578039 -0.698835 -0.0587877" type="mesh" contype="0" conaffinity="0" group="1" density="0" rgba="0.65 0.28 0.82 1" mesh="R_index_ip_link"/>
                          <geom pos="0.0110386 -0.00153501 -0.209289" quat="-0.696165 -0.0629199 -0.712259 -0.0638885" type="mesh" contype="0" conaffinity="0" group="1" density="0" rgba="0.65 0.28 0.82 1" mesh="R_middle_mpp_link"/>
                          <geom pos="0.0101542 0.00539532 -0.247461" quat="-0.703394 -0.059278 -0.705859 -0.0590342" type="mesh" contype="0" conaffinity="0" group="1" density="0" rgba="0.65 0.28 0.82 1" mesh="R_middle_ip_link"/>
                          <geom pos="-0.0101245 -0.0015346 -0.209011" quat="-0.695913 -0.0641649 -0.712506 -0.0626431" type="mesh" contype="0" conaffinity="0" group="1" density="0" rgba="0.65 0.28 0.82 1" mesh="R_ring_mpp_link"/>
                          <geom pos="-0.0110238 0.005396 -0.247176" quat="-0.696349 -0.0589944 -0.712952 -0.057593" type="mesh" contype="0" conaffinity="0" group="1" density="0" rgba="0.65 0.28 0.82 1" mesh="R_ring_ip_link"/>
                          <geom pos="-0.0305273 -0.00153355 -0.208324" quat="-0.688728 -0.0648017 -0.719453 -0.0619848" type="mesh" contype="0" conaffinity="0" group="1" density="0" rgba="0.65 0.28 0.82 1" mesh="R_little_mpp_link"/>
                          <geom pos="-0.0321921 0.0053971 -0.246464" quat="-0.68916 -0.0595808 -0.719904 -0.0569869" type="mesh" contype="0" conaffinity="0" group="1" density="0" rgba="0.65 0.28 0.82 1" mesh="R_little_ip_link"/>
                        </body>
                      </body>
                    </body>
                  </body>
                </body>
              </body>
            </body>
            <body name="head_yaw_link" pos="0.0115 0 0.34305" quat="1 0 0 0">
              <inertial pos="-0.00204647 0.00017996 -0.0311295" quat="0.998472 -0.0427876 -0.0328741 0.0119403" mass="0.241515" diaginertia="0.000104403 9.81746e-05 8.85421e-05"/>
              <joint name="head_yaw_joint" pos="0 0 0" axis="0 0 1" limited="true" range="-1.658 1.658"/>
              <geom type="mesh" contype="0" conaffinity="0" group="1" density="0" rgba="0.50 0.50 0.55 1" mesh="head_yaw_link"/>
              <geom name="head_yaw_collision" type="sphere" size="0.06" pos="0 0 0.03" rgba="0.50 0.50 0.55 0.3"/>
              <body name="head_pitch_link" pos="0 0 0.0265" quat="1 0 0 0">
                <inertial pos="0.0264729 0.000539383 0.0592949" quat="0.69872 0.13006 0.119811 0.693196" mass="1.13866" diaginertia="0.00599062 0.00547547 0.00296305"/>
                <joint name="head_pitch_joint" pos="0 0 0" axis="0 1 0" limited="true" range="-0.523 0.785"/>
                <geom type="mesh" contype="0" conaffinity="0" group="1" density="0" rgba="0.60 0.60 0.65 1" mesh="head_pitch_link"/>
                <geom name="head_pitch_collision" type="capsule" size="0.055 0.035" pos="0.026 0 0.075" rgba="0.60 0.60 0.65 0.3"/>
              </body>
            </body>
          </body>
        </body>
      </body>
    </body>
  </worldbody>
  <actuator>
    <motor name="L_hip_pitch_joint" joint="L_hip_pitch_joint" gear="1" ctrllimited="true" ctrlrange="-100 100"/>
    <motor name="L_hip_roll_joint" joint="L_hip_roll_joint" gear="1" ctrllimited="true" ctrlrange="-100 100"/>
    <motor name="L_hip_yaw_joint" joint="L_hip_yaw_joint" gear="1" ctrllimited="true" ctrlrange="-100 100"/>
    <motor name="L_knee_pitch_joint" joint="L_knee_pitch_joint" gear="1" ctrllimited="true" ctrlrange="-100 100"/>
    <motor name="L_ankle_pitch_joint" joint="L_ankle_pitch_joint" gear="1" ctrllimited="true" ctrlrange="-100 100"/>
    <motor name="L_ankle_roll_joint" joint="L_ankle_roll_joint" gear="1" ctrllimited="true" ctrlrange="-100 100"/>
    <motor name="R_hip_pitch_joint" joint="R_hip_pitch_joint" gear="1" ctrllimited="true" ctrlrange="-100 100"/>
    <motor name="R_hip_roll_joint" joint="R_hip_roll_joint" gear="1" ctrllimited="true" ctrlrange="-100 100"/>
    <motor name="R_hip_yaw_joint" joint="R_hip_yaw_joint" gear="1" ctrllimited="true" ctrlrange="-100 100"/>
    <motor name="R_knee_pitch_joint" joint="R_knee_pitch_joint" gear="1" ctrllimited="true" ctrlrange="-100 100"/>
    <motor name="R_ankle_pitch_joint" joint="R_ankle_pitch_joint" gear="1" ctrllimited="true" ctrlrange="-100 100"/>
    <motor name="R_ankle_roll_joint" joint="R_ankle_roll_joint" gear="1" ctrllimited="true" ctrlrange="-100 100"/>
    <motor name="waist_yaw_joint" joint="waist_yaw_joint" gear="1" ctrllimited="true" ctrlrange="-100 100"/>
    <motor name="waist_pitch_joint" joint="waist_pitch_joint" gear="1" ctrllimited="true" ctrlrange="-100 100"/>
    <motor name="waist_roll_joint" joint="waist_roll_joint" gear="1" ctrllimited="true" ctrlrange="-100 100"/>
    <motor name="L_shoulder_pitch_joint" joint="L_shoulder_pitch_joint" gear="1" ctrllimited="true" ctrlrange="-100 100"/>
    <motor name="L_shoulder_roll_joint" joint="L_shoulder_roll_joint" gear="1" ctrllimited="true" ctrlrange="-100 100"/>
    <motor name="L_shoulder_yaw_joint" joint="L_shoulder_yaw_joint" gear="1" ctrllimited="true" ctrlrange="-100 100"/>
    <motor name="L_elbow_pitch_joint" joint="L_elbow_pitch_joint" gear="1" ctrllimited="true" ctrlrange="-100 100"/>
    <motor name="L_elbow_yaw_joint" joint="L_elbow_yaw_joint" gear="1" ctrllimited="true" ctrlrange="-100 100"/>
    <motor name="L_wrist_pitch_joint" joint="L_wrist_pitch_joint" gear="1" ctrllimited="true" ctrlrange="-100 100"/>
    <motor name="L_wrist_roll_joint" joint="L_wrist_roll_joint" gear="1" ctrllimited="true" ctrlrange="-100 100"/>
    <motor name="R_shoulder_pitch_joint" joint="R_shoulder_pitch_joint" gear="1" ctrllimited="true" ctrlrange="-100 100"/>
    <motor name="R_shoulder_roll_joint" joint="R_shoulder_roll_joint" gear="1" ctrllimited="true" ctrlrange="-100 100"/>
    <motor name="R_shoulder_yaw_joint" joint="R_shoulder_yaw_joint" gear="1" ctrllimited="true" ctrlrange="-100 100"/>
    <motor name="R_elbow_pitch_joint" joint="R_elbow_pitch_joint" gear="1" ctrllimited="true" ctrlrange="-100 100"/>
    <motor name="R_elbow_yaw_joint" joint="R_elbow_yaw_joint" gear="1" ctrllimited="true" ctrlrange="-100 100"/>
    <motor name="R_wrist_pitch_joint" joint="R_wrist_pitch_joint" gear="1" ctrllimited="true" ctrlrange="-100 100"/>
    <motor name="R_wrist_roll_joint" joint="R_wrist_roll_joint" gear="1" ctrllimited="true" ctrlrange="-100 100"/>
    <motor name="head_yaw_joint" joint="head_yaw_joint" gear="1" ctrllimited="true" ctrlrange="-100 100"/>
    <motor name="head_pitch_joint" joint="head_pitch_joint" gear="1" ctrllimited="true" ctrlrange="-100 100"/>
  </actuator>
  <sensor>
    <framequat name="orientation" objtype="site" noise="0.001" objname="imu"/>
    <framepos name="position" objtype="site" noise="0.001" objname="imu"/>
    <gyro name="angular-velocity" site="imu" noise="0.005" cutoff="34.9"/>
    <accelerometer name="linear-acceleration" site="imu" noise="0.002" cutoff="40"/>
    <velocimeter name="linear-velocity" site="imu" noise="0.001" cutoff="30"/>
    <force name="left-foot-force" site="left_foot_force"/>
    <torque name="left-foot-torque" site="left_foot_torque"/>
    <force name="right-foot-force" site="right_foot_force"/>
    <torque name="right-foot-torque" site="right_foot_torque"/>
  </sensor>
</mujoco>