<mujoco model="walker_astron">
  <compiler angle="radian" meshdir="meshes/" boundmass="0.0001"/>
  <statistic meansize="0.140456" extent="1.93199" center="-0.0165219 -8.18765e-05 -0.0755538"/>
  <default>
    <joint damping="1.0" frictionloss="0.2" armature="0.01"/>
  </default>
  <asset>
    <mesh name="base_link" file="base_link.STL"/>
    <mesh name="R_hip_pitch_link" file="R_hip_pitch_link.STL"/>
    <mesh name="R_hip_roll_link" file="R_hip_roll_link.STL"/>
    <mesh name="R_hip_yaw_link" file="R_hip_yaw_link.STL"/>
    <mesh name="R_knee_pitch_link" file="R_knee_pitch_link.STL"/>
    <mesh name="R_ankle_pitch_link" file="R_ankle_pitch_link.STL"/>
    <mesh name="R_ankle_roll_link" file="R_ankle_roll_link.STL"/>
    <mesh name="L_hip_pitch_link" file="L_hip_pitch_link.STL"/>
    <mesh name="L_hip_roll_link" file="L_hip_roll_link.STL"/>
    <mesh name="L_hip_yaw_link" file="L_hip_yaw_link.STL"/>
    <mesh name="L_knee_pitch_link" file="L_knee_pitch_link.STL"/>
    <mesh name="L_ankle_pitch_link" file="L_ankle_pitch_link.STL"/>
    <mesh name="L_ankle_roll_link" file="L_ankle_roll_link.STL"/>
    <mesh name="waist_yaw_link" file="waist_yaw_link.STL"/>
    <mesh name="waist_pitch_link" file="waist_pitch_link.STL"/>
    <mesh name="waist_roll_link" file="waist_roll_link.STL"/>
    <mesh name="L_shoulder_pitch_link" file="L_shoulder_pitch_link.STL"/>
    <mesh name="L_shoulder_roll_link" file="L_shoulder_roll_link.STL"/>
    <mesh name="L_shoulder_yaw_link" file="L_shoulder_yaw_link.STL"/>
    <mesh name="L_elbow_pitch_link" file="L_elbow_pitch_link.STL"/>
    <mesh name="L_elbow_yaw_link" file="L_elbow_yaw_link.STL"/>
    <mesh name="L_wrist_pitch_link" file="L_wrist_pitch_link.STL"/>
    <mesh name="L_wrist_roll_link" file="L_wrist_roll_link.STL"/>
    <mesh name="R_shoulder_pitch_link" file="R_shoulder_pitch_link.STL"/>
    <mesh name="R_shoulder_roll_link" file="R_shoulder_roll_link.STL"/>
    <mesh name="R_shoulder_yaw_link" file="R_shoulder_yaw_link.STL"/>
    <mesh name="R_elbow_pitch_link" file="R_elbow_pitch_link.STL"/>
    <mesh name="R_elbow_yaw_link" file="R_elbow_yaw_link.STL"/>
    <mesh name="R_wrist_pitch_link" file="R_wrist_pitch_link.STL"/>
    <mesh name="R_wrist_roll_link" file="R_wrist_roll_link.STL"/>
    <mesh name="head_yaw_link" file="head_yaw_link.STL"/>
    <mesh name="head_pitch_link" file="head_pitch_link.STL"/>
  </asset>

  <worldbody>
    <body name="base_link" pos="0 0 0.91">
      <inertial pos="-0.00060742 0 -0.0039046" quat="0.707095 0.70711 0.00349032 -0.000856356" mass="5.3292" diaginertia="0.0256182 0.0239749 0.0175109"/>
      <joint name="floating_base" type="free"/>
      <geom type="mesh" contype="0" conaffinity="0" group="1" density="0" rgba="0.71373 0.48235 1 1" mesh="base_link"/>
      <geom type="mesh" rgba="0.71373 0.48235 1 1" mesh="base_link"/>
      <geom name="base_link_collision" size="0.06" type="sphere" pos="0 0 -0.004" rgba="0.71373 0.48235 1 0.3"/>
      <body name="body_imu_link" quat="0.707107 0 0 -0.707107">
        <inertial pos="0 0 0" mass="0.0001" diaginertia="1e-09 1e-09 1e-09"/>
        <geom size="0.005 0.005 0.005" type="box" contype="0" conaffinity="0" group="1" density="0" rgba="0 0 1 1"/>
        <site name='imu' size='0.01' pos="0 0 0"/>
      </body>

      <!-- RIGHT_LEG -->
      <body name="R_hip_pitch_link" pos="0 -0.073499 -0.019694" quat="0.60876 0.793355 0 0">
        <inertial pos="0.0062436 -0.014716 0.050426" quat="0.378165 0.612428 0.0424705 0.692906" mass="1.6559" diaginertia="0.00288145 0.00250818 0.00239467"/>
        <joint name="R_hip_pitch_joint" pos="0 0 0" axis="0 0 1" limited="true" range="-2.574 3.028" actuatorfrcrange="-210 210" armature="0.01"/>
        <geom type="mesh" contype="0" conaffinity="0" group="1" density="0" rgba="0.19608 0.19608 0.19608 1" mesh="R_hip_pitch_link"/>
        <!-- <geom type="mesh" rgba="0.19608 0.19608 0.19608 1" mesh="R_hip_pitch_link"/> -->
        <body name="R_hip_roll_link" pos="0 -0.02 0.053579" quat="0.560984 0.430459 0.560987 0.430459">
          <inertial pos="-0.033039 0.00204746 0.00120761" quat="0.699731 0.0123354 0.0104537 0.714223" mass="0.514808" diaginertia="0.00158819 0.00152639 0.000682657"/>
          <joint name="R_hip_roll_joint" pos="0 0 0" axis="0 0 1" limited="true" range="-2.094 0.349" actuatorfrcrange="-165 165" armature="0.01"/>
          <geom type="mesh" contype="0" conaffinity="0" group="1" density="0" rgba="0.698039 0.698039 0.698039 1" mesh="R_hip_roll_link"/>
          <geom name="R_hip_roll_collision" size="0.065 0.13" pos="-0.21 0 0" quat="0.707 0.0 0.707 0.0" type="cylinder" rgba="0.778 0.778 0.006 1"/>
          <!-- <geom type="mesh" rgba="0.698039 0.698039 0.698039 1" mesh="R_hip_roll_link"/> -->
          <body name="R_hip_yaw_link" pos="-0.0621 0 0" quat="0.499998 0.5 -0.500002 -0.5">
            <inertial pos="0.00740989 -0.00120109 0.123888" quat="0.999444 0.0208117 0.00600455 -0.0253666" mass="5.13155" diaginertia="0.0446208 0.04247 0.0109153"/>
            <joint name="R_hip_yaw_joint" pos="0 0 0" axis="0 0 1" limited="true" range="-2.1816 3.2812" actuatorfrcrange="-110 110" armature="0.01"/>
            <geom type="mesh" contype="0" conaffinity="0" group="1" density="0" rgba="0.698039 0.698039 0.698039 1" mesh="R_hip_yaw_link"/>
            <!-- <geom type="mesh" rgba="0.698039 0.698039 0.698039 1" mesh="R_hip_yaw_link"/> -->
            <geom name="R_hip_yaw_collision" type="capsule" size="0.07 0.18" pos="0 0 0.13" rgba="0.698039 0.698039 0.698039 0.3"/>
            <body name="R_knee_pitch_link" pos="0 -0.035 0.3179" quat="0.499998 0.5 -0.500002 -0.5">
              <inertial pos="-0.00271353 0.160478 0.00017413" quat="0.530221 0.509023 -0.48836 0.470389" mass="3.32312" diaginertia="0.0369759 0.0367282 0.00345006"/>
              <joint name="R_knee_pitch_joint" pos="0 0 0" axis="0 0 1" limited="true" range="-2.526 0.179" actuatorfrcrange="-210 210" armature="0.01"/>
              <geom type="mesh" contype="0" conaffinity="0" group="1" density="0" rgba="0.792157 0.819608 0.933333 1" mesh="R_knee_pitch_link"/>
              <!-- <geom type="mesh" rgba="0.792157 0.819608 0.933333 1" mesh="R_knee_pitch_link"/> -->
              <geom name="R_knee_pitch_collision" size="0.05 0.16" pos="0 0.2 0" quat="0.707105 0.707108 0 0" type="cylinder" rgba="0.778 0.778 0.006 1"/>
              <body name="R_ankle_pitch_link" pos="0 0.41 0" quat="0.707105 0 0 0.707108">
                <inertial pos="0.0057231 0.000124 -0.00221" quat="0.704487 0.707542 0.0378779 -0.0405859" mass="0.110584" diaginertia="4.69564e-05 3.42441e-05 2.56996e-05"/>
                <joint name="R_ankle_pitch_joint" pos="0 0 0" axis="0 0 1" limited="true" range="-0.5236 1.047" actuatorfrcrange="-60 60" armature="0.01"/>
                <geom type="mesh" contype="0" conaffinity="0" group="1" density="0" rgba="0.627451 0.627451 0.627451 1" mesh="R_ankle_pitch_link"/>
                <!-- <geom type="mesh" rgba="0.627451 0.627451 0.627451 1" mesh="R_ankle_pitch_link"/> -->
                <body name="R_ankle_roll_link" pos="0.012 0 0" quat="-2.59734e-06 -2.59735e-06 0.707108 0.707105">
                  <inertial pos="-0.020996 -2.02e-06 0.0340632" quat="0.99928 2.5859e-05 -0.0379487 3.56633e-05" mass="0.826871" diaginertia="0.00491997 0.00442435 0.000968853"/>
                  <joint name="R_ankle_roll_joint" pos="0 0 0" axis="0 0 1" limited="true" range="-0.436 0.436" actuatorfrcrange="-60 60" armature="0.01"/>
                  <geom type="mesh" contype="0" conaffinity="0" group="1" density="0" rgba="0.698039 0.698039 0.698039 1" mesh="R_ankle_roll_link"/>
                  <!-- <geom type="mesh" rgba="0.698039 0.698039 0.698039 1" mesh="R_ankle_roll_link"/> -->
                  <geom name="R_ankle_roll_collision" size="0.015 0.05 0.125" pos="-0.034 0 0.045" type="box" rgba="1 1 1 1" />
                  <geom name="R_foot_end_outer"      pos="-0.049  0.0   -0.08" size="0.005 0.005" quat="0.707105 0 0.707108 0" type="cylinder" rgba="0.10 0.50 0.50 1" contype="0" conaffinity="0"/>
                  <geom name="R_foot_front_outer"    size="0.01 0.001" pos="-0.049 -0.03  0.155" quat="0.707105 0 0.707108 0" type="cylinder" rgba="0.10 0.50 0.50 1" contype="0" conaffinity="0"/>
                  <geom name="R_foot_front_inner"    size="0.01 0.001" pos="-0.049  0.03  0.145" quat="0.707105 0 0.707108 0" type="cylinder" rgba="0.10 0.50 0.50 1" contype="0" conaffinity="0"/>
                  <geom name="R_foot_mid_outer"      size="0.01 0.001" pos="-0.049 -0.02  0.045" quat="0.707105 0 -0.707108 0" type="cylinder" rgba="0.10 0.50 0.50 1" contype="0" conaffinity="0"/>
                  <geom name="R_foot_mid_inner"      size="0.01 0.001" pos="-0.049  0.02  0.045" quat="0.707105 0 -0.707108 0" type="cylinder" rgba="0.10 0.50 0.50 1" contype="0" conaffinity="0"/>
                  <geom name="R_foot_strip_outer"    size="0.01 0.001" pos="-0.049 -0.01  0.095" quat="0.707105 0 -0.707108 0" type="cylinder" rgba="0.10 0.50 0.50 1" contype="0" conaffinity="0"/>
                  <geom name="R_foot_strip_center"   size="0.01 0.002" pos="-0.049  0.0   0.095" quat="0.707105 0 -0.707108 0" type="cylinder" rgba="0.10 0.50 0.50 1" contype="0" conaffinity="0"/>
                  <geom name="R_foot_strip_inner"    size="0.01 0.001" pos="-0.049  0.01  0.095" quat="0.707105 0 -0.707108 0" type="cylinder" rgba="0.10 0.50 0.50 1" contype="0" conaffinity="0"/>
                  <geom name="toe1_right_collision"  size="0.01 0.015" pos="-0.049  0.03  0.155" type="cylinder" rgba="0.10 0.50 0.50 1" contype="0" conaffinity="0"/>
                  <geom name="toe2_right_collision"  size="0.01 0.015" pos="-0.049 -0.03  0.155" type="cylinder" rgba="0.10 0.50 0.50 1" contype="0" conaffinity="0"/>
                  <site name="right_foot_end" pos="-0.049 0 0.17" size="0.008" rgba="1 0 0 1"/>
                  <site name = "right_foot_force" quat="0.0 0.707 0.0 0.707"/>
                  <site name = "right_foot_torque" quat="0.0 0.707 0.0 0.707"/>
                </body>
              </body>
            </body>
          </body>
        </body>
      </body>

      <!-- LEFT_LEG -->
      <body name="L_hip_pitch_link" pos="0 0.073499 -0.019694" quat="0.793352 0.608763 0 0">
        <inertial pos="0.0048541 -0.0150271 -0.0500696" quat="-0.117219 0.707818 -0.287786 0.634376" mass="1.65569" diaginertia="0.00293392 0.00256262 0.00240877"/>
        <joint name="L_hip_pitch_joint" pos="0 0 0" axis="0 0 1" limited="true" range="-2.574 3.028" actuatorfrcrange="-210 210" armature="0.01"/>
        <geom type="mesh" contype="0" conaffinity="0" group="1" density="0" rgba="0.196078 0.196078 0.196078 1" mesh="L_hip_pitch_link"/>
        <!-- <geom type="mesh" rgba="0.196078 0.196078 0.196078 1" mesh="L_hip_pitch_link"/> -->
        <body name="L_hip_roll_link" pos="0 -0.02 -0.053579" quat="0.430457 0.560986 0.430461 0.560986">
          <inertial pos="-0.0330367 -0.00203626 0.00120874" quat="0.714214 0.0105725 0.0122194 0.69974" mass="0.514808" diaginertia="0.00158831 0.0015264 0.000682669"/>
          <joint name="L_hip_roll_joint" pos="0 0 0" axis="0 0 1" limited="true" range="-0.349 2.094" actuatorfrcrange="-165 165" armature="0.01"/>
          <geom type="mesh" contype="0" conaffinity="0" group="1" density="0" rgba="0.698039 0.698039 0.698039 1" mesh="L_hip_roll_link"/>
          <geom name="L_hip_roll_collision" size="0.065 0.13" pos="-0.21 0 0" quat="0.707 0.0 0.707 0.0" type="cylinder" rgba="0.778 0.778 0.006 1"/>
          <!-- <geom type="mesh" rgba="0.698039 0.698039 0.698039 1" mesh="L_hip_roll_link"/> -->
          <body name="L_hip_yaw_link" pos="-0.0621 0 0" quat="0.499998 0.5 -0.500002 -0.5">
            <inertial pos="-0.00740878 -0.00120768 0.123895" quat="0.999466 0.0223923 -0.00598603 0.0230347" mass="5.13193" diaginertia="0.0446202 0.0424782 0.0109089"/>
            <joint name="L_hip_yaw_joint" pos="0 0 0" axis="0 0 1" limited="true" range="-3.2812 2.1816" actuatorfrcrange="-110 110" armature="0.01"/>
            <geom type="mesh" contype="0" conaffinity="0" group="1" density="0" rgba="0.698039 0.698039 0.698039 1" mesh="L_hip_yaw_link"/>
            <!-- <geom type="mesh" rgba="0.698039 0.698039 0.698039 1" mesh="L_hip_yaw_link"/> -->
            <geom name="L_hip_yaw_collision" type="capsule" size="0.07 0.18" pos="0 0 0.13" rgba="0.698039 0.698039 0.698039 0.3"/>
            <body name="L_knee_pitch_link" pos="0 -0.035 0.3179" quat="0.499998 0.5 -0.500002 -0.5">
              <inertial pos="-0.00270804 0.160407 -3.653e-05" quat="0.507457 0.489969 -0.512115 0.490057" mass="3.32222" diaginertia="0.0369622 0.0367307 0.00346204"/>
              <joint name="L_knee_pitch_joint" pos="0 0 0" axis="0 0 1" limited="true" range="-2.526 0.179" actuatorfrcrange="-210 210" armature="0.01"/>
              <geom type="mesh" contype="0" conaffinity="0" group="1" density="0" rgba="0.792157 0.819608 0.933333 1" mesh="L_knee_pitch_link"/>
              <!-- <geom type="mesh" rgba="0.792157 0.819608 0.933333 1" mesh="L_knee_pitch_link"/> -->
              <geom name="L_knee_pitch_collision" size="0.05 0.16" pos="0 0.2 0" quat="0.707105 0.707108 0 0" type="cylinder" rgba="0.778 0.778 0.006 1"/>
              <body name="L_ankle_pitch_link" pos="0 0.41 0" quat="0.707105 0 0 0.707108">
                <inertial pos="0.0057231 -0.000124 0.00221" quat="0.704485 0.707544 -0.0378772 0.0405866" mass="0.110584" diaginertia="4.69564e-05 3.42441e-05 2.57096e-05"/>
                <joint name="L_ankle_pitch_joint" pos="0 0 0" axis="0 0 1" limited="true" range="-0.5236 1.047" actuatorfrcrange="-60 60" armature="0.01"/>
                <geom type="mesh" contype="0" conaffinity="0" group="1" density="0" rgba="0.627451 0.627451 0.627451 1" mesh="L_ankle_pitch_link"/>
                <!-- <geom type="mesh" rgba="0.627451 0.627451 0.627451 1" mesh="L_ankle_pitch_link"/> -->
                <body name="L_ankle_roll_link" pos="0.012 0 0" quat="-2.59734e-06 -2.59735e-06 0.707108 0.707105">
                  <inertial pos="-0.020996 -2.02e-06 0.0340632" quat="0.99928 2.5859e-05 -0.0379487 3.56633e-05" mass="0.826871" diaginertia="0.00491997 0.00442435 0.000968853"/>
                  <joint name="L_ankle_roll_joint" pos="0 0 0" axis="0 0 1" limited="true" range="-0.436 0.436" actuatorfrcrange="-60 60" armature="0.01"/>
                  <geom type="mesh" contype="0" conaffinity="0" group="1" density="0" rgba="0.698039 0.698039 0.698039 1" mesh="L_ankle_roll_link"/>
                  <!-- <geom type="mesh" rgba="0.698039 0.698039 0.698039 1" mesh="L_ankle_roll_link"/> -->
                  <geom name="L_ankle_roll_collision" size="0.015 0.05 0.125" pos="-0.034 0 0.045" type="box" rgba="1 1 1 1" />
                  <geom name="L_foot_end_outer"      pos="-0.049  0.0   -0.08" size="0.005 0.005" quat="0.707105 0 0.707108 0" type="cylinder" rgba="0.10 0.50 0.50 1" contype="0" conaffinity="0"/>
                  <geom name="L_foot_front_outer"    size="0.01 0.001" pos="-0.049 -0.03  0.155" quat="0.707105 0 0.707108 0" type="cylinder" rgba="0.10 0.50 0.50 1" contype="0" conaffinity="0"/>
                  <geom name="L_foot_front_inner"    size="0.01 0.001" pos="-0.049  0.03  0.145" quat="0.707105 0 0.707108 0" type="cylinder" rgba="0.10 0.50 0.50 1" contype="0" conaffinity="0"/>
                  <geom name="L_foot_mid_outer"      size="0.01 0.001" pos="-0.049 -0.02  0.045" quat="0.707105 0 -0.707108 0" type="cylinder" rgba="0.10 0.50 0.50 1" contype="0" conaffinity="0"/>
                  <geom name="L_foot_mid_inner"      size="0.01 0.001" pos="-0.049  0.02  0.045" quat="0.707105 0 -0.707108 0" type="cylinder" rgba="0.10 0.50 0.50 1" contype="0" conaffinity="0"/>
                  <geom name="L_foot_strip_outer"    size="0.01 0.001" pos="-0.049 -0.01  0.095" quat="0.707105 0 -0.707108 0" type="cylinder" rgba="0.10 0.50 0.50 1" contype="0" conaffinity="0"/>
                  <geom name="L_foot_strip_center"   size="0.01 0.002" pos="-0.049  0.0   0.095" quat="0.707105 0 -0.707108 0" type="cylinder" rgba="0.10 0.50 0.50 1" contype="0" conaffinity="0"/>
                  <geom name="L_foot_strip_inner"    size="0.01 0.001" pos="-0.049  0.01  0.095" quat="0.707105 0 -0.707108 0" type="cylinder" rgba="0.10 0.50 0.50 1" contype="0" conaffinity="0"/>
                  <geom name="toe1_left_collision"   size="0.01 0.015" pos="-0.049  0.03  0.155" type="cylinder" rgba="0.10 0.50 0.50 1" contype="0" conaffinity="0"/>
                  <geom name="toe2_left_collision"   size="0.01 0.015" pos="-0.049 -0.03  0.155" type="cylinder" rgba="0.10 0.50 0.50 1" contype="0" conaffinity="0"/>
                  <site name="left_foot_end" pos="-0.049 0 0.17" size="0.008" rgba="0 1 0 1"/>
                  <site name = "left_foot_force" quat="0.0 0.707 0.0 0.707"/>
                  <site name = "left_foot_torque" quat="0.0 0.707 0.0 0.707"/>
                </body>
              </body>
            </body>
          </body>
        </body>
      </body>

      <!-- WAIST_LEFT_ARM -->
      <body name="waist_yaw_link" pos="0 0 0.076641" quat="-2.59734e-06 0.707105 0.707108 -2.59735e-06">
        <inertial pos="-0.00088235 0.00270178 -0.0369526" quat="0.152595 0.674186 0.0745552 0.71877" mass="2.0613" diaginertia="0.00579036 0.00442106 0.00398296"/>
        <joint name="waist_yaw_joint" pos="0 0 0" axis="0 0 1" limited="true" range="-2.8274 2.8274" actuatorfrcrange="-63 63" armature="0.01"/>
        <geom type="mesh" contype="0" conaffinity="0" group="1" density="0" rgba="0.490196 0.760784 0.223529 1" mesh="waist_yaw_link"/>
        <!-- <geom type="mesh" rgba="0.490196 0.760784 0.223529 1" mesh="waist_yaw_link"/> -->
        <geom name="waist_yaw_collision" type="sphere" size="0.09" pos="-0. 0.007 -0.049" rgba="0.490196 0.760784 0.223529 0.3"/>
        <body name="waist_pitch_link" pos="0 0.04 -0.1155" quat="0.499998 0.5 -0.500002 -0.5">
          <inertial pos="0.00141152 1.015e-05 0.00378014" quat="0.695978 -0.00323663 -0.00466562 0.71804" mass="1.56616" diaginertia="0.00200827 0.00193456 0.0014908"/>
          <joint name="waist_pitch_joint" pos="0 0 0" axis="0 0 1" limited="true" range="-1.2566 0.0523" actuatorfrcrange="-165 165" armature="0.01"/>
          <geom type="mesh" contype="0" conaffinity="0" group="1" density="0" rgba="0.898039 0.917647 0.929412 1" mesh="waist_pitch_link"/>
          <!-- <geom type="mesh" rgba="0.898039 0.917647 0.929412 1" mesh="waist_pitch_link"/> -->
          <geom name="waist_pitch_collision" type="sphere" size="0.055" pos="0.002 0 -0.001" rgba="0.898039 0.917647 0.929412 0.3"/>
          <body name="waist_roll_link" pos="0.0515 0 0" quat="0.499998 0.5 -0.500002 -0.5">
            <inertial pos="0.150678 -0.00010908 -0.00232477" quat="0.00191846 0.659828 0.0030952 0.751408" mass="13.3399" diaginertia="0.149397 0.12699 0.0780175"/>
            <joint name="waist_roll_joint" pos="0 0 0" axis="0 0 1" limited="true" range="-0.785 0.785" actuatorfrcrange="-110 110" armature="0.01"/>
            <geom type="mesh" contype="0" conaffinity="0" group="1" density="0" rgba="1 1 1 1" mesh="waist_roll_link"/>
            <geom name="waist_roll_collision" type="capsule" size="0.12 0.04" pos="0.05 0 0" quat="0.707105 0 0.707108 0" rgba="1 1 1 0.3"/>

            <body name="L_shoulder_pitch_link" pos="0.24778 -0.11426 0.0115" quat="0.541675 -0.454519 -0.541675 -0.454519">
              <inertial pos="0.00379496 -4.625e-05 -0.0469029" quat="0.655863 -0.0951486 -0.0431681 0.747614" mass="0.798422" diaginertia="0.000564005 0.00053755 0.000482425"/>
              <joint name="L_shoulder_pitch_joint" pos="0 0 0" axis="0 0 1" limited="true" range="-2.6 2.6" actuatorfrcrange="-60 60" armature="0.01"/>
              <geom type="mesh" contype="0" conaffinity="0" group="1" density="0" rgba="0.909804 0.443137 0.0313726 1" mesh="L_shoulder_pitch_link"/>
              <!-- <geom type="mesh" rgba="0.909804 0.443137 0.0313726 1" mesh="L_shoulder_pitch_link"/> -->
              <body name="L_shoulder_roll_link" pos="0 0 -0.0499" quat="0.499998 0.5 -0.500002 -0.5">
                <inertial pos="0.0814423 -0.00090177 -0.00388223" quat="0.357067 0.521151 0.304357 0.712931" mass="0.954452" diaginertia="0.00175475 0.00170192 0.000762658"/>
                <joint name="L_shoulder_roll_joint" pos="0 0 0" axis="0 0 1" limited="true" range="-1.919 0.1745" actuatorfrcrange="-60 60" armature="0.01"/>
                <geom type="mesh" contype="0" conaffinity="0" group="1" density="0" rgba="1 1 1 1" mesh="L_shoulder_roll_link"/>
                <geom name="L_shoulder_roll_collision" type="capsule" size="0.04 0.055" pos="0.063 0 0" quat="0.707105 0 0.707108 0" rgba="1 1 1 0.3"/>
                <body name="L_shoulder_yaw_link" pos="0.12675 0 0" quat="0.499998 0.5 0.500002 0.5">
                  <inertial pos="0.00509191 0.00111624 0.0777859" quat="0.998594 0.0154556 0.041642 0.0289335" mass="0.951576" diaginertia="0.00136951 0.00135249 0.000633421"/>
                  <joint name="L_shoulder_yaw_joint" pos="0 0 0" axis="0 0 1" limited="true" range="-2.879 2.879" actuatorfrcrange="-25 25" armature="0.01"/>
                  <geom type="mesh" contype="0" conaffinity="0" group="1" density="0" rgba="0.698039 0.698039 0.698039 1" mesh="L_shoulder_yaw_link"/>
                  <geom name="L_shoulder_yaw_collision" type="cylinder" size="0.035 0.05" pos="0 0 0.08" rgba="0.698039 0.698039 0.698039 0.3"/>
                  <body name="L_elbow_pitch_link" pos="0 0 0.09325" quat="0.499998 0.5 0.500002 0.5">
                    <inertial pos="0.00109585 0.0816298 0.00301164" quat="0.764598 0.601346 -0.110715 0.203751" mass="0.910303" diaginertia="0.00151258 0.00147366 0.000681232"/>
                    <joint name="L_elbow_pitch_joint" pos="0 0 0" axis="0 0 1" limited="true" range="-0.1396 2.3038" actuatorfrcrange="-25 25" armature="0.01"/>
                    <geom type="mesh" contype="0" conaffinity="0" group="1" density="0" rgba="0.909804 0.443137 0.0313726 1" mesh="L_elbow_pitch_link"/>
                    <geom name="L_elbow_pitch_collision" type="sphere" size="0.04" pos="0.002 0.08 0" rgba="0.909804 0.443137 0.0313726 0.3"/>
                    <body name="L_elbow_yaw_link" pos="0 0.12425 0" quat="-2.59734e-06 -2.59735e-06 0.707108 0.707105">
                      <inertial pos="0.00041996 -0.00835103 0.0205441" quat="0.58325 0.319289 -0.351443 0.659061" mass="0.0923308" diaginertia="8.72147e-05 8.16278e-05 5.94576e-05"/>
                      <joint name="L_elbow_yaw_joint" pos="0 0 0" axis="0 0 1" limited="true" range="-2.879 2.879" actuatorfrcrange="-25 25" armature="0.01"/>
                      <geom type="mesh" contype="0" conaffinity="0" group="1" density="0" rgba="1 1 1 1" mesh="L_elbow_yaw_link"/>
                      <geom name="L_elbow_yaw_collision" type="sphere" size="0.05" pos="0.001 -0.002 0.026" rgba="1 1 1 0.3"/>
                      <body name="L_wrist_pitch_link" pos="0 0 0.05575" quat="-2.59734e-06 -2.59735e-06 -0.707108 -0.707105">
                        <inertial pos="-0.00246512 0.0195859 -0.00275163" quat="0.357283 0.520895 -0.552869 0.543465" mass="0.493163" diaginertia="0.000333781 0.000328672 0.000161987"/>
                        <joint name="L_wrist_pitch_joint" pos="0 0 0" axis="0 0 1" limited="true" range="-0.71558 0.71558" actuatorfrcrange="-6 6" armature="0.01"/>
                        <geom type="mesh" contype="0" conaffinity="0" group="1" density="0" rgba="0.898039 0.917647 0.929412 1" mesh="L_wrist_pitch_link"/>
                        <!-- <geom type="mesh" rgba="0.898039 0.917647 0.929412 1" mesh="L_wrist_pitch_link"/> -->
                        <body name="L_wrist_roll_link" pos="0 0.039952 0" quat="0.499998 0.5 0.500002 0.5">
                          <inertial pos="0.021913 1.44e-05 -0.0085537" quat="0.694149 0.134748 0.134748 0.694149" mass="0.0476664" diaginertia="4.75e-05 4.14105e-05 1.91895e-05"/>
                          <joint name="L_wrist_roll_joint" pos="0 0 0" axis="0 0 1" limited="true" range="-1.6057 1.6057" actuatorfrcrange="-6 6" armature="0.01"/>
                          <geom type="mesh" contype="0" conaffinity="0" group="1" density="0" rgba="1 1 1 1" mesh="L_wrist_roll_link"/>
                          <geom name="L_wrist_roll_collision" type="sphere" size="0.03" pos="0.02 0 -0.01" rgba="1 1 1 0.3"/>
                          <geom name="hand_l_collision" type="capsule" size="0.04 0.025" pos="0.065 0 0" quat="0.707105 0 0.707108 0" rgba="0.65 0.28 0.82 0.5" contype="3" conaffinity="3"/>
                        </body>
                      </body>
                    </body>
                  </body>
                </body>
              </body>
            </body>

            <!-- RIGHT_ARM -->
            <body name="R_shoulder_pitch_link" pos="0.24788 0.11481 0.0115" quat="0.454527 0.541668 0.454528 -0.54167">
              <inertial pos="-0.00384147 7.92e-06 -0.046973" quat="0.715387 0.0207684 0.0681669 0.695085" mass="0.79994" diaginertia="0.00056395 0.000536869 0.000485841"/>
              <joint name="R_shoulder_pitch_joint" pos="0 0 0" axis="0 0 1" limited="true" range="-2.6 2.6" actuatorfrcrange="-60 60" armature="0.01"/>
              <geom type="mesh" contype="0" conaffinity="0" group="1" density="0" rgba="0.909804 0.443137 0.0313726 1" mesh="R_shoulder_pitch_link"/>
              <!-- <geom type="mesh" rgba="0.909804 0.443137 0.0313726 1" mesh="R_shoulder_pitch_link"/> -->
              <body name="R_shoulder_roll_link" pos="0 0 -0.0499" quat="0.499998 0.5 -0.500002 -0.5">
                <inertial pos="0.0814559 -0.00090026 0.00374986" quat="0.519194 0.362779 0.709455 0.309036" mass="0.954183" diaginertia="0.00175385 0.00170009 0.000764477"/>
                <joint name="R_shoulder_roll_joint" pos="0 0 0" axis="0 0 1" limited="true" range="-1.919 0.1745" actuatorfrcrange="-60 60" armature="0.01"/>
                <geom type="mesh" contype="0" conaffinity="0" group="1" density="0" rgba="0.909804 0.443137 0.0313726 1" mesh="R_shoulder_roll_link"/>
                <geom name="R_shoulder_roll_collision" type="capsule" size="0.04 0.055" pos="0.063 0 0" quat="0.707105 0 0.707108 0" rgba="0.909804 0.443137 0.0313726 0.3"/>
                <body name="R_shoulder_yaw_link" pos="0.12675 0 0" quat="0.499998 0.5 0.500002 0.5">
                  <inertial pos="-0.00508263 -0.00111484 0.0776773" quat="0.998595 -0.0152492 -0.0415447 0.029161" mass="0.952713" diaginertia="0.00137689 0.00135996 0.000633577"/>
                  <joint name="R_shoulder_yaw_joint" pos="0 0 0" axis="0 0 1" limited="true" range="-2.879 2.879" actuatorfrcrange="-25 25" armature="0.01"/>
                  <geom type="mesh" contype="0" conaffinity="0" group="1" density="0" rgba="0.698039 0.698039 0.698039 1" mesh="R_shoulder_yaw_link"/>
                  <geom name="R_shoulder_yaw_collision" type="cylinder" size="0.035 0.05" pos="0 0 0.08" rgba="0.698039 0.698039 0.698039 0.3"/>
                  <body name="R_elbow_pitch_link" pos="0 0 0.09325" quat="0.499998 0.5 0.500002 0.5">
                    <inertial pos="-0.00109585 0.0816298 -0.00301164" quat="0.601346 0.764598 -0.203751 0.110715" mass="0.910303" diaginertia="0.00151258 0.00147366 0.000681232"/>
                    <joint name="R_elbow_pitch_joint" pos="0 0 0" axis="0 0 1" limited="true" range="-2.3038 0.1396" actuatorfrcrange="-25 25" armature="0.01"/>
                    <geom type="mesh" contype="0" conaffinity="0" group="1" density="0" rgba="0.909804 0.443137 0.0313726 1" mesh="R_elbow_pitch_link"/>
                    <geom name="R_elbow_pitch_collision" type="sphere" size="0.04" pos="-0.002 0.08 0" rgba="0.909804 0.443137 0.0313726 0.3"/>
                    <body name="R_elbow_yaw_link" pos="0 0.12425 0" quat="-2.59734e-06 -2.59735e-06 -0.707108 -0.707105">
                      <inertial pos="-0.00042308 0.00819376 0.0202823" quat="0.356639 0.654815 -0.581473 0.325446" mass="0.0916493" diaginertia="8.62703e-05 8.04296e-05 5.91601e-05"/>
                      <joint name="R_elbow_yaw_joint" pos="0 0 0" axis="0 0 1" limited="true" range="-2.879 2.879" actuatorfrcrange="-25 25" armature="0.01"/>
                      <geom type="mesh" contype="0" conaffinity="0" group="1" density="0" rgba="1 1 1 1" mesh="R_elbow_yaw_link"/>
                      <geom name="R_elbow_yaw_collision" type="sphere" size="0.05" pos="-0.001 0.002 0.026" rgba="1 1 1 0.3"/>
                      <body name="R_wrist_pitch_link" pos="0 0 0.05575" quat="-2.59734e-06 -2.59735e-06 -0.707108 -0.707105">
                        <inertial pos="0.00246512 0.0195859 0.00275163" quat="0.520393 0.356644 -0.543892 0.553333" mass="0.493163" diaginertia="0.000333785 0.000328685 0.00016197"/>
                        <joint name="R_wrist_pitch_joint" pos="0 0 0" axis="0 0 1" limited="true" range="-0.71558 0.71558" actuatorfrcrange="-6 6" armature="0.01"/>
                        <geom type="mesh" contype="0" conaffinity="0" group="1" density="0" rgba="0.647059 1 0.529412 1" mesh="R_wrist_pitch_link"/>
                        <!-- <geom type="mesh" rgba="0.647059 1 0.529412 1" mesh="R_wrist_pitch_link"/> -->
                        <body name="R_wrist_roll_link" pos="0 0.039952 0" quat="0.499998 0.5 0.500002 0.5">
                          <inertial pos="0.021913 -1.437e-05 0.0085537" quat="0.694149 -0.134748 -0.134748 0.694149" mass="0.0476664" diaginertia="4.75e-05 4.14105e-05 1.91895e-05"/>
                          <joint name="R_wrist_roll_joint" pos="0 0 0" axis="0 0 1" limited="true" range="-1.6057 1.6057" actuatorfrcrange="-6 6" armature="0.01"/>
                          <geom type="mesh" contype="0" conaffinity="0" group="1" density="0" rgba="1 1 1 1" mesh="R_wrist_roll_link"/>
                          <geom name="R_wrist_roll_collision" type="sphere" size="0.03" pos="0.02 0 0.01" rgba="1 1 1 0.3"/>
                          <geom name="hand_r_collision" type="capsule" size="0.04 0.025" pos="0.065 0 0" quat="0.707105 0 0.707108 0" rgba="0.65 0.28 0.82 0.5" contype="3" conaffinity="3"/>
                        </body>
                      </body>
                    </body>
                  </body>
                </body>
              </body>
            </body>

            <!-- HEAD -->
            <body name="head_yaw_link" pos="0.34305 0 0.0115" quat="-2.59734e-06 -0.707108 2.59735e-06 -0.707105">
              <inertial pos="-0.0020465 0.00017996 -0.03113" quat="0.998454 -0.0424454 -0.0336011 0.0125907" mass="0.24152" diaginertia="0.000104075 9.8163e-05 8.8562e-05"/>
              <!-- <joint name="head_yaw_joint" pos="0 0 0" axis="0 0 1" limited="true" range="-1.693 1.693" actuatorfrcrange="-4.5 4.5" armature="0.01"/> -->
              <geom type="mesh" contype="0" conaffinity="0" group="1" density="0" rgba="1 0.67451 0.3098 1" mesh="head_yaw_link"/>
              <body name="head_pitch_link" pos="0 0 0.0265" quat="0.707105 0.707108 0 0">
                <inertial pos="0.026402 0.059357 -0.000621" quat="0.576401 0.407623 -0.584689 0.399681" mass="1.1362" diaginertia="0.00598538 0.00547093 0.00295488"/>
                <!-- <joint name="head_pitch_joint" pos="0 0 0" axis="0 0 1" limited="true" range="-0.8203 0.5585" actuatorfrcrange="-4.5 4.5" armature="0.01"/> -->
                <geom type="mesh" contype="0" conaffinity="0" group="1" density="0" rgba="0.69804 0.69804 0.69804 1" mesh="head_pitch_link"/>
                <geom name="head_pitch_collision" type="capsule" size="0.075 0.035" pos="0.017 0.09 0" quat="0.707105 -0.707108 0 0" rgba="0.69804 0.69804 0.69804 0.3"/>
              </body>
            </body>
          </body>
        </body>
      </body>
    </body>
  </worldbody>

  <!-- SENSOR -->
  <sensor>
    <framequat     name='orientation' objtype='site' objname='imu'/>
    <gyro          name='angular-velocity'    site='imu' noise='0.005' cutoff='34.9'/>
    <accelerometer name='linear-acceleration' site='imu' noise='0.01' cutoff='157'/>
    <force  name = "left-foot-force"   site = "left_foot_force"/>
    <torque name = "left-foot-torque"  site = "left_foot_torque"/>
    <force  name = "right-foot-force"  site = "right_foot_force"/>
    <torque name = "right-foot-torque" site = "right_foot_torque"/>
  </sensor>

  <!-- ACTUATOR -->
  <actuator>
    <motor name="R_hip_pitch_joint" joint="R_hip_pitch_joint" gear="1" ctrllimited="true" ctrlrange="-210 210"/>
    <motor name="R_hip_roll_joint" joint="R_hip_roll_joint" gear="1" ctrllimited="true" ctrlrange="-165 165"/>
    <motor name="R_hip_yaw_joint" joint="R_hip_yaw_joint" gear="1" ctrllimited="true" ctrlrange="-110 110"/>
    <motor name="R_knee_pitch_joint" joint="R_knee_pitch_joint" gear="1" ctrllimited="true" ctrlrange="-210 210"/>
    <motor name="R_ankle_pitch_joint" joint="R_ankle_pitch_joint" gear="1" ctrllimited="true" ctrlrange="-60 60"/>
    <motor name="R_ankle_roll_joint" joint="R_ankle_roll_joint" gear="1" ctrllimited="true" ctrlrange="-60 60"/>

    <motor name="L_hip_pitch_joint" joint="L_hip_pitch_joint" gear="1" ctrllimited="true" ctrlrange="-210 210"/>
    <motor name="L_hip_roll_joint" joint="L_hip_roll_joint" gear="1" ctrllimited="true" ctrlrange="-165 165"/>
    <motor name="L_hip_yaw_joint" joint="L_hip_yaw_joint" gear="1" ctrllimited="true" ctrlrange="-110 110"/>
    <motor name="L_knee_pitch_joint" joint="L_knee_pitch_joint" gear="1" ctrllimited="true" ctrlrange="-210 210"/>
    <motor name="L_ankle_pitch_joint" joint="L_ankle_pitch_joint" gear="1" ctrllimited="true" ctrlrange="-60 60"/>
    <motor name="L_ankle_roll_joint" joint="L_ankle_roll_joint" gear="1" ctrllimited="true" ctrlrange="-60 60"/>

    <motor name="waist_yaw_joint" joint="waist_yaw_joint" gear="1" ctrllimited="true" ctrlrange="-63 63"/>
    <motor name="waist_pitch_joint" joint="waist_pitch_joint" gear="1" ctrllimited="true" ctrlrange="-165 165"/>
    <motor name="waist_roll_joint" joint="waist_roll_joint" gear="1" ctrllimited="true" ctrlrange="-110 110"/>

    <motor name="L_shoulder_pitch_joint" joint="L_shoulder_pitch_joint" gear="1" ctrllimited="true" ctrlrange="-60 60"/>
    <motor name="L_shoulder_roll_joint" joint="L_shoulder_roll_joint" gear="1" ctrllimited="true" ctrlrange="-60 60"/>
    <motor name="L_shoulder_yaw_joint" joint="L_shoulder_yaw_joint" gear="1" ctrllimited="true" ctrlrange="-25 25"/>
    <motor name="L_elbow_pitch_joint" joint="L_elbow_pitch_joint" gear="1" ctrllimited="true" ctrlrange="-25 25"/>
    <motor name="L_elbow_yaw_joint" joint="L_elbow_yaw_joint" gear="1" ctrllimited="true" ctrlrange="-25 25"/>
    <motor name="L_wrist_pitch_joint" joint="L_wrist_pitch_joint" gear="1" ctrllimited="true" ctrlrange="-6 6"/>
    <motor name="L_wrist_roll_joint" joint="L_wrist_roll_joint" gear="1" ctrllimited="true" ctrlrange="-6 6"/>

    <motor name="R_shoulder_pitch_joint" joint="R_shoulder_pitch_joint" gear="1" ctrllimited="true" ctrlrange="-60 60"/>
    <motor name="R_shoulder_roll_joint" joint="R_shoulder_roll_joint" gear="1" ctrllimited="true" ctrlrange="-60 60"/>
    <motor name="R_shoulder_yaw_joint" joint="R_shoulder_yaw_joint" gear="1" ctrllimited="true" ctrlrange="-25 25"/>
    <motor name="R_elbow_pitch_joint" joint="R_elbow_pitch_joint" gear="1" ctrllimited="true" ctrlrange="-25 25"/>
    <motor name="R_elbow_yaw_joint" joint="R_elbow_yaw_joint" gear="1" ctrllimited="true" ctrlrange="-25 25"/>
    <motor name="R_wrist_pitch_joint" joint="R_wrist_pitch_joint" gear="1" ctrllimited="true" ctrlrange="-6 6"/>
    <motor name="R_wrist_roll_joint" joint="R_wrist_roll_joint" gear="1" ctrllimited="true" ctrlrange="-6 6"/>

    <!-- <motor name="head_yaw_joint" joint="head_yaw_joint" gear="1" ctrllimited="true" ctrlrange="-4.5 4.5"/>
    <motor name="head_pitch_joint" joint="head_pitch_joint" gear="1" ctrllimited="true" ctrlrange="-4.5 4.5"/> -->
  </actuator>

  <!-- setup scene -->
  <statistic center="1.0 0.7 1.0" extent="0.8"/>
  <visual>
    <headlight diffuse="0.6 0.6 0.6" ambient="0.1 0.1 0.1" specular="0.9 0.9 0.9"/>
    <rgba haze="0.15 0.25 0.35 1"/>
    <global azimuth="-140" elevation="-20"/>
  </visual>
  <asset>
    <texture type="skybox" builtin="flat" rgb1="0 0 0" rgb2="0 0 0" width="512" height="3072"/>
    <texture type="2d" name="groundplane" builtin="checker" mark="edge" rgb1="0.2 0.3 0.4" rgb2="0.1 0.2 0.3" markrgb="0.8 0.8 0.8" width="300" height="300"/>
    <material name="groundplane" texture="groundplane" texuniform="true" texrepeat="5 5" reflectance="0.2"/>
  </asset>
  <worldbody>
    <light pos="1 0 3.5" dir="0 0 -1" directional="true"/>
    <geom name="floor" size="0 0 0.05" type="plane" material="groundplane"/>
  </worldbody>
</mujoco>
