<?xml version="1.0" ?>
<!-- =================================================================================== -->
<!-- |    This document was autogenerated by xacro from walker_astron_v1.xacro         | -->
<!-- |    EDITING THIS FILE BY HAND IS NOT RECOMMENDED                                 | -->
<!-- =================================================================================== -->
<robot name="walker_astron_v1">
  <mujoco>
    <compiler autolimits="true" balanceinertia="false" boundmass="0.0001" convexhull="false" discardvisual="false" inertiafromgeom="false" meshdir="../../meshes/walker_astron_v1" usethread="true"/>
  </mujoco>
  <link name="base_link">
    <inertial>
      <origin rpy="0 0 0" xyz="-0.00060742 0 -0.00390464"/>
      <mass value="5.32923152"/>
      <inertia ixx="0.02561815" ixy="3.016E-05" ixz="-1.012E-05" iyy="0.01751097" iyz="-2.5E-07" izz="0.02397466"/>
    </inertial>
    <visual>
      <origin rpy="0 0 0" xyz="0 0 0"/>
      <geometry>
        <mesh filename="./meshes/base_link.STL"/>
      </geometry>
      <material name="">
        <color rgba="0.627450980392157 0.627450980392157 0.627450980392157 1"/>
      </material>
    </visual>
    <collision>
      <origin rpy="0 0 0" xyz="0 0 0"/>
      <geometry>
        <mesh filename="./meshes/base_link.STL"/>
      </geometry>
    </collision>
  </link>
  <link name="L_hip_pitch_link">
    <inertial>
      <origin rpy="0 0 0" xyz="0.0048541 0.05006963 -0.01502711"/>
      <mass value="1.65568528"/>
      <inertia ixx="0.00241952" ixy="-3.402E-05" ixz="2.351E-05" iyy="0.00281444" iyz="0.00017664" izz="0.00267135"/>
    </inertial>
    <visual>
      <origin rpy="0 0 0" xyz="0 0 0"/>
      <geometry>
        <mesh filename="./meshes/L_hip_pitch_link.STL"/>
      </geometry>
      <material name="">
        <color rgba="0.196078431372549 0.196078431372549 0.196078431372549 1"/>
      </material>
    </visual>
    <collision>
      <origin rpy="0 0 0" xyz="0 0 0"/>
      <geometry>
        <mesh filename="./meshes/L_hip_pitch_link.STL"/>
      </geometry>
    </collision>
  </link>
  <joint name="L_hip_pitch_joint" type="revolute">
    <origin rpy="-0.2618 0 0" xyz="0 0.073499 -0.019694"/>
    <parent link="base_link"/>
    <child link="L_hip_pitch_link"/>
    <axis xyz="0 1 0"/>
    <limit effort="210" lower="-2.98" upper="2.53" velocity="10.47"/>
  </joint>
  <link name="L_hip_roll_link">
    <inertial>
      <origin rpy="0 0 0" xyz="0.00120874 0.00203626 -0.0330367"/>
      <mass value="0.51480778"/>
      <inertia ixx="0.00068355" ixy="1.85E-06" ixz="-2.72E-05" iyy="0.00158828" iyz="-1.21E-06" izz="0.00152555"/>
    </inertial>
    <visual>
      <origin rpy="0 0 0" xyz="0 0 0"/>
      <geometry>
        <mesh filename="./meshes/L_hip_roll_link.STL"/>
      </geometry>
      <material name="">
        <color rgba="0.698039215686274 0.698039215686274 0.698039215686274 1"/>
      </material>
    </visual>
    <collision>
      <origin rpy="0 0 0" xyz="0 0 0"/>
      <geometry>
        <mesh filename="./meshes/L_hip_roll_link.STL"/>
      </geometry>
    </collision>
  </link>
  <joint name="L_hip_roll_joint" type="revolute">
    <origin rpy="0.261799387799153 0 0" xyz="0 0.0535794918034543 -0.0199999995489613"/>
    <parent link="L_hip_pitch_link"/>
    <child link="L_hip_roll_link"/>
    <axis xyz="1 0 0"/>
    <limit effort="165" lower="-0.314" upper="2.059" velocity="8.9"/>
  </joint>
  <link name="L_hip_yaw_link">
    <inertial>
      <origin rpy="0 0 0" xyz="-0.00120768 -0.00740878 -0.12389527"/>
      <mass value="5.13192556"/>
      <inertia ixx="0.04241863" ixy="8.24E-05" ixz="-0.00142152" iyy="0.04461162" iyz="-0.00037262" izz="0.01097702"/>
    </inertial>
    <visual>
      <origin rpy="0 0 0" xyz="0 0 0"/>
      <geometry>
        <mesh filename="./meshes/L_hip_yaw_link.STL"/>
      </geometry>
      <material name="">
        <color rgba="0.698039215686274 0.698039215686274 0.698039215686274 1"/>
      </material>
    </visual>
    <collision>
      <origin rpy="0 0 0" xyz="0 0 0"/>
      <geometry>
        <mesh filename="./meshes/L_hip_yaw_link.STL"/>
      </geometry>
    </collision>
  </link>
  <joint name="L_hip_yaw_joint" type="revolute">
    <origin rpy="0 0 0" xyz="0 0 -0.0621000000000043"/>
    <parent link="L_hip_roll_link"/>
    <child link="L_hip_yaw_link"/>
    <axis xyz="0 0 1"/>
    <limit effort="110" lower="-2.146" upper="3.246" velocity="10.47"/>
  </joint>
  <link name="L_knee_pitch_link">
    <inertial>
      <origin rpy="0 0 0" xyz="0.00270804 3.653E-05 -0.16040743"/>
      <mass value="3.32222379"/>
      <inertia ixx="0.03667868" ixy="-7.25E-06" ixz="-0.00131399" iyy="0.03696149" iyz="-0.00015599" izz="0.00351475"/>
    </inertial>
    <visual>
      <origin rpy="0 0 0" xyz="0 0 0"/>
      <geometry>
        <mesh filename="./meshes/L_knee_pitch_link.STL"/>
      </geometry>
      <material name="">
        <color rgba="0.792156862745098 0.819607843137255 0.933333333333333 1"/>
      </material>
    </visual>
    <collision>
      <origin rpy="0 0 0" xyz="0 0 0"/>
      <geometry>
        <mesh filename="./meshes/L_knee_pitch_link.STL"/>
      </geometry>
    </collision>
  </link>
  <joint name="L_knee_pitch_joint" type="revolute">
    <origin rpy="0 0 0" xyz="-0.0349999999999581 0 -0.317899997262446"/>
    <parent link="L_hip_yaw_link"/>
    <child link="L_knee_pitch_link"/>
    <axis xyz="0 1 0"/>
    <limit effort="210" lower="0.08" upper="2.478" velocity="10.47"/>
  </joint>
  <link name="L_ankle_pitch_link">
    <inertial>
      <origin rpy="0 0 0" xyz="-0.00012374 -0.00221434 -0.0057231"/>
      <mass value="0.11058391"/>
      <inertia ixx="2.571E-05" ixy="3E-08" ixz="-8E-08" iyy="3.443E-05" iyz="1.4E-06" izz="4.678E-05"/>
    </inertial>
    <visual>
      <origin rpy="0 0 0" xyz="0 0 0"/>
      <geometry>
        <mesh filename="./meshes/L_ankle_pitch_link.STL"/>
      </geometry>
      <material name="">
        <color rgba="0.627450980392157 0.627450980392157 0.627450980392157 1"/>
      </material>
    </visual>
    <collision>
      <origin rpy="0 0 0" xyz="0 0 0"/>
      <geometry>
        <mesh filename="./meshes/L_ankle_pitch_link.STL"/>
      </geometry>
    </collision>
  </link>
  <joint name="L_ankle_pitch_joint" type="revolute">
    <origin rpy="0 0 0" xyz="0 0 -0.409999999999987"/>
    <parent link="L_knee_pitch_link"/>
    <child link="L_ankle_pitch_link"/>
    <axis xyz="0 1 0"/>
    <limit effort="60" lower="-1.012" upper="0.488" velocity="12.57"/>
  </joint>
  <link name="L_ankle_roll_link">
    <inertial>
      <origin rpy="0 0 0" xyz="0.03406324 2.02E-06 -0.020996"/>
      <mass value="0.82687057"/>
      <inertia ixx="0.00099158" ixy="-1.9E-07" ixz="0.0002988" iyy="0.00442435" iyz="-2E-08" izz="0.00489724"/>
    </inertial>
    <visual>
      <origin rpy="0 0 0" xyz="0 0 0"/>
      <geometry>
        <mesh filename="./meshes/L_ankle_roll_link.STL"/>
      </geometry>
      <material name="">
        <color rgba="0.698039215686274 0.698039215686274 0.698039215686274 1"/>
      </material>
    </visual>
    <collision>
      <origin rpy="0 0 0" xyz="0 0 0"/>
      <geometry>
        <mesh filename="./meshes/L_ankle_roll_link.STL"/>
      </geometry>
    </collision>
  </link>
  <joint name="L_ankle_roll_joint" type="revolute">
    <origin rpy="0 0 0" xyz="0 0 -0.012"/>
    <parent link="L_ankle_pitch_link"/>
    <child link="L_ankle_roll_link"/>
    <axis xyz="1 0 0"/>
    <limit effort="60" lower="-0.401" upper="0.401" velocity="12.57"/>
  </joint>
  <joint name="L_foot_ft_joint" type="fixed">
    <origin rpy="0 0 0" xyz="0 0 0"/>
    <parent link="L_ankle_roll_link"/>
    <child link="L_foot_ft_link"/>
  </joint>
  <link name="L_foot_ft_link">
    <inertial>
      <mass value="0.00005"/>
      <origin rpy="0 0 0" xyz="0 0 0"/>
      <inertia ixx="5e-11" ixy="0" ixz="0" iyy="5e-11" iyz="0" izz="1e-10"/>
    </inertial>
    <visual>
      <origin rpy="0 0 0" xyz="0 0 0"/>
      <geometry>
        <cylinder length="0.01" radius="0.01"/>
      </geometry>
    </visual>
    <material name="orange">
      <color rgba="255 108 10 255"/>
    </material>
  </link>
  <!-- for urdf2mojuco parse -->
  <ft_sensor name="L_foot_ft">
    <parent link="L_ankle_roll_link"/>
    <origin rpy="0 0 0" xyz="0 0 0"/>
  </ft_sensor>
  <link name="R_hip_pitch_link">
    <inertial>
      <origin rpy="0 0 0" xyz="0.0062436 -0.05042619 -0.01471604"/>
      <mass value="1.65592419"/>
      <inertia ixx="0.00242058" ixy="1.359E-05" ixz="4.82E-05" iyy="0.00275017" iyz="-0.0001869" izz="0.00261347"/>
    </inertial>
    <visual>
      <origin rpy="0 0 0" xyz="0 0 0"/>
      <geometry>
        <mesh filename="./meshes/R_hip_pitch_link.STL"/>
      </geometry>
      <material name="">
        <color rgba="0.196078431372549 0.196078431372549 0.196078431372549 1"/>
      </material>
    </visual>
    <collision>
      <origin rpy="0 0 0" xyz="0 0 0"/>
      <geometry>
        <mesh filename="./meshes/R_hip_pitch_link.STL"/>
      </geometry>
    </collision>
  </link>
  <joint name="R_hip_pitch_joint" type="revolute">
    <origin rpy="0.261799387799121 0 0" xyz="0 -0.073422566263531 -0.0196735173365314"/>
    <parent link="base_link"/>
    <child link="R_hip_pitch_link"/>
    <axis xyz="0 1 0"/>
    <limit effort="210" lower="-2.98" upper="2.53" velocity="10.47"/>
  </joint>
  <link name="R_hip_roll_link">
    <inertial>
      <origin rpy="0 0 0" xyz="0.00120761 -0.00204745 -0.033039"/>
      <mass value="0.51480826"/>
      <inertia ixx="0.00068354" ixy="-2.15E-06" ixz="-2.723E-05" iyy="0.00158816" iyz="1.2E-06" izz="0.00152554"/>
    </inertial>
    <visual>
      <origin rpy="0 0 0" xyz="0 0 0"/>
      <geometry>
        <mesh filename="./meshes/R_hip_roll_link.STL"/>
      </geometry>
      <material name="">
        <color rgba="0.698039215686274 0.698039215686274 0.698039215686274 1"/>
      </material>
    </visual>
    <collision>
      <origin rpy="0 0 0" xyz="0 0 0"/>
      <geometry>
        <mesh filename="./meshes/R_hip_roll_link.STL"/>
      </geometry>
    </collision>
  </link>
  <joint name="R_hip_roll_joint" type="revolute">
    <origin rpy="-0.2618 0 0" xyz="0 -0.053579 -0.02"/>
    <parent link="R_hip_pitch_link"/>
    <child link="R_hip_roll_link"/>
    <axis xyz="1 0 0"/>
    <limit effort="165" lower="-2.059" upper="0.314" velocity="8.9"/>
  </joint>
  <link name="R_hip_yaw_link">
    <inertial>
      <origin rpy="0 0 0" xyz="-0.00120109 0.00740989 -0.12388792"/>
      <mass value="5.13154726"/>
      <inertia ixx="0.04242003" ixy="-9.387E-05" ixz="-0.00132247" iyy="0.04461121" iyz="0.00037314" izz="0.01097485"/>
    </inertial>
    <visual>
      <origin rpy="0 0 0" xyz="0 0 0"/>
      <geometry>
        <mesh filename="./meshes/R_hip_yaw_link.STL"/>
      </geometry>
      <material name="">
        <color rgba="0.698039215686274 0.698039215686274 0.698039215686274 1"/>
      </material>
    </visual>
    <collision>
      <origin rpy="0 0 0" xyz="0 0 0"/>
      <geometry>
        <mesh filename="./meshes/R_hip_yaw_link.STL"/>
      </geometry>
    </collision>
  </link>
  <joint name="R_hip_yaw_joint" type="revolute">
    <origin rpy="0 0 0" xyz="0 0 -0.0621"/>
    <parent link="R_hip_roll_link"/>
    <child link="R_hip_yaw_link"/>
    <axis xyz="0 0 1"/>
    <limit effort="110" lower="-3.246" upper="2.146" velocity="10.47"/>
  </joint>
  <link name="R_knee_pitch_link">
    <inertial>
      <origin rpy="0 0 0" xyz="0.00271353 -0.00017413 -0.1604776"/>
      <mass value="3.32311625"/>
      <inertia ixx="0.03667916" ixy="2.614E-05" ixz="-0.00129682" iyy="0.03697352" iyz="0.00015974" izz="0.00350144"/>
    </inertial>
    <visual>
      <origin rpy="0 0 0" xyz="0 0 0"/>
      <geometry>
        <mesh filename="./meshes/R_knee_pitch_link.STL"/>
      </geometry>
      <material name="">
        <color rgba="0.792156862745098 0.819607843137255 0.933333333333333 1"/>
      </material>
    </visual>
    <collision>
      <origin rpy="0 0 0" xyz="0 0 0"/>
      <geometry>
        <mesh filename="./meshes/R_knee_pitch_link.STL"/>
      </geometry>
    </collision>
  </link>
  <joint name="R_knee_pitch_joint" type="revolute">
    <origin rpy="0 0 0" xyz="-0.035 0 -0.3179"/>
    <parent link="R_hip_yaw_link"/>
    <child link="R_knee_pitch_link"/>
    <axis xyz="0 1 0"/>
    <limit effort="210" lower="0.08" upper="2.478" velocity="10.47"/>
  </joint>
  <link name="R_ankle_pitch_link">
    <inertial>
      <origin rpy="0 0 0" xyz="0.00012374 0.00221434 -0.0057231"/>
      <mass value="0.11058391"/>
      <inertia ixx="2.571E-05" ixy="3E-08" ixz="8E-08" iyy="3.443E-05" iyz="-1.4E-06" izz="4.678E-05"/>
    </inertial>
    <visual>
      <origin rpy="0 0 0" xyz="0 0 0"/>
      <geometry>
        <mesh filename="./meshes/R_ankle_pitch_link.STL"/>
      </geometry>
      <material name="">
        <color rgba="0.627450980392157 0.627450980392157 0.627450980392157 1"/>
      </material>
    </visual>
    <collision>
      <origin rpy="0 0 0" xyz="0 0 0"/>
      <geometry>
        <mesh filename="./meshes/R_ankle_pitch_link.STL"/>
      </geometry>
    </collision>
  </link>
  <joint name="R_ankle_pitch_joint" type="revolute">
    <origin rpy="0 0 0" xyz="0 0 -0.410000000000008"/>
    <parent link="R_knee_pitch_link"/>
    <child link="R_ankle_pitch_link"/>
    <axis xyz="0 1 0"/>
    <limit effort="60" lower="-1.012" upper="0.488" velocity="12.57"/>
  </joint>
  <link name="R_ankle_roll_link">
    <inertial>
      <origin rpy="0 0 0" xyz="0.03406324 2.02E-06 -0.020996"/>
      <mass value="0.82687057"/>
      <inertia ixx="0.00099158" ixy="-1.9E-07" ixz="0.0002988" iyy="0.00442435" iyz="-2E-08" izz="0.00489724"/>
    </inertial>
    <visual>
      <origin rpy="0 0 0" xyz="0 0 0"/>
      <geometry>
        <mesh filename="./meshes/R_ankle_roll_link.STL"/>
      </geometry>
      <material name="">
        <color rgba="0.698039215686274 0.698039215686274 0.698039215686274 1"/>
      </material>
    </visual>
    <collision>
      <origin rpy="0 0 0" xyz="0 0 0"/>
      <geometry>
        <mesh filename="./meshes/R_ankle_roll_link.STL"/>
      </geometry>
    </collision>
  </link>
  <joint name="R_ankle_roll_joint" type="revolute">
    <origin rpy="0 0 0" xyz="0 0 -0.0120000000000001"/>
    <parent link="R_ankle_pitch_link"/>
    <child link="R_ankle_roll_link"/>
    <axis xyz="1 0 0"/>
    <limit effort="60" lower="-0.401" upper="0.401" velocity="12.57"/>
  </joint>
  <joint name="R_foot_ft_joint" type="fixed">
    <origin rpy="0 0 0" xyz="0 0 0"/>
    <parent link="R_ankle_roll_link"/>
    <child link="R_foot_ft_link"/>
  </joint>
  <link name="R_foot_ft_link">
    <inertial>
      <mass value="0.00005"/>
      <origin rpy="0 0 0" xyz="0 0 0"/>
      <inertia ixx="5e-11" ixy="0" ixz="0" iyy="5e-11" iyz="0" izz="1e-10"/>
    </inertial>
    <visual>
      <origin rpy="0 0 0" xyz="0 0 0"/>
      <geometry>
        <cylinder length="0.01" radius="0.01"/>
      </geometry>
    </visual>
    <material name="orange">
      <color rgba="255 108 10 255"/>
    </material>
  </link>
  <!-- for urdf2mojuco parse -->
  <ft_sensor name="R_foot_ft">
    <parent link="R_ankle_roll_link"/>
    <origin rpy="0 0 0" xyz="0 0 0"/>
  </ft_sensor>
  <link name="waist_yaw_link">
    <inertial>
      <origin rpy="0 0 0" xyz="0.00270178 -0.00088235 0.03695265"/>
      <mass value="2.06130216"/>
      <inertia ixx="0.00455692" ixy="2.339E-05" ixz="-0.0004179" iyy="0.00399271" iyz="9.219E-05" izz="0.00564475"/>
    </inertial>
    <visual>
      <origin rpy="0 0 0" xyz="0 0 0"/>
      <geometry>
        <mesh filename="./meshes/waist_yaw_link.STL"/>
      </geometry>
      <material name="">
        <color rgba="0.490196078431373 0.76078431372549 0.223529411764706 1"/>
      </material>
    </visual>
    <collision>
      <origin rpy="0 0 0" xyz="0 0 0"/>
      <geometry>
        <mesh filename="./meshes/waist_yaw_link.STL"/>
      </geometry>
    </collision>
  </link>
  <joint name="waist_yaw_joint" type="revolute">
    <origin rpy="0.0 0.0 0.0" xyz="0 0 0.0766405733000631"/>
    <parent link="base_link"/>
    <child link="waist_yaw_link"/>
    <axis xyz="0 0 1"/>
    <limit effort="63" lower="-2.792" upper="2.792" velocity="10.47"/>
  </joint>
  <link name="waist_pitch_link">
    <inertial>
      <origin rpy="0 0 0" xyz="-0.00141152 -0.00378014 -1.015E-05"/>
      <mass value="1.56616016"/>
      <inertia ixx="0.00193458" ixy="4.94E-06" ixz="-2.31E-06" iyy="0.00149086" iyz="1.11E-06" izz="0.0020082"/>
    </inertial>
    <visual>
      <origin rpy="0 0 0" xyz="0 0 0"/>
      <geometry>
        <mesh filename="./meshes/waist_pitch_link.STL"/>
      </geometry>
      <material name="">
        <color rgba="0.898039215686275 0.917647058823529 0.929411764705882 1"/>
      </material>
    </visual>
    <collision>
      <origin rpy="0 0 0" xyz="0 0 0"/>
      <geometry>
        <mesh filename="./meshes/waist_pitch_link.STL"/>
      </geometry>
    </collision>
  </link>
  <joint name="waist_pitch_joint" type="revolute">
    <origin rpy="0 0 0" xyz="0.0399999999999999 0 0.1155"/>
    <parent link="waist_yaw_link"/>
    <child link="waist_pitch_link"/>
    <axis xyz="0 1 0"/>
    <limit effort="165" lower="-0.017" upper="1.221" velocity="8.9"/>
  </joint>
  <link name="waist_roll_link">
    <inertial>
      <origin rpy="0 0 0" xyz="-0.0023246 0.00010908 0.15067891"/>
      <mass value="13.34004282"/>
      <inertia ixx="0.14820786" ixy="-0.0001414" ixz="-0.00914777" iyy="0.12699244" iyz="0.00012313" izz="0.07921235"/>
    </inertial>
    <visual>
      <origin rpy="0 0 0" xyz="0 0 0"/>
      <geometry>
        <mesh filename="./meshes/waist_roll_link.STL"/>
      </geometry>
      <material name="">
        <color rgba="1 1 1 1"/>
      </material>
    </visual>
    <collision>
      <origin rpy="0 0 0" xyz="0 0 0"/>
      <geometry>
        <mesh filename="./meshes/waist_roll_link.STL"/>
      </geometry>
    </collision>
  </link>
  <joint name="waist_roll_joint" type="revolute">
    <origin rpy="0 0 0" xyz="-0.0515000000005501 0 0"/>
    <parent link="waist_pitch_link"/>
    <child link="waist_roll_link"/>
    <axis xyz="1 0 0"/>
    <limit effort="110" lower="-0.75" upper="0.75" velocity="10.47"/>
  </joint>
  <link name="torso_link">
    <inertial>
      <origin rpy="0 0 0" xyz="0 0 0"/>
      <mass value="0.0001"/>
      <inertia ixx="1e-10" ixy="0" ixz="0" iyy="1e-10" iyz="0" izz="1e-10"/>
    </inertial>
  </link>
  <joint name="torso_waist_joint" type="fixed">
    <origin rpy="0 0 0" xyz="0.0115000000000002 0 0.247778898928156"/>
    <parent link="waist_roll_link"/>
    <child link="torso_link"/>
    <axis xyz="0 0 1"/>
  </joint>
  <link name="L_arm_base_link">
    <inertial>
      <origin rpy="0 0 0" xyz="0 0 0"/>
      <mass value="0.0001"/>
      <inertia ixx="1e-10" ixy="0" ixz="0" iyy="1e-10" iyz="0" izz="1e-10"/>
    </inertial>
  </link>
  <joint name="L_arm_base_joint" type="fixed">
    <origin rpy="0.174532925199404 0 0" xyz="0.0 0.114261537495599 0.0"/>
    <parent link="torso_link"/>
    <child link="L_arm_base_link"/>
    <axis xyz="0 0 1"/>
  </joint>
  <link name="L_shoulder_pitch_link">
    <inertial>
      <origin rpy="0 0 0" xyz="0.00379496 0.04690286 -4.625E-05"/>
      <mass value="0.79842185"/>
      <inertia ixx="0.00053576" ixy="-1.098E-05" ixz="-2.52E-06" iyy="0.00048497" iyz="5.49E-06" izz="0.00056322"/>
    </inertial>
    <visual>
      <origin rpy="0 0 0" xyz="0 0 0"/>
      <geometry>
        <mesh filename="./meshes/L_shoulder_pitch_link.STL"/>
      </geometry>
      <material name="">
        <color rgba="0.909803921568627 0.443137254901961 0.0313725490196078 1"/>
      </material>
    </visual>
    <collision>
      <origin rpy="0 0 0" xyz="0 0 0"/>
      <geometry>
        <mesh filename="./meshes/L_shoulder_pitch_link.STL"/>
      </geometry>
    </collision>
  </link>
  <joint name="L_shoulder_pitch_joint" type="revolute">
    <origin rpy="0 0 0" xyz="0 0 0"/>
    <parent link="L_arm_base_link"/>
    <child link="L_shoulder_pitch_link"/>
    <axis xyz="0 1 0"/>
    <limit effort="60" lower="-3.089" upper="2.565" velocity="13.61"/>
  </joint>
  <link name="L_shoulder_roll_link">
    <inertial>
      <origin rpy="0 0 0" xyz="0.00388223 0.00090177 -0.08144232"/>
      <mass value="0.95445238"/>
      <inertia ixx="0.00164727" ixy="7.19E-06" ixz="-0.00025056" iyy="0.00173441" iyz="-6.456E-05" izz="0.00083765"/>
    </inertial>
    <visual>
      <origin rpy="0 0 0" xyz="0 0 0"/>
      <geometry>
        <mesh filename="./meshes/L_shoulder_roll_link.STL"/>
      </geometry>
      <material name="">
        <color rgba="1 1 1 1"/>
      </material>
    </visual>
    <collision>
      <origin rpy="0 0 0" xyz="0 0 0"/>
      <geometry>
        <mesh filename="./meshes/L_shoulder_roll_link.STL"/>
      </geometry>
    </collision>
  </link>
  <joint name="L_shoulder_roll_joint" type="revolute">
    <origin rpy="0 0 0" xyz="0 0.0499000000000001 0"/>
    <parent link="L_shoulder_pitch_link"/>
    <child link="L_shoulder_roll_link"/>
    <axis xyz="1 0 0"/>
    <limit effort="60" lower="-0.139" upper="1.884" velocity="13.61"/>
  </joint>
  <link name="L_shoulder_yaw_link">
    <inertial>
      <origin rpy="0 0 0" xyz="-0.00111624 -0.00509191 -0.07778589"/>
      <mass value="0.95157552"/>
      <inertia ixx="0.00135197" ixy="2.72E-06" ixz="2.03E-05" iyy="0.00136425" iyz="-6.158E-05" izz="0.0006392"/>
    </inertial>
    <visual>
      <origin rpy="0 0 0" xyz="0 0 0"/>
      <geometry>
        <mesh filename="./meshes/L_shoulder_yaw_link.STL"/>
      </geometry>
      <material name="">
        <color rgba="0.698039215686274 0.698039215686274 0.698039215686274 1"/>
      </material>
    </visual>
    <collision>
      <origin rpy="0 0 0" xyz="0 0 0"/>
      <geometry>
        <mesh filename="./meshes/L_shoulder_yaw_link.STL"/>
      </geometry>
    </collision>
  </link>
  <joint name="L_shoulder_yaw_joint" type="revolute">
    <origin rpy="0 0 0" xyz="0 0 -0.126749998384828"/>
    <parent link="L_shoulder_roll_link"/>
    <child link="L_shoulder_yaw_link"/>
    <axis xyz="0 0 1"/>
    <limit effort="25" lower="-2.844" upper="2.844" velocity="13.61"/>
  </joint>
  <link name="L_elbow_pitch_link">
    <inertial>
      <origin rpy="0 0 0" xyz="-0.00109585 -0.00301164 -0.08162983"/>
      <mass value="0.91030288"/>
      <inertia ixx="0.0015001" ixy="-7.5E-07" ixz="6.414E-05" iyy="0.00142992" iyz="0.00019571" izz="0.00073744"/>
    </inertial>
    <visual>
      <origin rpy="0 0 0" xyz="0 0 0"/>
      <geometry>
        <mesh filename="./meshes/L_elbow_pitch_link.STL"/>
      </geometry>
      <material name="">
        <color rgba="0.909803921568627 0.443137254901961 0.0313725490196078 1"/>
      </material>
    </visual>
    <collision>
      <origin rpy="0 0 0" xyz="0 0 0"/>
      <geometry>
        <mesh filename="./meshes/L_elbow_pitch_link.STL"/>
      </geometry>
    </collision>
  </link>
  <joint name="L_elbow_pitch_joint" type="revolute">
    <origin rpy="0 0 0" xyz="0 0 -0.0932499981849194"/>
    <parent link="L_shoulder_yaw_link"/>
    <child link="L_elbow_pitch_link"/>
    <axis xyz="0 1 0"/>
    <limit effort="25" lower="-2.2689" upper="0.104" velocity="13.61"/>
  </joint>
  <link name="L_elbow_yaw_link">
    <inertial>
      <origin rpy="0 0 0" xyz="0.00041996 0.00835103 -0.0205441"/>
      <mass value="0.09233082"/>
      <inertia ixx="8.165E-05" ixy="1.5E-07" ixz="6.7E-07" iyy="6.775E-05" iyz="1.273E-05" izz="7.884E-05"/>
    </inertial>
    <visual>
      <origin rpy="0 0 0" xyz="0 0 0"/>
      <geometry>
        <mesh filename="./meshes/L_elbow_yaw_link.STL"/>
      </geometry>
      <material name="">
        <color rgba="1 1 1 1"/>
      </material>
    </visual>
    <collision>
      <origin rpy="0 0 0" xyz="0 0 0"/>
      <geometry>
        <mesh filename="./meshes/L_elbow_yaw_link.STL"/>
      </geometry>
    </collision>
  </link>
  <joint name="L_elbow_yaw_joint" type="revolute">
    <origin rpy="0 0 0" xyz="0 0 -0.124250001797163"/>
    <parent link="L_elbow_pitch_link"/>
    <child link="L_elbow_yaw_link"/>
    <axis xyz="0 0 1"/>
    <limit effort="25" lower="-2.844" upper="2.844" velocity="13.61"/>
  </joint>
  <link name="L_wrist_pitch_link">
    <inertial>
      <origin rpy="0 0 0" xyz="0.00244378 0.00252389 -0.01940281"/>
      <mass value="0.49823595"/>
      <inertia ixx="0.00032853" ixy="3.17E-06" ixz="2.818E-05" iyy="0.00033198" iyz="-2.391E-05" izz="0.00017354"/>
    </inertial>
    <visual>
      <origin rpy="0 0 0" xyz="0 0 0"/>
      <geometry>
        <mesh filename="./meshes/L_wrist_pitch_link.STL"/>
      </geometry>
      <material name="">
        <color rgba="0.898039215686275 0.917647058823529 0.929411764705882 1"/>
      </material>
    </visual>
    <collision>
      <origin rpy="0 0 0" xyz="0 0 0"/>
      <geometry>
        <mesh filename="./meshes/L_wrist_pitch_link.STL"/>
      </geometry>
    </collision>
  </link>
  <joint name="L_wrist_pitch_joint" type="revolute">
    <origin rpy="0 0 0" xyz="0 0 -0.05575"/>
    <parent link="L_elbow_yaw_link"/>
    <child link="L_wrist_pitch_link"/>
    <axis xyz="0 1 0"/>
    <limit effort="6" lower="-0.68" upper="0.68" velocity="12.57"/>
  </joint>
  <link name="L_wrist_roll_link">
    <inertial>
      <origin rpy="0 0 0" xyz="0.0085537 -1.437E-05 -0.02191296"/>
      <mass value="0.04766635"/>
      <inertia ixx="2.225E-05" ixy="0" ixz="-7.71E-06" iyy="4.753E-05" iyz="0" izz="3.827E-05"/>
    </inertial>
    <visual>
      <origin rpy="0 0 0" xyz="0 0 0"/>
      <geometry>
        <mesh filename="./meshes/L_wrist_roll_link.STL"/>
      </geometry>
      <material name="">
        <color rgba="1 1 1 1"/>
      </material>
    </visual>
    <collision>
      <origin rpy="0 0 0" xyz="0 0 0"/>
      <geometry>
        <mesh filename="./meshes/L_wrist_roll_link.STL"/>
      </geometry>
    </collision>
  </link>
  <joint name="L_wrist_roll_joint" type="revolute">
    <origin rpy="0 0 0" xyz="0 0 -0.0399515014686295"/>
    <parent link="L_wrist_pitch_link"/>
    <child link="L_wrist_roll_link"/>
    <axis xyz="1 0 0"/>
    <limit effort="6" lower="-1.57" upper="1.57" velocity="12.57"/>
  </joint>
  <link
    name="L_sixforce_link">
    <inertial>
      <origin
        xyz="-0.00011076 3.22E-06 0.01133832"
        rpy="0 0 0" />
      <mass
        value="0.2454096" />
      <inertia
        ixx="7.52E-05"
        ixy="0"
        ixz="-2.13E-06"
        iyy="9.35E-05"
        iyz="0"
        izz="0.000106" />
    </inertial>
    <visual>
      <origin
        xyz="0 0 0"
        rpy="0 0 0" />
      <geometry>
        <mesh
          filename="L_sixforce_link.STL" />
      </geometry>
      <material
        name="">
        <color
          rgba="1 1 1 1" />
      </material>
    </visual>
    <collision>
      <origin
        xyz="0 0 0"
        rpy="0 0 0" />
      <geometry>
        <mesh
          filename="L_sixforce_link.STL" />
      </geometry>
    </collision>
  </link>
  <joint
    name="L_sixforce_joint"
    type="fixed">
    <origin
      xyz="-0.0044948 -0.0019462 -0.084379"
      rpy="-0.004889 0.0051472 0" />
    <parent
      link="L_wrist_roll_link" />
    <child
      link="L_sixforce_link" />
    <axis
      xyz="0 0 0" />
  </joint>
    <link
    name="L_hand_link">
    <inertial>
      <origin
        xyz="0.01534045 2E-06 -0.00192629"
        rpy="0 0 0" />
      <mass
        value="0.28014837" />
      <inertia
        ixx="0.0003278"
        ixy="-2E-08"
        ixz="-9.94E-06"
        iyy="0.00042842"
        iyz="0"
        izz="0.00038273" />
    </inertial>
  </link>
  <joint
    name="L_hand_joint"
    type="fixed">
    <origin
      xyz="-0.075478 -0.00070644 -0.0055"
      rpy="0 0 0.0093592" />
    <parent
      link="L_sixforce_link" />
    <child
      link="L_hand_link" />
    <axis
      xyz="0 0 0" />
  </joint>
  <joint
    name="L_dexterous_hand_mount_joint"
    type="fixed">
    <origin
      xyz="0.08 0 0.05"
      rpy="3.14 0 3.14" />
    <parent
      link="L_hand_link" />
    <child
      link="L_hand_base_link" />
    <axis
      xyz="0 0 0" />
  </joint>
  <mujoco>
    <compiler
      meshdir="../../meshes/hand3_v1"
      balanceinertia="false"
      discardvisual="false"
      autolimits="true"
      inertiafromgeom="false"
      convexhull="false"
      boundmass="0.0001"
      usethread="true" />
  </mujoco>
  <link
    name="L_hand_base_link">
    <inertial>
      <origin
        xyz="0.00065934 0.00064662 0.02223161"
        rpy="0 0 0" />
      <mass
        value="0.05238695" />
      <inertia
        ixx="0.00001722"
        ixy="0.00000028"
        ixz="-0.00000043"
        iyy="0.00003682"
        iyz="-0.00000022"
        izz="0.00004011" />
    </inertial>
    <visual>
      <origin
        xyz="0 0 0"
        rpy="0 0 0" />
      <geometry>
        <mesh
          filename="./meshes/hand_v3/left/L_hand_base_link.STL" />
      </geometry>
      <material
        name="">
        <color
          rgba="0.792156862745098 0.819607843137255 0.933333333333333 1" />
      </material>
    </visual>
    <collision>
      <origin
        xyz="0 0 0"
        rpy="0 0 0" />
      <geometry>
        <mesh
          filename="./meshes/hand_v3/left/L_hand_base_link.STL" />
      </geometry>
    </collision>
  </link>
  <link
    name="L_palm_link">
    <inertial>
      <origin
        xyz="-0.00938866 -0.00221701 -0.0117814"
        rpy="0 0 0" />
      <mass
        value="0.38223591" />
      <inertia
        ixx="0.00022773"
        ixy="-0.00000169"
        ixz="0.00000005"
        iyy="0.00035269"
        iyz="-0.00001316"
        izz="0.00050349" />
    </inertial>
    <visual>
      <origin
        xyz="0 0 0"
        rpy="0 0 0" />
      <geometry>
        <mesh
          filename="./meshes/hand_v3/left/L_palm_link.STL" />
      </geometry>
      <material
        name="">
        <color
          rgba="1 1 1 1" />
      </material>
    </visual>
    <collision>
      <origin
        xyz="0 0 0"
        rpy="0 0 0" />
      <geometry>
        <mesh
          filename="./meshes/hand_v3/left/L_palm_link.STL" />
      </geometry>
    </collision>
  </link>
  <joint
    name="L_palm_joint"
    type="fixed">
    <origin
      xyz="0.00035572 -0.013196 0.099778"
      rpy="1.5708 -1.5708 0" />
    <parent
      link="L_hand_base_link" />
    <child
      link="L_palm_link" />
    <axis
      xyz="0 0 0" />
    <limit
      lower="0"
      upper="0"
      effort="0"
      velocity="0" />
  </joint>
  <link
    name="L_thumb_cmp_link">
    <inertial>
      <origin
        xyz="0.00563085 -0.00075 -0.00435852"
        rpy="0 0 0" />
      <mass
        value="0.01511033" />
      <inertia
        ixx="0.00000093"
        ixy="0.00000007"
        ixz="0.0000003"
        iyy="0.00000105"
        iyz="-0.00000002"
        izz="0.00000107" />
    </inertial>
    <visual>
      <origin
        xyz="0 0 0"
        rpy="0 0 0" />
      <geometry>
        <mesh
          filename="./meshes/hand_v3/left/L_thumb_cmp_link.STL" />
      </geometry>
      <material
        name="">
        <color
          rgba="0.752941176470588 0.752941176470588 0.752941176470588 1" />
      </material>
    </visual>
    <collision>
      <origin
        xyz="0 0 0"
        rpy="0 0 0" />
      <geometry>
        <mesh
          filename="./meshes/hand_v3/left/L_thumb_cmp_link.STL" />
      </geometry>
    </collision>
  </link>
  <joint
    name="L_thumb_cmp_joint"
    type="revolute">
    <origin
      xyz="-0.048578 0.028956 -0.0073648"
      rpy="-1.5708 -0.75224 1.5708" />
    <parent
      link="L_palm_link" />
    <child
      link="L_thumb_cmp_link" />
    <axis
      xyz="0 0 1" />
    <limit
      lower="-0.96"
      upper="0"
      effort="1.35"
      velocity="2.09" />
  </joint>
  <link
    name="L_thumb_mpp_link">
    <inertial>
      <origin
        xyz="0.03618423 -0.00195018 -0.00007704"
        rpy="0 0 0" />
      <mass
        value="0.06741198" />
      <inertia
        ixx="0.00000637"
        ixy="-0.00000267"
        ixz="0.00000003"
        iyy="0.00003296"
        iyz="0"
        izz="0.00003268" />
    </inertial>
    <visual>
      <origin
        xyz="0 0 0"
        rpy="0 0 0" />
      <geometry>
        <mesh
          filename="./meshes/hand_v3/left/L_thumb_mpp_link.STL" />
      </geometry>
      <material
        name="">
        <color
          rgba="0.752941176470588 0.752941176470588 0.752941176470588 1" />
      </material>
    </visual>
    <collision>
      <origin
        xyz="0 0 0"
        rpy="0 0 0" />
      <geometry>
        <mesh
          filename="./meshes/hand_v3/left/L_thumb_mpp_link.STL" />
      </geometry>
    </collision>
  </link>
  <joint
    name="L_thumb_mpp_joint"
    type="revolute">
    <origin
      xyz="0.012 -0.0010557 -0.010045"
      rpy="-1.6755 0 0" />
    <parent
      link="L_thumb_cmp_link" />
    <child
      link="L_thumb_mpp_link" />
    <axis
      xyz="0 0 1" />
    <limit
      lower="0"
      upper="1.04"
      effort="1.35"
      velocity="2.09" />
  </joint>
  <link
    name="L_thumb_ip_link">
    <inertial>
      <origin
        xyz="0.01353705 0.00416931 0.00000614"
        rpy="0 0 0" />
      <mass
        value="0.01731117" />
      <inertia
        ixx="0.00000104"
        ixy="-0.00000015"
        ixz="0"
        iyy="0.00000185"
        iyz="0"
        izz="0.00000176" />
    </inertial>
    <visual>
      <origin
        xyz="0 0 0"
        rpy="0 0 0" />
      <geometry>
        <mesh
          filename="./meshes/hand_v3/left/L_thumb_ip_link.STL" />
      </geometry>
      <material
        name="">
        <color
          rgba="0.752941176470588 0.752941176470588 0.752941176470588 1" />
      </material>
    </visual>
    <collision>
      <origin
        xyz="0 0 0"
        rpy="0 0 0" />
      <geometry>
        <mesh
          filename="./meshes/hand_v3/left/L_thumb_ip_link.STL" />
      </geometry>
    </collision>
  </link>
  <joint
    name="L_thumb_ip_joint"
    type="revolute">
    <origin
      xyz="0.075 -1.163E-05 0"
      rpy="0 0 0" />
    <parent
      link="L_thumb_mpp_link" />
    <child
      link="L_thumb_ip_link" />
    <axis
      xyz="0 0 1" />
    <limit
      lower="0"
      upper="1.05"
      effort="1.35"
      velocity="2.09" />
  </joint>
  <link
    name="L_index_mpp_link">
    <inertial>
      <origin
        xyz="0.01525314 -0.00181681 0.00015205"
        rpy="0 0 0" />
      <mass
        value="0.01470075" />
      <inertia
        ixx="0.00000087"
        ixy="0"
        ixz="0"
        iyy="0.00000357"
        iyz="0"
        izz="0.00000352" />
    </inertial>
    <visual>
      <origin
        xyz="0 0 0"
        rpy="0 0 0" />
      <geometry>
        <mesh
          filename="./meshes/hand_v3/left/L_index_mpp_link.STL" />
      </geometry>
      <material
        name="">
        <color
          rgba="0.752941176470588 0.752941176470588 0.752941176470588 1" />
      </material>
    </visual>
    <collision>
      <origin
        xyz="0 0 0"
        rpy="0 0 0" />
      <geometry>
        <mesh
          filename="./meshes/hand_v3/left/L_index_mpp_link.STL" />
      </geometry>
    </collision>
  </link>
  <joint
    name="L_index_mpp_joint"
    type="revolute">
    <origin
      xyz="0.041817 0.030769 -0.011696"
      rpy="1.5708 -0.18118 0.020071" />
    <parent
      link="L_palm_link" />
    <child
      link="L_index_mpp_link" />
    <axis
      xyz="0 0 1" />
    <limit
      lower="0"
      upper="1.46"
      effort="1.35"
      velocity="2.09" />
  </joint>
  <link
    name="L_index_ip_link">
    <inertial>
      <origin
        xyz="0.01680857 -0.00117535 0"
        rpy="0 0 0" />
      <mass
        value="0.01334933" />
      <inertia
        ixx="0.00000042"
        ixy="-0.00000029"
        ixz="0"
        iyy="0.00000262"
        iyz="0"
        izz="0.00000261" />
    </inertial>
    <visual>
      <origin
        xyz="0 0 0"
        rpy="0 0 0" />
      <geometry>
        <mesh
          filename="./meshes/hand_v3/left/L_index_ip_link.STL" />
      </geometry>
      <material
        name="">
        <color
          rgba="0.752941176470588 0.752941176470588 0.752941176470588 1" />
      </material>
    </visual>
    <collision>
      <origin
        xyz="0 0 0"
        rpy="0 0 0" />
      <geometry>
        <mesh
          filename="./meshes/hand_v3/left/L_index_ip_link.STL" />
      </geometry>
    </collision>
  </link>
  <joint
    name="L_index_ip_joint"
    type="revolute">
    <origin
      xyz="0.0388 0 0"
      rpy="0 0 -0.014509" />
    <parent
      link="L_index_mpp_link" />
    <child
      link="L_index_ip_link" />
    <axis
      xyz="0 0 1" />
    <limit
      lower="0"
      upper="1.62"
      effort="1.35"
      velocity="2.09" />
  </joint>
  <link
    name="L_middle_mpp_link">
    <inertial>
      <origin
        xyz="0.01476009 -0.00171481 0.00012869"
        rpy="0 0 0" />
      <mass
        value="0.01430214" />
      <inertia
        ixx="0.00000086"
        ixy="-0.00000003"
        ixz="0"
        iyy="0.00000344"
        iyz="0"
        izz="0.00000339" />
    </inertial>
    <visual>
      <origin
        xyz="0 0 0"
        rpy="0 0 0" />
      <geometry>
        <mesh
          filename="./meshes/hand_v3/left/L_middle_mpp_link.STL" />
      </geometry>
      <material
        name="">
        <color
          rgba="0.752941176470588 0.752941176470588 0.752941176470588 1" />
      </material>
    </visual>
    <collision>
      <origin
        xyz="0 0 0"
        rpy="0 0 0" />
      <geometry>
        <mesh
          filename="./meshes/hand_v3/left/L_middle_mpp_link.STL" />
      </geometry>
    </collision>
  </link>
  <joint
    name="L_middle_mpp_joint"
    type="revolute">
    <origin
      xyz="0.042022 0.010356 -0.011696"
      rpy="1.5708 -0.18118 0" />
    <parent
      link="L_palm_link" />
    <child
      link="L_middle_mpp_link" />
    <axis
      xyz="0 0 1" />
    <limit
      lower="0"
      upper="1.46"
      effort="1.35"
      velocity="2.09" />
  </joint>
  <link
    name="L_middle_ip_link">
    <inertial>
      <origin
        xyz="0.01771317 -0.00109666 0.0000256"
        rpy="0 0 0" />
      <mass
        value="0.0148881" />
      <inertia
        ixx="0.00000047"
        ixy="-0.00000038"
        ixz="0"
        iyy="0.00000344"
        iyz="0"
        izz="0.00000344" />
    </inertial>
    <visual>
      <origin
        xyz="0 0 0"
        rpy="0 0 0" />
      <geometry>
        <mesh
          filename="./meshes/hand_v3/left/L_middle_ip_link.STL" />
      </geometry>
      <material
        name="">
        <color
          rgba="0.752941176470588 0.752941176470588 0.752941176470588 1" />
      </material>
    </visual>
    <collision>
      <origin
        xyz="0 0 0"
        rpy="0 0 0" />
      <geometry>
        <mesh
          filename="./meshes/hand_v3/left/L_middle_ip_link.STL" />
      </geometry>
    </collision>
  </link>
  <joint
    name="L_middle_ip_joint"
    type="revolute">
    <origin
      xyz="0.0388 0 0"
      rpy="0 0 -0.012066" />
    <parent
      link="L_middle_mpp_link" />
    <child
      link="L_middle_ip_link" />
    <axis
      xyz="0 0 1" />
    <limit
      lower="0"
      upper="1.62"
      effort="1.35"
      velocity="2.09" />
  </joint>
  <link
    name="L_ring_mpp_link">
    <inertial>
      <origin
        xyz="0.01475954 -0.00171495 0.00012869"
        rpy="0 0 0" />
      <mass
        value="0.01430214" />
      <inertia
        ixx="0.00000086"
        ixy="-0.00000003"
        ixz="0"
        iyy="0.00000344"
        iyz="0"
        izz="0.00000339" />
    </inertial>
    <visual>
      <origin
        xyz="0 0 0"
        rpy="0 0 0" />
      <geometry>
        <mesh
          filename="./meshes/hand_v3/left/L_ring_mpp_link.STL" />
      </geometry>
      <material
        name="">
        <color
          rgba="0.752941176470588 0.752941176470588 0.752941176470588 1" />
      </material>
    </visual>
    <collision>
      <origin
        xyz="0 0 0"
        rpy="0 0 0" />
      <geometry>
        <mesh
          filename="./meshes/hand_v3/left/L_ring_mpp_link.STL" />
      </geometry>
    </collision>
  </link>
  <joint
    name="L_ring_mpp_joint"
    type="revolute">
    <origin
      xyz="0.041817 -0.010057 -0.011696"
      rpy="1.5708 -0.18118 -0.020071" />
    <parent
      link="L_palm_link" />
    <child
      link="L_ring_mpp_link" />
    <axis
      xyz="0 0 1" />
    <limit
      lower="0"
      upper="1.46"
      effort="1.35"
      velocity="2.09" />
  </joint>
  <link
    name="L_ring_ip_link">
    <inertial>
      <origin
        xyz="0.01615432 -0.00130235 0.00002763"
        rpy="0 0 0" />
      <mass
        value="0.01374794" />
      <inertia
        ixx="0.00000043"
        ixy="-0.00000033"
        ixz="0"
        iyy="0.00000282"
        iyz="0"
        izz="0.00000281" />
    </inertial>
    <visual>
      <origin
        xyz="0 0 0"
        rpy="0 0 0" />
      <geometry>
        <mesh
          filename="./meshes/hand_v3/left/L_ring_ip_link.STL" />
      </geometry>
      <material
        name="">
        <color
          rgba="0.752941176470588 0.752941176470588 0.752941176470588 1" />
      </material>
    </visual>
    <collision>
      <origin
        xyz="0 0 0"
        rpy="0 0 0" />
      <geometry>
        <mesh
          filename="./meshes/hand_v3/left/L_ring_ip_link.STL" />
      </geometry>
    </collision>
  </link>
  <joint
    name="L_ring_ip_joint"
    type="revolute">
    <origin
      xyz="0.0388 0 0"
      rpy="0 0 -0.014509" />
    <parent
      link="L_ring_mpp_link" />
    <child
      link="L_ring_ip_link" />
    <axis
      xyz="0 0 1" />
    <limit
      lower="0"
      upper="1.62"
      effort="1.35"
      velocity="2.09" />
  </joint>
  <link
    name="L_little_mpp_link">
    <inertial>
      <origin
        xyz="0.0147588 -0.00171514 0.00012869"
        rpy="0 0 0" />
      <mass
        value="0.01430214" />
      <inertia
        ixx="0.00000086"
        ixy="-0.00000003"
        ixz="0"
        iyy="0.00000344"
        iyz="0"
        izz="0.00000339" />
    </inertial>
    <visual>
      <origin
        xyz="0 0 0"
        rpy="0 0 0" />
      <geometry>
        <mesh
          filename="./meshes/hand_v3/left/L_little_mpp_link.STL" />
      </geometry>
      <material
        name="">
        <color
          rgba="0.752941176470588 0.752941176470588 0.752941176470588 1" />
      </material>
    </visual>
    <collision>
      <origin
        xyz="0 0 0"
        rpy="0 0 0" />
      <geometry>
        <mesh
          filename="./meshes/hand_v3/left/L_little_mpp_link.STL" />
      </geometry>
    </collision>
  </link>
  <joint
    name="L_little_mpp_joint"
    type="revolute">
    <origin
      xyz="0.041203 -0.030462 -0.011696"
      rpy="1.5708 -0.18118 -0.040143" />
    <parent
      link="L_palm_link" />
    <child
      link="L_little_mpp_link" />
    <axis
      xyz="0 0 1" />
    <limit
      lower="0"
      upper="1.46"
      effort="1.35"
      velocity="2.09" />
  </joint>
  <link
    name="L_little_ip_link">
    <inertial>
      <origin
        xyz="0.01303327 -0.00143438 0.0000295"
        rpy="0 0 0" />
      <mass
        value="0.01179268" />
      <inertia
        ixx="0.00000034"
        ixy="-0.00000023"
        ixz="0"
        iyy="0.00000179"
        iyz="0"
        izz="0.00000178" />
    </inertial>
    <visual>
      <origin
        xyz="0 0 0"
        rpy="0 0 0" />
      <geometry>
        <mesh
          filename="./meshes/hand_v3/left/L_little_ip_link.STL" />
      </geometry>
      <material
        name="">
        <color
          rgba="0.752941176470588 0.752941176470588 0.752941176470588 1" />
      </material>
    </visual>
    <collision>
      <origin
        xyz="0 0 0"
        rpy="0 0 0" />
      <geometry>
        <mesh
          filename="./meshes/hand_v3/left/L_little_ip_link.STL" />
      </geometry>
    </collision>
  </link>
  <joint
    name="L_little_ip_joint"
    type="revolute">
    <origin
      xyz="0.0388 0 0"
      rpy="0 0 -0.014509" />
    <parent
      link="L_little_mpp_link" />
    <child
      link="L_little_ip_link" />
    <axis
      xyz="0 0 1" />
    <limit
      lower="0"
      upper="1.62"
      effort="1.35"
      velocity="2.09" />
  </joint>
  <link name="R_arm_base_link">
    <inertial>
      <origin rpy="0 0 0" xyz="0 0 0"/>
      <mass value="0.0001"/>
      <inertia ixx="1e-10" ixy="0" ixz="0" iyy="1e-10" iyz="0" izz="1e-10"/>
    </inertial>
  </link>
  <joint name="R_arm_base_joint" type="fixed">
    <origin rpy="-0.174532925199405 0 0" xyz="0.0 -0.114809942431709 0.0"/>
    <parent link="torso_link"/>
    <child link="R_arm_base_link"/>
    <axis xyz="0 0 1"/>
  </joint>
  <link name="R_shoulder_pitch_link">
    <inertial>
      <origin rpy="0 0 0" xyz="0.00384148 -0.046973 7.92E-06"/>
      <mass value="0.79994046"/>
      <inertia ixx="0.00053607" ixy="6.43E-06" ixz="-2.4E-07" iyy="0.00048679" iyz="-5.14E-06" izz="0.00056359"/>
    </inertial>
    <visual>
      <origin rpy="0 0 0" xyz="0 0 0"/>
      <geometry>
        <mesh filename="./meshes/R_shoulder_pitch_link.STL"/>
      </geometry>
      <material name="">
        <color rgba="0.909803921568627 0.443137254901961 0.0313725490196078 1"/>
      </material>
    </visual>
    <collision>
      <origin rpy="0 0 0" xyz="0 0 0"/>
      <geometry>
        <mesh filename="./meshes/R_shoulder_pitch_link.STL"/>
      </geometry>
    </collision>
  </link>
  <joint name="R_shoulder_pitch_joint" type="revolute">
    <origin rpy="0 0 0" xyz="0 0 0"/>
    <parent link="R_arm_base_link"/>
    <child link="R_shoulder_pitch_link"/>
    <axis xyz="0 1 0"/>
    <limit effort="60" lower="-3.089" upper="2.565" velocity="13.61"/>
  </joint>
  <link name="R_shoulder_roll_link">
    <inertial>
      <origin rpy="0 0 0" xyz="0.00374986 -0.00090026 -0.08145595"/>
      <mass value="0.95418329"/>
      <inertia ixx="0.00164607" ixy="-7.42E-06" ixz="-0.00024807" iyy="0.00173406" iyz="6.443E-05" izz="0.00083829"/>
    </inertial>
    <visual>
      <origin rpy="0 0 0" xyz="0 0 0"/>
      <geometry>
        <mesh filename="./meshes/R_shoulder_roll_link.STL"/>
      </geometry>
      <material name="">
        <color rgba="0.909803921568627 0.443137254901961 0.0313725490196078 1"/>
      </material>
    </visual>
    <collision>
      <origin rpy="0 0 0" xyz="0 0 0"/>
      <geometry>
        <mesh filename="./meshes/R_shoulder_roll_link.STL"/>
      </geometry>
    </collision>
  </link>
  <joint name="R_shoulder_roll_joint" type="revolute">
    <origin rpy="0 0 0" xyz="0 -0.0499 0"/>
    <parent link="R_shoulder_pitch_link"/>
    <child link="R_shoulder_roll_link"/>
    <axis xyz="1 0 0"/>
    <limit effort="60" lower="-1.884" upper="0.139" velocity="13.61"/>
  </joint>
  <link name="R_shoulder_yaw_link">
    <inertial>
      <origin rpy="0 0 0" xyz="-0.00111484 -0.00508263 -0.07767727"/>
      <mass value="0.95271279"/>
      <inertia ixx="0.00135945" ixy="2.71E-06" ixz="2.018E-05" iyy="0.00137161" iyz="-6.206E-05" izz="0.00063937"/>
    </inertial>
    <visual>
      <origin rpy="0 0 0" xyz="0 0 0"/>
      <geometry>
        <mesh filename="./meshes/R_shoulder_yaw_link.STL"/>
      </geometry>
      <material name="">
        <color rgba="0.698039215686274 0.698039215686274 0.698039215686274 1"/>
      </material>
    </visual>
    <collision>
      <origin rpy="0 0 0" xyz="0 0 0"/>
      <geometry>
        <mesh filename="./meshes/R_shoulder_yaw_link.STL"/>
      </geometry>
    </collision>
  </link>
  <joint name="R_shoulder_yaw_joint" type="revolute">
    <origin rpy="0 0 0" xyz="0 0 -0.126750000099661"/>
    <parent link="R_shoulder_roll_link"/>
    <child link="R_shoulder_yaw_link"/>
    <axis xyz="0 0 1"/>
    <limit effort="25" lower="-2.844" upper="2.844" velocity="13.61"/>
  </joint>
  <link name="R_elbow_pitch_link">
    <inertial>
      <origin rpy="0 0 0" xyz="-0.00109585 -0.00301164 -0.08162983"/>
      <mass value="0.91030288"/>
      <inertia ixx="0.00150011" ixy="-7.5E-07" ixz="6.414E-05" iyy="0.00142992" iyz="0.00019571" izz="0.00073744"/>
    </inertial>
    <visual>
      <origin rpy="0 0 0" xyz="0 0 0"/>
      <geometry>
        <mesh filename="./meshes/R_elbow_pitch_link.STL"/>
      </geometry>
      <material name="">
        <color rgba="0.909803921568627 0.443137254901961 0.0313725490196078 1"/>
      </material>
    </visual>
    <collision>
      <origin rpy="0 0 0" xyz="0 0 0"/>
      <geometry>
        <mesh filename="./meshes/R_elbow_pitch_link.STL"/>
      </geometry>
    </collision>
  </link>
  <joint name="R_elbow_pitch_joint" type="revolute">
    <origin rpy="0 0 0" xyz="0 0 -0.0932499981849196"/>
    <parent link="R_shoulder_yaw_link"/>
    <child link="R_elbow_pitch_link"/>
    <axis xyz="0 1 0"/>
    <limit effort="25" lower="-2.2689" upper="0.104" velocity="13.61"/>
  </joint>
  <link name="R_elbow_yaw_link">
    <inertial>
      <origin rpy="0 0 0" xyz="0.00042308 0.00819376 -0.0202823"/>
      <mass value="0.09164929"/>
      <inertia ixx="8.047E-05" ixy="1.4E-07" ixz="6.8E-07" iyy="6.686E-05" iyz="1.222E-05" izz="7.851E-05"/>
    </inertial>
    <visual>
      <origin rpy="0 0 0" xyz="0 0 0"/>
      <geometry>
        <mesh filename="./meshes/R_elbow_yaw_link.STL"/>
      </geometry>
      <material name="">
        <color rgba="1 1 1 1"/>
      </material>
    </visual>
    <collision>
      <origin rpy="0 0 0" xyz="0 0 0"/>
      <geometry>
        <mesh filename="./meshes/R_elbow_yaw_link.STL"/>
      </geometry>
    </collision>
  </link>
  <joint name="R_elbow_yaw_joint" type="revolute">
    <origin rpy="0 0 0" xyz="0 0 -0.124250001797163"/>
    <parent link="R_elbow_pitch_link"/>
    <child link="R_elbow_yaw_link"/>
    <axis xyz="0 0 1"/>
    <limit effort="25" lower="-2.844" upper="2.844" velocity="13.61"/>
  </joint>
  <link name="R_wrist_pitch_link">
    <inertial>
      <origin rpy="0 0 0" xyz="0.00244378 0.00252389 -0.01940281"/>
      <mass value="0.49823595"/>
      <inertia ixx="0.00032853" ixy="3.17E-06" ixz="2.818E-05" iyy="0.00033198" iyz="-2.391E-05" izz="0.00017354"/>
    </inertial>
    <visual>
      <origin rpy="0 0 0" xyz="0 0 0"/>
      <geometry>
        <mesh filename="./meshes/R_wrist_pitch_link.STL"/>
      </geometry>
      <material name="">
        <color rgba="0.647058823529412 1 0.529411764705882 1"/>
      </material>
    </visual>
    <collision>
      <origin rpy="0 0 0" xyz="0 0 0"/>
      <geometry>
        <mesh filename="./meshes/R_wrist_pitch_link.STL"/>
      </geometry>
    </collision>
  </link>
  <joint name="R_wrist_pitch_joint" type="revolute">
    <origin rpy="0 0 0" xyz="0 0 -0.05575"/>
    <parent link="R_elbow_yaw_link"/>
    <child link="R_wrist_pitch_link"/>
    <axis xyz="0 1 0"/>
    <limit effort="6" lower="-0.68" upper="0.68" velocity="12.57"/>
  </joint>
  <link name="R_wrist_roll_link">
    <inertial>
      <origin rpy="0 0 0" xyz="0.0085537 -1.437E-05 -0.02191296"/>
      <mass value="0.04766635"/>
      <inertia ixx="2.225E-05" ixy="0" ixz="-7.71E-06" iyy="4.753E-05" iyz="0" izz="3.827E-05"/>
    </inertial>
    <visual>
      <origin rpy="0 0 0" xyz="0 0 0"/>
      <geometry>
        <mesh filename="./meshes/R_wrist_roll_link.STL"/>
      </geometry>
      <material name="">
        <color rgba="1 1 1 1"/>
      </material>
    </visual>
    <collision>
      <origin rpy="0 0 0" xyz="0 0 0"/>
      <geometry>
        <mesh filename="./meshes/R_wrist_roll_link.STL"/>
      </geometry>
    </collision>
  </link>
  <joint name="R_wrist_roll_joint" type="revolute">
    <origin rpy="0 0 0" xyz="0 0 -0.0399515014686294"/>
    <parent link="R_wrist_pitch_link"/>
    <child link="R_wrist_roll_link"/>
    <axis xyz="1 0 0"/>
    <limit effort="6" lower="-1.57" upper="1.57" velocity="12.57"/>
  </joint>
  <link
    name="R_sixforce_link">
    <inertial>
      <origin
        xyz="-0.00011076 3.22E-06 0.011338"
        rpy="0 0 0" />
      <mass
        value="0.24541" />
      <inertia
        ixx="7.52E-05"
        ixy="0"
        ixz="-2.13E-06"
        iyy="9.35E-05"
        iyz="0"
        izz="0.000106" />
    </inertial>
    <visual>
      <origin
        xyz="0 0 0"
        rpy="0 0 0" />
      <geometry>
        <mesh
          filename="R_sixforce_link.STL" />
      </geometry>
      <material
        name="">
        <color
          rgba="1 1 1 1" />
      </material>
    </visual>
    <collision>
      <origin
        xyz="0 0 0"
        rpy="0 0 0" />
      <geometry>
        <mesh
          filename="R_sixforce_link.STL" />
      </geometry>
    </collision>
  </link>
  <joint
    name="R_sixforce_joint"
    type="fixed">
    <origin
      xyz="0.0022054 -0.0019134 -0.081806"
      rpy="-0.0048735 0 0" />
    <parent
      link="R_wrist_roll_link" />
    <child
      link="R_sixforce_link" />
    <axis
      xyz="0 0 0" />
  </joint>
    <link
    name="R_hand_link">
    <inertial>
      <origin
        xyz="0.01534045 2E-06 -0.00192629"
        rpy="0 0 0" />
      <mass
        value="0.28014837" />
      <inertia
        ixx="0.0003278"
        ixy="-2E-08"
        ixz="-9.94E-06"
        iyy="0.00042842"
        iyz="0"
        izz="0.00038273" />
    </inertial>
  </link>
  <joint
    name="R_hand_joint"
    type="fixed">
    <origin
      xyz="-0.082205 -0.00086958 -0.0053662"
      rpy="0.0048735 0.0034895 1.7006E-05" />
    <parent
      link="R_sixforce_link" />
    <child
      link="R_hand_link" />
    <axis
      xyz="0 0 0" />
  </joint>
  <joint
    name="R_dexterous_hand_mount_joint"
    type="fixed">
    <origin
      xyz="0.08 0 0.05"
      rpy="3.14 0 0" />
    <parent
      link="R_hand_link" />
    <child
      link="R_hand_base_link" />
    <axis
      xyz="0 0 0" />
  </joint>
  <mujoco>
    <compiler
      meshdir="../../meshes/hand3_v1"
      balanceinertia="false"
      discardvisual="false"
      autolimits="true"
      inertiafromgeom="false"
      convexhull="false"
      boundmass="0.0001"
      usethread="true" />
  </mujoco>
  <link
    name="R_hand_base_link">
    <inertial>
      <origin
        xyz="0.00065934 -0.00064662 0.02223161"
        rpy="0 0 0" />
      <mass
        value="0.05238695" />
      <inertia
        ixx="0.00001722"
        ixy="-0.00000028"
        ixz="-0.00000043"
        iyy="0.00003682"
        iyz="0.00000022"
        izz="0.00004011" />
    </inertial>
    <visual>
      <origin
        xyz="0 0 0"
        rpy="0 0 0" />
      <geometry>
        <mesh
          filename="./meshes/hand_v3/right/R_hand_base_link.STL" />
      </geometry>
      <material
        name="">
        <color
          rgba="0.792156862745098 0.819607843137255 0.933333333333333 1" />
      </material>
    </visual>
    <collision>
      <origin
        xyz="0 0 0"
        rpy="0 0 0" />
      <geometry>
        <mesh
          filename="./meshes/hand_v3/right/R_hand_base_link.STL" />
      </geometry>
    </collision>
  </link>
  <link
    name="R_palm_link">
    <inertial>
      <origin
        xyz="-0.00938866 0.00221701 -0.0117814"
        rpy="0 0 0" />
      <mass
        value="0.38223591" />
      <inertia
        ixx="0.00022773"
        ixy="0.00000169"
        ixz="0.00000005"
        iyy="0.00035269"
        iyz="0.00001316"
        izz="0.00050349" />
    </inertial>
    <visual>
      <origin
        xyz="0 0 0"
        rpy="0 0 0" />
      <geometry>
        <mesh
          filename="./meshes/hand_v3/right/R_palm_link.STL" />
      </geometry>
      <material
        name="">
        <color
          rgba="0.752941176470588 0.752941176470588 0.752941176470588 1" />
      </material>
    </visual>
    <collision>
      <origin
        xyz="0 0 0"
        rpy="0 0 0" />
      <geometry>
        <mesh
          filename="./meshes/hand_v3/right/R_palm_link.STL" />
      </geometry>
    </collision>
  </link>
  <joint
    name="R_palm_joint"
    type="fixed">
    <origin
      xyz="0.00035702 -0.013196 0.099778"
      rpy="1.5708 -1.5708 0" />
    <parent
      link="R_hand_base_link" />
    <child
      link="R_palm_link" />
    <axis
      xyz="0 0 0" />
  </joint>
  <link
    name="R_thumb_cmp_link">
    <inertial>
      <origin
        xyz="0.00563085 0.00075 -0.00435852"
        rpy="0 0 0" />
      <mass
        value="0.01511033" />
      <inertia
        ixx="0.00000093"
        ixy="-0.00000007"
        ixz="0.0000003"
        iyy="0.00000105"
        iyz="0.00000002"
        izz="0.00000107" />
    </inertial>
    <visual>
      <origin
        xyz="0 0 0"
        rpy="0 0 0" />
      <geometry>
        <mesh
          filename="./meshes/hand_v3/right/R_thumb_cmp_link.STL" />
      </geometry>
      <material
        name="">
        <color
          rgba="0.752941176470588 0.752941176470588 0.752941176470588 1" />
      </material>
    </visual>
    <collision>
      <origin
        xyz="0 0 0"
        rpy="0 0 0" />
      <geometry>
        <mesh
          filename="./meshes/hand_v3/right/R_thumb_cmp_link.STL" />
      </geometry>
    </collision>
  </link>
  <joint
    name="R_thumb_cmp_joint"
    type="revolute">
    <origin
      xyz="-0.048578 -0.028956 -0.0073648"
      rpy="1.5708 -0.75224 -1.5708" />
    <parent
      link="R_palm_link" />
    <child
      link="R_thumb_cmp_link" />
    <axis
      xyz="0 0 1" />
    <limit
      lower="0"
      upper="0.96"
      effort="1.35"
      velocity="2.09" />
  </joint>
  <link
    name="R_thumb_mpp_link">
    <inertial>
      <origin
        xyz="0.03618423 -0.00195018 0.00007704"
        rpy="0 0 0" />
      <mass
        value="0.06741198" />
      <inertia
        ixx="0.00000637"
        ixy="-0.00000267"
        ixz="-0.00000003"
        iyy="0.00003296"
        iyz="0"
        izz="0.00003268" />
    </inertial>
    <visual>
      <origin
        xyz="0 0 0"
        rpy="0 0 0" />
      <geometry>
        <mesh
          filename="./meshes/hand_v3/right/R_thumb_mpp_link.STL" />
      </geometry>
      <material
        name="">
        <color
          rgba="0.752941176470588 0.752941176470588 0.752941176470588 1" />
      </material>
    </visual>
    <collision>
      <origin
        xyz="0 0 0"
        rpy="0 0 0" />
      <geometry>
        <mesh
          filename="./meshes/hand_v3/right/R_thumb_mpp_link.STL" />
      </geometry>
    </collision>
  </link>
  <joint
    name="R_thumb_mpp_joint"
    type="revolute">
    <origin
      xyz="0.012 0.0010557 -0.010045"
      rpy="-1.4661 -0.00015422 -1.621E-05" />
    <parent
      link="R_thumb_cmp_link" />
    <child
      link="R_thumb_mpp_link" />
    <axis
      xyz="0 0 1" />
    <limit
      lower="0"
      upper="1.04"
      effort="1.35"
      velocity="2.09" />
  </joint>
  <link
    name="R_thumb_ip_link">
    <inertial>
      <origin
        xyz="0.01353705 0.00416931 -0.00000614"
        rpy="0 0 0" />
      <mass
        value="0.01731117" />
      <inertia
        ixx="0.00000104"
        ixy="-0.00000015"
        ixz="0"
        iyy="0.00000185"
        iyz="0"
        izz="0.00000176" />
    </inertial>
    <visual>
      <origin
        xyz="0 0 0"
        rpy="0 0 0" />
      <geometry>
        <mesh
          filename="./meshes/hand_v3/right/R_thumb_ip_link.STL" />
      </geometry>
      <material
        name="">
        <color
          rgba="0.752941176470588 0.752941176470588 0.752941176470588 1" />
      </material>
    </visual>
    <collision>
      <origin
        xyz="0 0 0"
        rpy="0 0 0" />
      <geometry>
        <mesh
          filename="./meshes/hand_v3/right/R_thumb_ip_link.STL" />
      </geometry>
    </collision>
  </link>
  <joint
    name="R_thumb_ip_joint"
    type="revolute">
    <origin
      xyz="0.075 0 0"
      rpy="0 0 0.012082" />
    <parent
      link="R_thumb_mpp_link" />
    <child
      link="R_thumb_ip_link" />
    <axis
      xyz="0 0 1" />
    <limit
      lower="0"
      upper="1.05"
      effort="1.35"
      velocity="2.09" />
  </joint>
  <link
    name="R_index_mpp_link">
    <inertial>
      <origin
        xyz="0.01525314 -0.00181681 -0.00015205"
        rpy="0 0 0" />
      <mass
        value="0.01470075" />
      <inertia
        ixx="0.00000087"
        ixy="0"
        ixz="0"
        iyy="0.00000357"
        iyz="0"
        izz="0.00000352" />
    </inertial>
    <visual>
      <origin
        xyz="0 0 0"
        rpy="0 0 0" />
      <geometry>
        <mesh
          filename="./meshes/hand_v3/right/R_index_mpp_link.STL" />
      </geometry>
      <material
        name="">
        <color
          rgba="0.752941176470588 0.752941176470588 0.752941176470588 1" />
      </material>
    </visual>
    <collision>
      <origin
        xyz="0 0 0"
        rpy="0 0 0" />
      <geometry>
        <mesh
          filename="./meshes/hand_v3/right/R_index_mpp_link.STL" />
      </geometry>
    </collision>
  </link>
  <joint
    name="R_index_mpp_joint"
    type="revolute">
    <origin
      xyz="0.041818 -0.03077 -0.011696"
      rpy="1.5708 -0.18118 -0.020071" />
    <parent
      link="R_palm_link" />
    <child
      link="R_index_mpp_link" />
    <axis
      xyz="0 0 1" />
    <limit
      lower="0"
      upper="1.46"
      effort="1.35"
      velocity="2.09" />
  </joint>
  <link
    name="R_index_ip_link">
    <inertial>
      <origin
        xyz="0.01680857 -0.00117535 0"
        rpy="0 0 0" />
      <mass
        value="0.01334933" />
      <inertia
        ixx="0.00000042"
        ixy="-0.00000029"
        ixz="0"
        iyy="0.00000262"
        iyz="0"
        izz="0.00000261" />
    </inertial>
    <visual>
      <origin
        xyz="0 0 0"
        rpy="0 0 0" />
      <geometry>
        <mesh
          filename="./meshes/hand_v3/right/R_index_ip_link.STL" />
      </geometry>
      <material
        name="">
        <color
          rgba="0.752941176470588 0.752941176470588 0.752941176470588 1" />
      </material>
    </visual>
    <collision>
      <origin
        xyz="0 0 0"
        rpy="0 0 0" />
      <geometry>
        <mesh
          filename="./meshes/hand_v3/right/R_index_ip_link.STL" />
      </geometry>
    </collision>
  </link>
  <joint
    name="R_index_ip_joint"
    type="revolute">
    <origin
      xyz="0.0388 0 0"
      rpy="0 0 -0.014509" />
    <parent
      link="R_index_mpp_link" />
    <child
      link="R_index_ip_link" />
    <axis
      xyz="0 0 1" />
    <limit
      lower="0"
      upper="1.62"
      effort="1.35"
      velocity="2.09" />
  </joint>
  <link
    name="R_middle_mpp_link">
    <inertial>
      <origin
        xyz="0.01476009 -0.00171481 -0.00012869"
        rpy="0 0 0" />
      <mass
        value="0.01430214" />
      <inertia
        ixx="0.00000086"
        ixy="-0.00000003"
        ixz="0"
        iyy="0.00000344"
        iyz="0"
        izz="0.00000339" />
    </inertial>
    <visual>
      <origin
        xyz="0 0 0"
        rpy="0 0 0" />
      <geometry>
        <mesh
          filename="./meshes/hand_v3/right/R_middle_mpp_link.STL" />
      </geometry>
      <material
        name="">
        <color
          rgba="0.752941176470588 0.752941176470588 0.752941176470588 1" />
      </material>
    </visual>
    <collision>
      <origin
        xyz="0 0 0"
        rpy="0 0 0" />
      <geometry>
        <mesh
          filename="./meshes/hand_v3/right/R_middle_mpp_link.STL" />
      </geometry>
    </collision>
  </link>
  <joint
    name="R_middle_mpp_joint"
    type="revolute">
    <origin
      xyz="0.042022 -0.011107 -0.011696"
      rpy="1.5673 -0.18114 0.019678" />
    <parent
      link="R_palm_link" />
    <child
      link="R_middle_mpp_link" />
    <axis
      xyz="0 0 1" />
    <limit
      lower="0"
      upper="1.46"
      effort="1.35"
      velocity="2.09" />
  </joint>
  <link
    name="R_middle_ip_link">
    <inertial>
      <origin
        xyz="0.01771317 -0.00109666 -0.0000256"
        rpy="0 0 0" />
      <mass
        value="0.0148881" />
      <inertia
        ixx="0.00000047"
        ixy="-0.00000038"
        ixz="0"
        iyy="0.00000344"
        iyz="0"
        izz="0.00000344" />
    </inertial>
    <visual>
      <origin
        xyz="0 0 0"
        rpy="0 0 0" />
      <geometry>
        <mesh
          filename="./meshes/hand_v3/right/R_middle_ip_link.STL" />
      </geometry>
      <material
        name="">
        <color
          rgba="0.752941176470588 0.752941176470588 0.752941176470588 1" />
      </material>
    </visual>
    <collision>
      <origin
        xyz="0 0 0"
        rpy="0 0 0" />
      <geometry>
        <mesh
          filename="./meshes/hand_v3/right/R_middle_ip_link.STL" />
      </geometry>
    </collision>
  </link>
  <joint
    name="R_middle_ip_joint"
    type="revolute">
    <origin
      xyz="0.038807 0 0"
      rpy="0.00023357 -0.019354 -0.012068" />
    <parent
      link="R_middle_mpp_link" />
    <child
      link="R_middle_ip_link" />
    <axis
      xyz="0 0 1" />
    <limit
      lower="0"
      upper="1.62"
      effort="1.35"
      velocity="2.09" />
  </joint>
  <link
    name="R_ring_mpp_link">
    <inertial>
      <origin
        xyz="0.01475954 -0.00171495 -0.00012869"
        rpy="0 0 0" />
      <mass
        value="0.01430214" />
      <inertia
        ixx="0.00000086"
        ixy="-0.00000003"
        ixz="0"
        iyy="0.00000344"
        iyz="0"
        izz="0.00000339" />
    </inertial>
    <visual>
      <origin
        xyz="0 0 0"
        rpy="0 0 0" />
      <geometry>
        <mesh
          filename="./meshes/hand_v3/right/R_ring_mpp_link.STL" />
      </geometry>
      <material
        name="">
        <color
          rgba="0.752941176470588 0.752941176470588 0.752941176470588 1" />
      </material>
    </visual>
    <collision>
      <origin
        xyz="0 0 0"
        rpy="0 0 0" />
      <geometry>
        <mesh
          filename="./meshes/hand_v3/right/R_ring_mpp_link.STL" />
      </geometry>
    </collision>
  </link>
  <joint
    name="R_ring_mpp_joint"
    type="revolute">
    <origin
      xyz="0.041818 0.010057 -0.011696"
      rpy="1.5708 -0.18118 0.020071" />
    <parent
      link="R_palm_link" />
    <child
      link="R_ring_mpp_link" />
    <axis
      xyz="0 0 1" />
    <limit
      lower="0"
      upper="1.46"
      effort="1.35"
      velocity="2.09" />
  </joint>
  <link
    name="R_ring_ip_link">
    <inertial>
      <origin
        xyz="0.01615432 -0.00130235 -0.00002763"
        rpy="0 0 0" />
      <mass
        value="0.01374794" />
      <inertia
        ixx="0.00000043"
        ixy="-0.00000033"
        ixz="0"
        iyy="0.00000282"
        iyz="0"
        izz="0.00000281" />
    </inertial>
    <visual>
      <origin
        xyz="0 0 0"
        rpy="0 0 0" />
      <geometry>
        <mesh
          filename="./meshes/hand_v3/right/R_ring_ip_link.STL" />
      </geometry>
      <material
        name="">
        <color
          rgba="0.752941176470588 0.752941176470588 0.752941176470588 1" />
      </material>
    </visual>
    <collision>
      <origin
        xyz="0 0 0"
        rpy="0 0 0" />
      <geometry>
        <mesh
          filename="./meshes/hand_v3/right/R_ring_ip_link.STL" />
      </geometry>
    </collision>
  </link>
  <joint
    name="R_ring_ip_joint"
    type="revolute">
    <origin
      xyz="0.0388 0 0"
      rpy="0 0 -0.014509" />
    <parent
      link="R_ring_mpp_link" />
    <child
      link="R_ring_ip_link" />
    <axis
      xyz="0 0 1" />
    <limit
      lower="0"
      upper="1.62"
      effort="1.35"
      velocity="2.09" />
  </joint>
  <link
    name="R_little_mpp_link">
    <inertial>
      <origin
        xyz="0.0147588 -0.00171514 -0.00012869"
        rpy="0 0 0" />
      <mass
        value="0.01430214" />
      <inertia
        ixx="0.00000086"
        ixy="-0.00000003"
        ixz="0"
        iyy="0.00000344"
        iyz="0"
        izz="0.00000339" />
    </inertial>
    <visual>
      <origin
        xyz="0 0 0"
        rpy="0 0 0" />
      <geometry>
        <mesh
          filename="./meshes/hand_v3/right/R_little_mpp_link.STL" />
      </geometry>
      <material
        name="">
        <color
          rgba="0.752941176470588 0.752941176470588 0.752941176470588 1" />
      </material>
    </visual>
    <collision>
      <origin
        xyz="0 0 0"
        rpy="0 0 0" />
      <geometry>
        <mesh
          filename="./meshes/hand_v3/right/R_little_mpp_link.STL" />
      </geometry>
    </collision>
  </link>
  <joint
    name="R_little_mpp_joint"
    type="revolute">
    <origin
      xyz="0.041203 0.030462 -0.011696"
      rpy="1.5708 -0.18118 0.040143" />
    <parent
      link="R_palm_link" />
    <child
      link="R_little_mpp_link" />
    <axis
      xyz="0 0 1" />
    <limit
      lower="0"
      upper="1.46"
      effort="1.35"
      velocity="2.09" />
  </joint>
  <link
    name="R_little_ip_link">
    <inertial>
      <origin
        xyz="0.01303327 -0.00143438 -0.0000295"
        rpy="0 0 0" />
      <mass
        value="0.01179268" />
      <inertia
        ixx="0.00000034"
        ixy="-0.00000023"
        ixz="0"
        iyy="0.00000179"
        iyz="0"
        izz="0.00000178" />
    </inertial>
    <visual>
      <origin
        xyz="0 0 0"
        rpy="0 0 0" />
      <geometry>
        <mesh
          filename="./meshes/hand_v3/right/R_little_ip_link.STL" />
      </geometry>
      <material
        name="">
        <color
          rgba="0.752941176470588 0.752941176470588 0.752941176470588 1" />
      </material>
    </visual>
    <collision>
      <origin
        xyz="0 0 0"
        rpy="0 0 0" />
      <geometry>
        <mesh
          filename="./meshes/hand_v3/right/R_little_ip_link.STL" />
      </geometry>
    </collision>
  </link>
  <joint
    name="R_little_ip_joint"
    type="revolute">
    <origin
      xyz="0.0388 0 0"
      rpy="0 0 -0.014509" />
    <parent
      link="R_little_mpp_link" />
    <child
      link="R_little_ip_link" />
    <axis
      xyz="0 0 1" />
    <limit
      lower="0"
      upper="1.62"
      effort="1.35"
      velocity="2.09" />
  </joint>
  <link name="head_base_link">
    <inertial>
      <origin rpy="0 0 0" xyz="0 0 0"/>
      <mass value="0.0001"/>
      <inertia ixx="1e-10" ixy="0" ixz="0" iyy="1e-10" iyz="0" izz="1e-10"/>
    </inertial>
  </link>
  <joint name="head_base_joint" type="fixed">
    <origin rpy="0 0 0" xyz="0.0 0 0.09527110107"/>
    <parent link="torso_link"/>
    <child link="head_base_link"/>
    <axis xyz="0 0 1"/>
  </joint>
  <link name="head_yaw_link">
    <inertial>
      <origin rpy="0 0 0" xyz="-0.00204647 0.00017996 -0.0311295"/>
      <mass value="0.24151544"/>
      <inertia ixx="0.00010433" ixy="2.2E-07" ixz="1.04E-06" iyy="9.811E-05" iyz="-8E-07" izz="8.868E-05"/>
    </inertial>
    <visual>
      <origin rpy="0 0 0" xyz="0 0 0"/>
      <geometry>
        <mesh filename="./meshes/head_yaw_link.STL"/>
      </geometry>
      <material name="">
        <color rgba="1 0.674509803921569 0.309803921568627 1"/>
      </material>
    </visual>
    <collision>
      <origin rpy="0 0 0" xyz="0 0 0"/>
      <geometry>
        <mesh filename="./meshes/head_yaw_link.STL"/>
      </geometry>
    </collision>
  </link>
  <joint name="head_yaw_joint" type="revolute">
    <origin rpy="0 0 0" xyz="0 0 0"/>
    <parent link="head_base_link"/>
    <child link="head_yaw_link"/>
    <axis xyz="0 0 1"/>
    <limit effort="4.5" lower="-1.658" upper="1.658" velocity="5.24"/>
  </joint>
  <link name="head_pitch_link">
    <inertial>
      <origin rpy="0 0 0" xyz="0.02647525 0.00053943 0.05930006"/>
      <mass value="1.13856043"/>
      <inertia ixx="0.00517136" ixy="1.895E-05" ixz="-0.00081881" iyy="0.00598944" iyz="4.349E-05" izz="0.00326749"/>
    </inertial>
    <visual>
      <origin rpy="0 0 0" xyz="0 0 0"/>
      <geometry>
        <mesh filename="./meshes/head_pitch_link.STL"/>
      </geometry>
      <material name="">
        <color rgba="0.698039215686274 0.698039215686274 0.698039215686274 1"/>
      </material>
    </visual>
    <collision>
      <origin rpy="0 0 0" xyz="0 0 0"/>
      <geometry>
        <mesh filename="./meshes/head_pitch_link.STL"/>
      </geometry>
    </collision>
  </link>
  <joint name="head_pitch_joint" type="revolute">
    <origin rpy="0 0 0" xyz="0 0 0.0264999999999996"/>
    <parent link="head_yaw_link"/>
    <child link="head_pitch_link"/>
    <axis xyz="0 1 0"/>
    <limit effort="4.5" lower="-0.523" upper="0.785" velocity="5.24"/>
  </joint>
  <joint name="body_imu_joint" type="fixed">
    <origin rpy="0.0 0.0 -1.5707963267948966" xyz="0.0 0.0 0.0"/>
    <parent link="base_link"/>
    <child link="body_imu"/>
  </joint>
  <link name="body_imu">
    <inertial>
      <mass value="0.0001"/>
      <origin rpy="0 0 0" xyz="0 0 0"/>
      <inertia ixx="1e-10" ixy="0" ixz="0" iyy="1e-10" iyz="0" izz="1e-10"/>
    </inertial>
    <visual>
      <origin rpy="0 0 0" xyz="0 0 0"/>
      <geometry>
        <box size="0.015 0.015 0.004"/>
      </geometry>
    </visual>
    <material name="orange">
      <color rgba="255 108 10 255"/>
    </material>
  </link>
  <!-- for urdf2mojuco parse -->
  <imu_sensor name="body_imu">
    <parent link="base_link"/>
    <origin rpy="0.0 0.0 -1.5707963267948966" xyz="0.0 0.0 0.0"/>
  </imu_sensor>
  <joint name="head_imu_joint" type="fixed">
    <origin rpy="0.0 0.0 -1.5707963267948966" xyz="0.0 0.0 0.0"/>
    <parent link="head_pitch_link"/>
    <child link="head_imu"/>
  </joint>
  <link name="head_imu">
    <inertial>
      <mass value="0.0001"/>
      <origin rpy="0 0 0" xyz="0 0 0"/>
      <inertia ixx="1e-10" ixy="0" ixz="0" iyy="1e-10" iyz="0" izz="1e-10"/>
    </inertial>
    <visual>
      <origin rpy="0 0 0" xyz="0 0 0"/>
      <geometry>
        <box size="0.015 0.015 0.004"/>
      </geometry>
    </visual>
    <material name="orange">
      <color rgba="255 108 10 255"/>
    </material>
  </link>
  <!-- for urdf2mojuco parse -->
  <imu_sensor name="head_imu">
    <parent link="head_pitch_link"/>
    <origin rpy="0.0 0.0 -1.5707963267948966" xyz="0.0 0.0 0.0"/>
  </imu_sensor>
  <!-- for simulation -->
  <gps_sensor name="body_gps">
    <parent link="base_link"/>
    <origin rpy="0.0 0.0 0.0" xyz="0.0 0.0 0.0"/>
  </gps_sensor>
</robot>
