<?xml version='1.0' encoding='utf-8'?>
<robot name="walker_c1_right_arm">
  <link name="base_link">
    <inertial>
      <origin rpy="0 0 0" xyz="-0.00060742 0 -0.00390464" />
      <mass value="5.32923152" />
      <inertia ixx="0.02561815" ixy="3.016E-05" ixz="-1.012E-05" iyy="0.01751097" iyz="-2.5E-07" izz="0.02397466" />
    </inertial>
  </link>
  <link name="waist_yaw_link">
    <inertial>
      <origin rpy="0 0 0" xyz="0.00270178 -0.00088235 0.03695265" />
      <mass value="2.06130216" />
      <inertia ixx="0.00455692" ixy="2.339E-05" ixz="-0.0004179" iyy="0.00399271" iyz="9.219E-05" izz="0.00564475" />
    </inertial>
  </link>
  <link name="waist_pitch_link">
    <inertial>
      <origin rpy="0 0 0" xyz="-0.00141152 -0.00378014 -1.015E-05" />
      <mass value="1.56616016" />
      <inertia ixx="0.00193458" ixy="4.94E-06" ixz="-2.31E-06" iyy="0.00149086" iyz="1.11E-06" izz="0.0020082" />
    </inertial>
  </link>
  <link name="waist_roll_link">
    <inertial>
      <origin rpy="0 0 0" xyz="-0.0023246 0.00010908 0.15067891" />
      <mass value="13.34004282" />
      <inertia ixx="0.14820786" ixy="-0.0001414" ixz="-0.00914777" iyy="0.12699244" iyz="0.00012313" izz="0.07921235" />
    </inertial>
  </link>
  <link name="torso_link">
    <inertial>
      <origin rpy="0 0 0" xyz="0 0 0" />
      <mass value="0.0001" />
      <inertia ixx="1e-10" ixy="0" ixz="0" iyy="1e-10" iyz="0" izz="1e-10" />
    </inertial>
  </link>
  <link name="R_arm_base_link">
    <inertial>
      <origin rpy="0 0 0" xyz="0 0 0" />
      <mass value="0.0001" />
      <inertia ixx="1e-10" ixy="0" ixz="0" iyy="1e-10" iyz="0" izz="1e-10" />
    </inertial>
  </link>
  <link name="R_shoulder_pitch_link">
    <inertial>
      <origin rpy="0 0 0" xyz="0.00384148 -0.046973 7.92E-06" />
      <mass value="0.79994046" />
      <inertia ixx="0.00053607" ixy="6.43E-06" ixz="-2.4E-07" iyy="0.00048679" iyz="-5.14E-06" izz="0.00056359" />
    </inertial>
  </link>
  <link name="R_shoulder_roll_link">
    <inertial>
      <origin rpy="0 0 0" xyz="0.00374986 -0.00090026 -0.08145595" />
      <mass value="0.95418329" />
      <inertia ixx="0.00164607" ixy="-7.42E-06" ixz="-0.00024807" iyy="0.00173406" iyz="6.443E-05" izz="0.00083829" />
    </inertial>
  </link>
  <link name="R_shoulder_yaw_link">
    <inertial>
      <origin rpy="0 0 0" xyz="-0.00111484 -0.00508263 -0.07767727" />
      <mass value="0.95271279" />
      <inertia ixx="0.00135945" ixy="2.71E-06" ixz="2.018E-05" iyy="0.00137161" iyz="-6.206E-05" izz="0.00063937" />
    </inertial>
  </link>
  <link name="R_elbow_pitch_link">
    <inertial>
      <origin rpy="0 0 0" xyz="-0.00109585 -0.00301164 -0.08162983" />
      <mass value="0.91030288" />
      <inertia ixx="0.00150011" ixy="-7.5E-07" ixz="6.414E-05" iyy="0.00142992" iyz="0.00019571" izz="0.00073744" />
    </inertial>
  </link>
  <link name="R_elbow_yaw_link">
    <inertial>
      <origin rpy="0 0 0" xyz="0.00042308 0.00819376 -0.0202823" />
      <mass value="0.09164929" />
      <inertia ixx="8.047E-05" ixy="1.4E-07" ixz="6.8E-07" iyy="6.686E-05" iyz="1.222E-05" izz="7.851E-05" />
    </inertial>
  </link>
  <link name="R_wrist_pitch_link">
    <inertial>
      <origin rpy="0 0 0" xyz="0.00244378 0.00252389 -0.01940281" />
      <mass value="0.49823595" />
      <inertia ixx="0.00032853" ixy="3.17E-06" ixz="2.818E-05" iyy="0.00033198" iyz="-2.391E-05" izz="0.00017354" />
    </inertial>
  </link>
  <link name="R_wrist_roll_link">
    <inertial>
      <origin rpy="0 0 0" xyz="0.0085537 -1.437E-05 -0.02191296" />
      <mass value="0.04766635" />
      <inertia ixx="2.225E-05" ixy="0" ixz="-7.71E-06" iyy="4.753E-05" iyz="0" izz="3.827E-05" />
    </inertial>
  </link>
  <link name="R_sixforce_link">
    <inertial>
      <origin xyz="-0.00011076 3.22E-06 0.011338" rpy="0 0 0" />
      <mass value="0.24541" />
      <inertia ixx="7.52E-05" ixy="0" ixz="-2.13E-06" iyy="9.35E-05" iyz="0" izz="0.000106" />
    </inertial>
  </link>
  <link name="R_hand_link">
    <inertial>
      <origin xyz="0.01534045 2E-06 -0.00192629" rpy="0 0 0" />
      <mass value="0.28014837" />
      <inertia ixx="0.0003278" ixy="-2E-08" ixz="-9.94E-06" iyy="0.00042842" iyz="0" izz="0.00038273" />
    </inertial>
  </link>
  <link name="R_hand_base_link">
    <inertial>
      <origin xyz="0.00065934 -0.00064662 0.02223161" rpy="0 0 0" />
      <mass value="0.05238695" />
      <inertia ixx="0.00001722" ixy="-0.00000028" ixz="-0.00000043" iyy="0.00003682" iyz="0.00000022" izz="0.00004011" />
    </inertial>
  </link>
  <link name="R_palm_link">
    <inertial>
      <origin xyz="-0.00938866 0.00221701 -0.0117814" rpy="0 0 0" />
      <mass value="0.38223591" />
      <inertia ixx="0.00022773" ixy="0.00000169" ixz="0.00000005" iyy="0.00035269" iyz="0.00001316" izz="0.00050349" />
    </inertial>
  </link>
  <joint name="waist_yaw_joint" type="revolute">
    <origin rpy="0.0 0.0 0.0" xyz="0 0 0.0766405733000631" />
    <parent link="base_link" />
    <child link="waist_yaw_link" />
    <axis xyz="0 0 1" />
    <limit effort="63" lower="-2.792" upper="2.792" velocity="10.47" />
  </joint>
  <joint name="waist_pitch_joint" type="revolute">
    <origin rpy="0 0 0" xyz="0.0399999999999999 0 0.1155" />
    <parent link="waist_yaw_link" />
    <child link="waist_pitch_link" />
    <axis xyz="0 1 0" />
    <limit effort="165" lower="-0.017" upper="1.221" velocity="8.9" />
  </joint>
  <joint name="waist_roll_joint" type="revolute">
    <origin rpy="0 0 0" xyz="-0.0515000000005501 0 0" />
    <parent link="waist_pitch_link" />
    <child link="waist_roll_link" />
    <axis xyz="1 0 0" />
    <limit effort="110" lower="-0.75" upper="0.75" velocity="10.47" />
  </joint>
  <joint name="torso_waist_joint" type="fixed">
    <origin rpy="0 0 0" xyz="0.0115000000000002 0 0.247778898928156" />
    <parent link="waist_roll_link" />
    <child link="torso_link" />
    <axis xyz="0 0 1" />
  </joint>
  <joint name="R_arm_base_joint" type="fixed">
    <origin rpy="-0.174532925199405 0 0" xyz="0.0 -0.114809942431709 0.0" />
    <parent link="torso_link" />
    <child link="R_arm_base_link" />
    <axis xyz="0 0 1" />
  </joint>
  <joint name="R_shoulder_pitch_joint" type="revolute">
    <origin rpy="0 0 0" xyz="0 0 0" />
    <parent link="R_arm_base_link" />
    <child link="R_shoulder_pitch_link" />
    <axis xyz="0 1 0" />
    <limit effort="60" lower="-3.089" upper="2.565" velocity="13.61" />
  </joint>
  <joint name="R_shoulder_roll_joint" type="revolute">
    <origin rpy="0 0 0" xyz="0 -0.0499 0" />
    <parent link="R_shoulder_pitch_link" />
    <child link="R_shoulder_roll_link" />
    <axis xyz="1 0 0" />
    <limit effort="60" lower="-1.884" upper="0.139" velocity="13.61" />
  </joint>
  <joint name="R_shoulder_yaw_joint" type="revolute">
    <origin rpy="0 0 0" xyz="0 0 -0.126750000099661" />
    <parent link="R_shoulder_roll_link" />
    <child link="R_shoulder_yaw_link" />
    <axis xyz="0 0 1" />
    <limit effort="25" lower="-2.844" upper="2.844" velocity="13.61" />
  </joint>
  <joint name="R_elbow_pitch_joint" type="revolute">
    <origin rpy="0 0 0" xyz="0 0 -0.0932499981849196" />
    <parent link="R_shoulder_yaw_link" />
    <child link="R_elbow_pitch_link" />
    <axis xyz="0 1 0" />
    <limit effort="25" lower="-2.2689" upper="0.104" velocity="13.61" />
  </joint>
  <joint name="R_elbow_yaw_joint" type="revolute">
    <origin rpy="0 0 0" xyz="0 0 -0.124250001797163" />
    <parent link="R_elbow_pitch_link" />
    <child link="R_elbow_yaw_link" />
    <axis xyz="0 0 1" />
    <limit effort="25" lower="-2.844" upper="2.844" velocity="13.61" />
  </joint>
  <joint name="R_wrist_pitch_joint" type="revolute">
    <origin rpy="0 0 0" xyz="0 0 -0.05575" />
    <parent link="R_elbow_yaw_link" />
    <child link="R_wrist_pitch_link" />
    <axis xyz="0 1 0" />
    <limit effort="6" lower="-0.68" upper="0.68" velocity="12.57" />
  </joint>
  <joint name="R_wrist_roll_joint" type="revolute">
    <origin rpy="0 0 0" xyz="0 0 -0.0399515014686294" />
    <parent link="R_wrist_pitch_link" />
    <child link="R_wrist_roll_link" />
    <axis xyz="1 0 0" />
    <limit effort="6" lower="-1.57" upper="1.57" velocity="12.57" />
  </joint>
  <joint name="R_sixforce_joint" type="fixed">
    <origin xyz="0.0022054 -0.0019134 -0.081806" rpy="-0.0048735 0 0" />
    <parent link="R_wrist_roll_link" />
    <child link="R_sixforce_link" />
    <axis xyz="0 0 0" />
  </joint>
  <joint name="R_hand_joint" type="fixed">
    <origin xyz="-0.082205 -0.00086958 -0.0053662" rpy="0.0048735 0.0034895 1.7006E-05" />
    <parent link="R_sixforce_link" />
    <child link="R_hand_link" />
    <axis xyz="0 0 0" />
  </joint>
  <joint name="R_dexterous_hand_mount_joint" type="fixed">
    <origin xyz="0.08 0 0.05" rpy="3.14 0 0" />
    <parent link="R_hand_link" />
    <child link="R_hand_base_link" />
    <axis xyz="0 0 0" />
  </joint>
  <joint name="R_palm_joint" type="fixed">
    <origin xyz="0.00035702 -0.013196 0.099778" rpy="1.5708 -1.5708 0" />
    <parent link="R_hand_base_link" />
    <child link="R_palm_link" />
    <axis xyz="0 0 0" />
  </joint>
</robot>