<?xml version="1.0" encoding="utf-8"?>
<!-- This URDF was automatically created by SolidWorks to URDF Exporter! Originally created by Stephen Brawner (brawner@gmail.com) 
     Commit Version: 1.6.0-4-g7f85cfe  Build Version: 1.6.7995.38578
     For more information, please see http://wiki.ros.org/sw_urdf_exporter -->
<robot
  name="hand3_v1">
  <mujoco>
    <compiler
      meshdir="../../meshes/hand3_v1"
      balanceinertia="false"
      discardvisual="false"
      autolimits="true"
      inertiafromgeom="false"
      convexhull="false"
      boundmass="0.0001"
      usethread="true" />
  </mujoco>
  <link
    name="L_hand_base_link">
    <inertial>
      <origin
        xyz="0.00065934 0.00064662 0.02223161"
        rpy="0 0 0" />
      <mass
        value="0.05238695" />
      <inertia
        ixx="0.00001722"
        ixy="0.00000028"
        ixz="-0.00000043"
        iyy="0.00003682"
        iyz="-0.00000022"
        izz="0.00004011" />
    </inertial>
    <visual>
      <origin
        xyz="0 0 0"
        rpy="0 0 0" />
      <geometry>
        <mesh
          filename="package://ubt_left_hand_v3_description/meshes/hand3_v1/L_hand_base_link.STL" />
      </geometry>
      <material
        name="">
        <color
          rgba="0.792156862745098 0.819607843137255 0.933333333333333 1" />
      </material>
    </visual>
    <collision>
      <origin
        xyz="0 0 0"
        rpy="0 0 0" />
      <geometry>
        <mesh
          filename="package://ubt_left_hand_v3_description/meshes/hand3_v1/L_hand_base_link.STL" />
      </geometry>
    </collision>
  </link>
  <link
    name="L_palm_link">
    <inertial>
      <origin
        xyz="-0.00938866 -0.00221701 -0.0117814"
        rpy="0 0 0" />
      <mass
        value="0.38223591" />
      <inertia
        ixx="0.00022773"
        ixy="-0.00000169"
        ixz="0.00000005"
        iyy="0.00035269"
        iyz="-0.00001316"
        izz="0.00050349" />
    </inertial>
    <visual>
      <origin
        xyz="0 0 0"
        rpy="0 0 0" />
      <geometry>
        <mesh
          filename="package://ubt_left_hand_v3_description/meshes/hand3_v1/L_palm_link.STL" />
      </geometry>
      <material
        name="">
        <color
          rgba="1 1 1 1" />
      </material>
    </visual>
    <collision>
      <origin
        xyz="0 0 0"
        rpy="0 0 0" />
      <geometry>
        <mesh
          filename="package://ubt_left_hand_v3_description/meshes/hand3_v1/L_palm_link.STL" />
      </geometry>
    </collision>
  </link>
  <joint
    name="L_palm_joint"
    type="fixed">
    <origin
      xyz="0.00035572 -0.013196 0.099778"
      rpy="1.5708 -1.5708 0" />
    <parent
      link="L_hand_base_link" />
    <child
      link="L_palm_link" />
    <axis
      xyz="0 0 0" />
    <limit
      lower="0"
      upper="0"
      effort="0"
      velocity="0" />
  </joint>
  <link
    name="L_thumb_cmp_link">
    <inertial>
      <origin
        xyz="0.00563085 -0.00075 -0.00435852"
        rpy="0 0 0" />
      <mass
        value="0.01511033" />
      <inertia
        ixx="0.00000093"
        ixy="0.00000007"
        ixz="0.0000003"
        iyy="0.00000105"
        iyz="-0.00000002"
        izz="0.00000107" />
    </inertial>
    <visual>
      <origin
        xyz="0 0 0"
        rpy="0 0 0" />
      <geometry>
        <mesh
          filename="package://ubt_left_hand_v3_description/meshes/hand3_v1/L_thumb_cmp_link.STL" />
      </geometry>
      <material
        name="">
        <color
          rgba="0.752941176470588 0.752941176470588 0.752941176470588 1" />
      </material>
    </visual>
    <collision>
      <origin
        xyz="0 0 0"
        rpy="0 0 0" />
      <geometry>
        <mesh
          filename="package://ubt_left_hand_v3_description/meshes/hand3_v1/L_thumb_cmp_link.STL" />
      </geometry>
    </collision>
  </link>
  <joint
    name="L_thumb_cmp_joint"
    type="revolute">
    <origin
      xyz="-0.048578 0.028956 -0.0073648"
      rpy="-1.5708 -0.75224 1.5708" />
    <parent
      link="L_palm_link" />
    <child
      link="L_thumb_cmp_link" />
    <axis
      xyz="0 0 1" />
    <limit
      lower="-0.96"
      upper="0"
      effort="1.35"
      velocity="2.09" />
  </joint>
  <link
    name="L_thumb_mpp_link">
    <inertial>
      <origin
        xyz="0.03618423 -0.00195018 -0.00007704"
        rpy="0 0 0" />
      <mass
        value="0.06741198" />
      <inertia
        ixx="0.00000637"
        ixy="-0.00000267"
        ixz="0.00000003"
        iyy="0.00003296"
        iyz="0"
        izz="0.00003268" />
    </inertial>
    <visual>
      <origin
        xyz="0 0 0"
        rpy="0 0 0" />
      <geometry>
        <mesh
          filename="package://ubt_left_hand_v3_description/meshes/hand3_v1/L_thumb_mpp_link.STL" />
      </geometry>
      <material
        name="">
        <color
          rgba="0.752941176470588 0.752941176470588 0.752941176470588 1" />
      </material>
    </visual>
    <collision>
      <origin
        xyz="0 0 0"
        rpy="0 0 0" />
      <geometry>
        <mesh
          filename="package://ubt_left_hand_v3_description/meshes/hand3_v1/L_thumb_mpp_link.STL" />
      </geometry>
    </collision>
  </link>
  <joint
    name="L_thumb_mpp_joint"
    type="revolute">
    <origin
      xyz="0.012 -0.0010557 -0.010045"
      rpy="-1.6755 0 0" />
    <parent
      link="L_thumb_cmp_link" />
    <child
      link="L_thumb_mpp_link" />
    <axis
      xyz="0 0 1" />
    <limit
      lower="0"
      upper="1.04"
      effort="1.35"
      velocity="2.09" />
  </joint>
  <link
    name="L_thumb_ip_link">
    <inertial>
      <origin
        xyz="0.01353705 0.00416931 0.00000614"
        rpy="0 0 0" />
      <mass
        value="0.01731117" />
      <inertia
        ixx="0.00000104"
        ixy="-0.00000015"
        ixz="0"
        iyy="0.00000185"
        iyz="0"
        izz="0.00000176" />
    </inertial>
    <visual>
      <origin
        xyz="0 0 0"
        rpy="0 0 0" />
      <geometry>
        <mesh
          filename="package://ubt_left_hand_v3_description/meshes/hand3_v1/L_thumb_ip_link.STL" />
      </geometry>
      <material
        name="">
        <color
          rgba="0.752941176470588 0.752941176470588 0.752941176470588 1" />
      </material>
    </visual>
    <collision>
      <origin
        xyz="0 0 0"
        rpy="0 0 0" />
      <geometry>
        <mesh
          filename="package://ubt_left_hand_v3_description/meshes/hand3_v1/L_thumb_ip_link.STL" />
      </geometry>
    </collision>
  </link>
  <joint
    name="L_thumb_ip_joint"
    type="revolute">
    <origin
      xyz="0.075 -1.163E-05 0"
      rpy="0 0 0" />
    <parent
      link="L_thumb_mpp_link" />
    <child
      link="L_thumb_ip_link" />
    <axis
      xyz="0 0 1" />
    <limit
      lower="0"
      upper="1.05"
      effort="1.35"
      velocity="2.09" />
  </joint>
  <link
    name="L_index_mpp_link">
    <inertial>
      <origin
        xyz="0.01525314 -0.00181681 0.00015205"
        rpy="0 0 0" />
      <mass
        value="0.01470075" />
      <inertia
        ixx="0.00000087"
        ixy="0"
        ixz="0"
        iyy="0.00000357"
        iyz="0"
        izz="0.00000352" />
    </inertial>
    <visual>
      <origin
        xyz="0 0 0"
        rpy="0 0 0" />
      <geometry>
        <mesh
          filename="package://ubt_left_hand_v3_description/meshes/hand3_v1/L_index_mpp_link.STL" />
      </geometry>
      <material
        name="">
        <color
          rgba="0.752941176470588 0.752941176470588 0.752941176470588 1" />
      </material>
    </visual>
    <collision>
      <origin
        xyz="0 0 0"
        rpy="0 0 0" />
      <geometry>
        <mesh
          filename="package://ubt_left_hand_v3_description/meshes/hand3_v1/L_index_mpp_link.STL" />
      </geometry>
    </collision>
  </link>
  <joint
    name="L_index_mpp_joint"
    type="revolute">
    <origin
      xyz="0.041817 0.030769 -0.011696"
      rpy="1.5708 -0.18118 0.020071" />
    <parent
      link="L_palm_link" />
    <child
      link="L_index_mpp_link" />
    <axis
      xyz="0 0 1" />
    <limit
      lower="0"
      upper="1.46"
      effort="1.35"
      velocity="2.09" />
  </joint>
  <link
    name="L_index_ip_link">
    <inertial>
      <origin
        xyz="0.01680857 -0.00117535 0"
        rpy="0 0 0" />
      <mass
        value="0.01334933" />
      <inertia
        ixx="0.00000042"
        ixy="-0.00000029"
        ixz="0"
        iyy="0.00000262"
        iyz="0"
        izz="0.00000261" />
    </inertial>
    <visual>
      <origin
        xyz="0 0 0"
        rpy="0 0 0" />
      <geometry>
        <mesh
          filename="package://ubt_left_hand_v3_description/meshes/hand3_v1/L_index_ip_link.STL" />
      </geometry>
      <material
        name="">
        <color
          rgba="0.752941176470588 0.752941176470588 0.752941176470588 1" />
      </material>
    </visual>
    <collision>
      <origin
        xyz="0 0 0"
        rpy="0 0 0" />
      <geometry>
        <mesh
          filename="package://ubt_left_hand_v3_description/meshes/hand3_v1/L_index_ip_link.STL" />
      </geometry>
    </collision>
  </link>
  <joint
    name="L_index_ip_joint"
    type="revolute">
    <origin
      xyz="0.0388 0 0"
      rpy="0 0 -0.014509" />
    <parent
      link="L_index_mpp_link" />
    <child
      link="L_index_ip_link" />
    <axis
      xyz="0 0 1" />
    <limit
      lower="0"
      upper="1.62"
      effort="1.35"
      velocity="2.09" />
  </joint>
  <link
    name="L_middle_mpp_link">
    <inertial>
      <origin
        xyz="0.01476009 -0.00171481 0.00012869"
        rpy="0 0 0" />
      <mass
        value="0.01430214" />
      <inertia
        ixx="0.00000086"
        ixy="-0.00000003"
        ixz="0"
        iyy="0.00000344"
        iyz="0"
        izz="0.00000339" />
    </inertial>
    <visual>
      <origin
        xyz="0 0 0"
        rpy="0 0 0" />
      <geometry>
        <mesh
          filename="package://ubt_left_hand_v3_description/meshes/hand3_v1/L_middle_mpp_link.STL" />
      </geometry>
      <material
        name="">
        <color
          rgba="0.752941176470588 0.752941176470588 0.752941176470588 1" />
      </material>
    </visual>
    <collision>
      <origin
        xyz="0 0 0"
        rpy="0 0 0" />
      <geometry>
        <mesh
          filename="package://ubt_left_hand_v3_description/meshes/hand3_v1/L_middle_mpp_link.STL" />
      </geometry>
    </collision>
  </link>
  <joint
    name="L_middle_mpp_joint"
    type="revolute">
    <origin
      xyz="0.042022 0.010356 -0.011696"
      rpy="1.5708 -0.18118 0" />
    <parent
      link="L_palm_link" />
    <child
      link="L_middle_mpp_link" />
    <axis
      xyz="0 0 1" />
    <limit
      lower="0"
      upper="1.46"
      effort="1.35"
      velocity="2.09" />
  </joint>
  <link
    name="L_middle_ip_link">
    <inertial>
      <origin
        xyz="0.01771317 -0.00109666 0.0000256"
        rpy="0 0 0" />
      <mass
        value="0.0148881" />
      <inertia
        ixx="0.00000047"
        ixy="-0.00000038"
        ixz="0"
        iyy="0.00000344"
        iyz="0"
        izz="0.00000344" />
    </inertial>
    <visual>
      <origin
        xyz="0 0 0"
        rpy="0 0 0" />
      <geometry>
        <mesh
          filename="package://ubt_left_hand_v3_description/meshes/hand3_v1/L_middle_ip_link.STL" />
      </geometry>
      <material
        name="">
        <color
          rgba="0.752941176470588 0.752941176470588 0.752941176470588 1" />
      </material>
    </visual>
    <collision>
      <origin
        xyz="0 0 0"
        rpy="0 0 0" />
      <geometry>
        <mesh
          filename="package://ubt_left_hand_v3_description/meshes/hand3_v1/L_middle_ip_link.STL" />
      </geometry>
    </collision>
  </link>
  <joint
    name="L_middle_ip_joint"
    type="revolute">
    <origin
      xyz="0.0388 0 0"
      rpy="0 0 -0.012066" />
    <parent
      link="L_middle_mpp_link" />
    <child
      link="L_middle_ip_link" />
    <axis
      xyz="0 0 1" />
    <limit
      lower="0"
      upper="1.62"
      effort="1.35"
      velocity="2.09" />
  </joint>
  <link
    name="L_ring_mpp_link">
    <inertial>
      <origin
        xyz="0.01475954 -0.00171495 0.00012869"
        rpy="0 0 0" />
      <mass
        value="0.01430214" />
      <inertia
        ixx="0.00000086"
        ixy="-0.00000003"
        ixz="0"
        iyy="0.00000344"
        iyz="0"
        izz="0.00000339" />
    </inertial>
    <visual>
      <origin
        xyz="0 0 0"
        rpy="0 0 0" />
      <geometry>
        <mesh
          filename="package://ubt_left_hand_v3_description/meshes/hand3_v1/L_ring_mpp_link.STL" />
      </geometry>
      <material
        name="">
        <color
          rgba="0.752941176470588 0.752941176470588 0.752941176470588 1" />
      </material>
    </visual>
    <collision>
      <origin
        xyz="0 0 0"
        rpy="0 0 0" />
      <geometry>
        <mesh
          filename="package://ubt_left_hand_v3_description/meshes/hand3_v1/L_ring_mpp_link.STL" />
      </geometry>
    </collision>
  </link>
  <joint
    name="L_ring_mpp_joint"
    type="revolute">
    <origin
      xyz="0.041817 -0.010057 -0.011696"
      rpy="1.5708 -0.18118 -0.020071" />
    <parent
      link="L_palm_link" />
    <child
      link="L_ring_mpp_link" />
    <axis
      xyz="0 0 1" />
    <limit
      lower="0"
      upper="1.46"
      effort="1.35"
      velocity="2.09" />
  </joint>
  <link
    name="L_ring_ip_link">
    <inertial>
      <origin
        xyz="0.01615432 -0.00130235 0.00002763"
        rpy="0 0 0" />
      <mass
        value="0.01374794" />
      <inertia
        ixx="0.00000043"
        ixy="-0.00000033"
        ixz="0"
        iyy="0.00000282"
        iyz="0"
        izz="0.00000281" />
    </inertial>
    <visual>
      <origin
        xyz="0 0 0"
        rpy="0 0 0" />
      <geometry>
        <mesh
          filename="package://ubt_left_hand_v3_description/meshes/hand3_v1/L_ring_ip_link.STL" />
      </geometry>
      <material
        name="">
        <color
          rgba="0.752941176470588 0.752941176470588 0.752941176470588 1" />
      </material>
    </visual>
    <collision>
      <origin
        xyz="0 0 0"
        rpy="0 0 0" />
      <geometry>
        <mesh
          filename="package://ubt_left_hand_v3_description/meshes/hand3_v1/L_ring_ip_link.STL" />
      </geometry>
    </collision>
  </link>
  <joint
    name="L_ring_ip_joint"
    type="revolute">
    <origin
      xyz="0.0388 0 0"
      rpy="0 0 -0.014509" />
    <parent
      link="L_ring_mpp_link" />
    <child
      link="L_ring_ip_link" />
    <axis
      xyz="0 0 1" />
    <limit
      lower="0"
      upper="1.62"
      effort="1.35"
      velocity="2.09" />
  </joint>
  <link
    name="L_little_mpp_link">
    <inertial>
      <origin
        xyz="0.0147588 -0.00171514 0.00012869"
        rpy="0 0 0" />
      <mass
        value="0.01430214" />
      <inertia
        ixx="0.00000086"
        ixy="-0.00000003"
        ixz="0"
        iyy="0.00000344"
        iyz="0"
        izz="0.00000339" />
    </inertial>
    <visual>
      <origin
        xyz="0 0 0"
        rpy="0 0 0" />
      <geometry>
        <mesh
          filename="package://ubt_left_hand_v3_description/meshes/hand3_v1/L_little_mpp_link.STL" />
      </geometry>
      <material
        name="">
        <color
          rgba="0.752941176470588 0.752941176470588 0.752941176470588 1" />
      </material>
    </visual>
    <collision>
      <origin
        xyz="0 0 0"
        rpy="0 0 0" />
      <geometry>
        <mesh
          filename="package://ubt_left_hand_v3_description/meshes/hand3_v1/L_little_mpp_link.STL" />
      </geometry>
    </collision>
  </link>
  <joint
    name="L_little_mpp_joint"
    type="revolute">
    <origin
      xyz="0.041203 -0.030462 -0.011696"
      rpy="1.5708 -0.18118 -0.040143" />
    <parent
      link="L_palm_link" />
    <child
      link="L_little_mpp_link" />
    <axis
      xyz="0 0 1" />
    <limit
      lower="0"
      upper="1.46"
      effort="1.35"
      velocity="2.09" />
  </joint>
  <link
    name="L_little_ip_link">
    <inertial>
      <origin
        xyz="0.01303327 -0.00143438 0.0000295"
        rpy="0 0 0" />
      <mass
        value="0.01179268" />
      <inertia
        ixx="0.00000034"
        ixy="-0.00000023"
        ixz="0"
        iyy="0.00000179"
        iyz="0"
        izz="0.00000178" />
    </inertial>
    <visual>
      <origin
        xyz="0 0 0"
        rpy="0 0 0" />
      <geometry>
        <mesh
          filename="package://ubt_left_hand_v3_description/meshes/hand3_v1/L_little_ip_link.STL" />
      </geometry>
      <material
        name="">
        <color
          rgba="0.752941176470588 0.752941176470588 0.752941176470588 1" />
      </material>
    </visual>
    <collision>
      <origin
        xyz="0 0 0"
        rpy="0 0 0" />
      <geometry>
        <mesh
          filename="package://ubt_left_hand_v3_description/meshes/hand3_v1/L_little_ip_link.STL" />
      </geometry>
    </collision>
  </link>
  <joint
    name="L_little_ip_joint"
    type="revolute">
    <origin
      xyz="0.0388 0 0"
      rpy="0 0 -0.014509" />
    <parent
      link="L_little_mpp_link" />
    <child
      link="L_little_ip_link" />
    <axis
      xyz="0 0 1" />
    <limit
      lower="0"
      upper="1.62"
      effort="1.35"
      velocity="2.09" />
  </joint>
</robot>